Workbook
Name MIG_APENAS.NÚM: _xlfn.LAMBDA(_xlpm.texto, _xlfn.CONCAT( IFERROR( -- MID( _xlpm.texto, _xlfn.SEQUENCE(LEN( _xlpm.texto ) ), 1 ), "" ) ) )
Name MIG_REMOVER.ESPECIAL: _xlfn.LAMBDA(_xlpm.texto, TRIM( MIG_TROCAR.CARACTERES( _xlpm.texto, "áàâãäÁÀÂÃÄéèêëÉÈÊËíìîïÍÌÎÏóòôöÓÒÔÖúùûüÚÙÛÜçÇ&'`´", "aaaaaAAAAAeeeeEEEEiiiiIIIIooooOOOOuuuuUUUUcC " ) ) )

Sheet Dados
A1: ? | B1: → | C1: → | D1: @NRESTRUTURA@ | E1: → | F1: → | G1: → | H1: → | I1: → | J1: → | K1: → | L1: → | M1: @IDTPEMPRESA@ | N1: → | O1: → | P1: → | Q1: → | R1: → | S1: → | T1: → | U1: → | V1: → | W1: → | X1: → | Y1: → | Z1: → | AA1: → | AB1: → | AD1: @CDSINDICAL@ | AF1: ORGANIZAÇÃO | AG1: @NRPARCNEGOCIO@ | AH1: @NRESTRUTURAM@ | AI1: @NRESTRUTURAH@ | AJ1: @NRENDERECOPARC@ | AK1: @CNPJ@ | AL1: @CEI@ | AM1: @RAZAOSOCIAL@ | AN1: @NATJURIDICA@ | AO1: @CDCNAE@ | AP1: @CDFPAS@ | AQ1: @CDCAGED@ | AR1: @IDSIMPLES@ | AS1: @IDPARTICIPAT@ | AT1: @IDENDERECO@ | AU1: @CDPAIS@ | AV1: @SGESTADO@ | AW1: @MUNICIPIO@ | AX1: @LOGRADOURO@ | AY1: @ENDERECO@ | AZ1: ID | BA1: @NUMERO@ | BB1: @BAIRRO@ | BC1: @CEP@ | BD1: @REFERENCIAENDERECO@ | BE1: @NMFANTASIA@ | BF1: @NMESTRUTURA@ | BG1: @NMPRINCIPALPARC@ | BH1: @CDCPFESTRUTURA@ | BI1: @DTINIVIGENCIA@ | BJ1: @DTFIMVIGENCIA@ | BK1: @COMPETENCIA@ | BL1: @DTBASESINDICAL@ | BM1: Estrutura | BN1: Endereco | BO1: Saída | BU1: --Busca de PK’s livres | BZ1: --Validações de PK | CE1: Atualiza Novo Código
A2: Tipo de Estrutura Teknisa | B2: Início de Vigência | C2: Fim de Vigência | D2: Nº Estrutura | E2: Mês Competência | F2: CNPJ | G2: CEI | H2: Razão Social | I2: Natureza Jurídica | J2: CNAE | K2: FPAS | L2: CAGED | M2: Tipo de Empresa | N2: Optante Simples | O2: Participaçao PAT | P2: Tp Endereço | Q2: Pais | R2: Estado | S2: Município | T2: Logradouro | U2: Endereço | V2: Numero | W2: Nome do Bairro | X2: CEP | Y2: Referência do Endereço | Z2: Nome Fantasia | AA2: Nome Estrutura | AB2: CPF | AC2: Data Base Sindical | AD2: Cód Sindicato | AE2: Inserir? Verificando por código de integração | AF2: 4385 | AG2: =1739-1 -> 1738 | AH2: =167-1 -> 166 | AI2: =167-1 -> 166 | AJ2: =1719-1 -> 1718 | AK2: CNPJ | AL2: CEI | AM2: Razão Social | AN2: Natureza Jurídica | AO2: CNAE | AP2: FPAS | AQ2: CAGED | AR2: Optante Simples Retirar o NVL do script. Deixar a escolha neste campo. | AS2: Participação PAT | AT2: Tp Endereço | AU2: Pais | AV2: Estado | AW2: Município | AX2: Logradouro | AY2: Endereço | AZ2: Insere ENDEREÇO? (a coluna de tipo de endereço e endereço devem existir) | BA2: Número | BB2: Nome do Bairro | BC2: CEP | BD2: Referência do Endereço | BE2: Nome Fantasia | BF2: Nome Estrutura Ver NVL nas querys de estrutura. Fazer algo melhor na próxima versão! | BG2: Este campo não existe na planilha. Prevenindo estruturas sem nome para a inserção do nome do parceiro de negocio. | BH2: CPF | BM2: INSERT INTO PARCNEGOCIO ( NRORG, NRPARCNEGOCIO, NMPRINCIPALPARC, NMSECUNDARIPARC, NRINSCRICAOPARC, IDATIVO, DTINCLUSAO, NRORGINCLUSAO, CDOPERINCLUSAO, CDTIPOPARCPRINCIPAL, CDTIPOINSCRICAO, IDPESSOAFISICA, IDINSTITUICAO, IDPARCFUNDIDO ) VALUES ( @NRORG@, @NRPARCNEGOCIO@, '@NMPRINCIPALPARC@', '@NMPRINCIPALPARC@', '@CNPJ@', 'S', SYSDATE, @NRORG@, '000000099991', 'ESTRUTURA', 'CNPJ', 'N', 'N', 'N' ); INSERT INTO ESTRUTURAM ( NRORG, NRESTRUTURAM, NRPARCNEGOCIO, CDINTESTRUTURA, NRTIPOESTRUTURA, DTINIVIGENCIA, DTFIMVIGENCIA, NMESTRUTURAM, IDATIVO, DTINCLUSAO, CDOPERINCLUSAO ) VALUES ( @NRORG@, @NRESTRUTURAM@, @NRPARCNEGOCIO@, '@NRESTRUTURA@', @NRTPESTRUTURA@, '@DTINIVIGENCIA@', '@DTFIMVIGENCIA@', NVL( '@NMESTRUTURA@', NVL( '@NMFANTASIA@', '@RAZAOSOCIAL@' ) ), 'S', SYSDATE, '000000099991'); INSERT INTO ESTRUTURAH ( NRORG, NRESTRUTURAM, NRESTRUTURAH, NRPARCNEGOCIO, DTMESCOMPETENC, CDCNPJESTRUT, CDCEIESTRUT, NMRAZSOCESTRUT, NMFANTASIA, NMESTRUTURAH, CDNATUJURI, CDCNAE, NRCAGED, IDTIPOEMPR, IDOPTSIMPLES, IDPARTICIPAT, CDCPFESTRUTURA, DTBASESINDICAL, CDSINDICAL, IDATIVO, DTINCLUSAO, CDOPERINCLUSAO) VALUES ( @NRORG@, @NRESTRUTURAM@, @NRESTRUTURAH@, @NRPARCNEGOCIO@, '@COMPETENCIA@', '@CNPJ@', '@CEI@', '@RAZAOSOCIAL@', '@NMFANTASIA@', NVL( '@NMESTRUTURA@', NVL( '@NMFANTASIA@', '@RAZAOSOCIAL@' ) ), '@NATJURIDICA@', '@CDCNAE@', '@CDCAGED@', '@IDTPEMPRESA@', NVL( '@IDSIMPLES@', 'N' ), '@IDPARTICIPAT@', '@CDCPFESTRUTURA@', '@DTBASESINDICAL@', '@CDSINDICAL@', 'S', SYSDATE, '000000099991'); | BN2: INSERT INTO ENDERECOPARC ( NRORG, NRENDERECOPARC, NRPARCNEGOCIO, CDTIPOENDERECO, IDATIVO, DTINCLUSAO, CDOPERINCLUSAO, CDPAIS, SGESTADO, CDLOGRADOURO, NMBAIRROENDERECO, DSREFERENCIAENDE, NRCEPENDERECO, DSENDERECO, NRIMOVELENDERECO, CDMUNICIPIO ) VALUES ( @NRORG@, @NRENDERECOPARC@, @NRPARCNEGOCIO@, '@IDENDERECO@', 'S', SYSDATE, '000000099991', LPAD( '@CDPAIS@', 4, '0' ), '@SGESTADO@', '@LOGRADOURO@', '@BAIRRO@', '@REFERENCIAENDERECO@', '@CEP@', '@ENDERECO@', '@NUMERO@', ( SELECT MAX( CDMUNICIPIO ) FROM MUNICIPIO WHERE UPPER( NMMUNICIPIO ) = '@MUNICIPIO@' AND CDPAIS = LPAD( '@CDPAIS@', 4, '0' ) AND SGESTADO = '@SGESTADO@' ) ); | BO2: Saída | BP2: Configurações | BU2: ="/*"&BU4&"*/ SELECT A + 1 A, B - 1 B, B - A - 1 LENGHT, (SELECT TO_NUMBER(NRSEQUENCIAL) FROM NOVOCODIGO WHERE NRORG = "&BU9&" AND CDCONTADOR = '"&BU4&"') NOVOCODIGO FROM (SELECT 0 A, MIN("&BU5&") B FROM "&BU4&" WHERE NRORG = "&BU9&" UNION ALL SELECT "&BU5&", LEAD("&BU5&") OVER (ORDER BY "&BU5&") FROM "&BU4&" WHERE NRORG = "&BU9&" ) WHERE B - A > "&BU8&" OR B IS NULL ORDER BY A;" -> /*PARCNEGOCIO*/ SELECT A + 1 A, B - 1 B, B - A - 1 LENGHT, (SELECT TO_NUMBER(NRSEQUENCIAL) FROM NOVOCODIGO WHERE NRORG = 4385 AND CDCONTADOR = 'PARCNEGOCIO') NOVOCODIGO FROM (SELECT 0 A, MIN(NRPARCNEGOCIO) B FROM PARCNEGOCIO WHERE NRORG = 4385 UNION ALL SELECT NRPARCNEGOCIO, LEAD(NRPARCNEGOCIO) OVER (ORDER BY NRPARCNEGOCIO) FROM PARCNEGOCIO WHERE NRORG = 4385 ) WHERE B - A > 8 OR B IS NULL ORDER BY A; | BV2: ="/*"&BV4&"*/ SELECT A + 1 A, B - 1 B, B - A - 1 LENGHT, (SELECT TO_NUMBER(NRSEQUENCIAL) FROM NOVOCODIGO WHERE NRORG = "&BV9&" AND CDCONTADOR = '"&BV4&"') NOVOCODIGO FROM (SELECT 0 A, MIN("&BV5&") B FROM "&BV4&" WHERE NRORG = "&BV9&" UNION ALL SELECT "&BV5&", LEAD("&BV5&") OVER (ORDER BY "&BV5&") FROM "&BV4&" WHERE NRORG = "&BV9&" ) WHERE B - A > "&BV8&" OR B IS NULL ORDER BY A;" -> /*ESTRUTURAM*/ SELECT A + 1 A, B - 1 B, B - A - 1 LENGHT, (SELECT TO_NUMBER(NRSEQUENCIAL) FROM NOVOCODIGO WHERE NRORG = 4385 AND CDCONTADOR = 'ESTRUTURAM') NOVOCODIGO FROM (SELECT 0 A, MIN(NRESTRUTURAM) B FROM ESTRUTURAM WHERE NRORG = 4385 UNION ALL SELECT NRESTRUTURAM, LEAD(NRESTRUTURAM) OVER (ORDER BY NRESTRUTURAM) FROM ESTRUTURAM WHERE NRORG = 4385 ) WHERE B - A > 8 OR B IS NULL ORDER BY A; | BW2: ="/*"&BW4&"*/ SELECT A + 1 A, B - 1 B, B - A - 1 LENGHT, (SELECT TO_NUMBER(NRSEQUENCIAL) FROM NOVOCODIGO WHERE NRORG = "&BW9&" AND CDCONTADOR = '"&BW4&"') NOVOCODIGO FROM (SELECT 0 A, MIN("&BW5&") B FROM "&BW4&" WHERE NRORG = "&BW9&" UNION ALL SELECT "&BW5&", LEAD("&BW5&") OVER (ORDER BY "&BW5&") FROM "&BW4&" WHERE NRORG = "&BW9&" ) WHERE B - A > "&BW8&" OR B IS NULL ORDER BY A;" -> /*ESTRUTURAH*/ SELECT A + 1 A, B - 1 B, B - A - 1 LENGHT, (SELECT TO_NUMBER(NRSEQUENCIAL) FROM NOVOCODIGO WHERE NRORG = 4385 AND CDCONTADOR = 'ESTRUTURAH') NOVOCODIGO FROM (SELECT 0 A, MIN(NRESTRUTURAH) B FROM ESTRUTURAH WHERE NRORG = 4385 UNION ALL SELECT NRESTRUTURAH, LEAD(NRESTRUTURAH) OVER (ORDER BY NRESTRUTURAH) FROM ESTRUTURAH WHERE NRORG = 4385 ) WHERE B - A > 8 OR B IS NULL ORDER BY A; | BX2: ="/*"&BX4&"*/ SELECT A + 1 A, B - 1 B, B - A - 1 LENGHT, (SELECT TO_NUMBER(NRSEQUENCIAL) FROM NOVOCODIGO WHERE NRORG = "&BX9&" AND CDCONTADOR = '"&BX4&"') NOVOCODIGO FROM (SELECT 0 A, MIN("&BX5&") B FROM "&BX4&" WHERE NRORG = "&BX9&" UNION ALL SELECT "&BX5&", LEAD("&BX5&") OVER (ORDER BY "&BX5&") FROM "&BX4&" WHERE NRORG = "&BX9&" ) WHERE B - A > "&BX8&" OR B IS NULL ORDER BY A;" -> /*ENDERECOPARC*/ SELECT A + 1 A, B - 1 B, B - A - 1 LENGHT, (SELECT TO_NUMBER(NRSEQUENCIAL) FROM NOVOCODIGO WHERE NRORG = 4385 AND CDCONTADOR = 'ENDERECOPARC') NOVOCODIGO FROM (SELECT 0 A, MIN(NRENDERECOPARC) B FROM ENDERECOPARC WHERE NRORG = 4385 UNION ALL SELECT NRENDERECOPARC, LEAD(NRENDERECOPARC) OVER (ORDER BY NRENDERECOPARC) FROM ENDERECOPARC WHERE NRORG = 4385 ) WHERE B - A > 8 OR B IS NULL ORDER BY A; | BZ2: ="SELECT DECODE(COUNT(1),0,'OK',COUNT(1)||' conflito(s)') STATUS, '"&BZ4&"' TABELA FROM "&BZ4&" WHERE NRORG = "&BZ9&" AND "&BZ5&" BETWEEN "&BZ6&" AND "&BZ7&" UNION ALL " -> SELECT DECODE(COUNT(1),0,'OK',COUNT(1)||' conflito(s)') STATUS, 'PARCNEGOCIO' TABELA FROM PARCNEGOCIO WHERE NRORG = 4385 AND NRPARCNEGOCIO BETWEEN 1739 AND 1746 UNION ALL | CA2: ="SELECT DECODE(COUNT(1),0,'OK',COUNT(1)||' conflito(s)') STATUS, '"&CA4&"' TABELA FROM "&CA4&" WHERE NRORG = "&CA9&" AND "&CA5&" BETWEEN "&CA6&" AND "&CA7&" UNION ALL " -> SELECT DECODE(COUNT(1),0,'OK',COUNT(1)||' conflito(s)') STATUS, 'ESTRUTURAM' TABELA FROM ESTRUTURAM WHERE NRORG = 4385 AND NRESTRUTURAM BETWEEN 167 AND 174 UNION ALL | CB2: ="SELECT DECODE(COUNT(1),0,'OK',COUNT(1)||' conflito(s)') STATUS, '"&CB4&"' TABELA FROM "&CB4&" WHERE NRORG = "&CB9&" AND "&CB5&" BETWEEN "&CB6&" AND "&CB7&" UNION ALL " -> SELECT DECODE(COUNT(1),0,'OK',COUNT(1)||' conflito(s)') STATUS, 'ESTRUTURAH' TABELA FROM ESTRUTURAH WHERE NRORG = 4385 AND NRESTRUTURAH BETWEEN 167 AND 174 UNION ALL | CC2: ="SELECT DECODE(COUNT(1),0,'OK',COUNT(1)||' conflito(s)') STATUS, '"&CC4&"' TABELA FROM "&CC4&" WHERE NRORG = "&CC9&" AND "&CC5&" BETWEEN "&CC6&" AND "&CC7&";/* UNION ALL */" -> SELECT DECODE(COUNT(1),0,'OK',COUNT(1)||' conflito(s)') STATUS, 'ENDERECOPARC' TABELA FROM ENDERECOPARC WHERE NRORG = 4385 AND NRENDERECOPARC BETWEEN 1719 AND 1726;/* UNION ALL */ | CD2: /*Atualiza ou cria o novo codigo*/ | CE2: ="MERGE INTO NOVOCODIGO NC USING ( SELECT LPAD( MAX( "&CE5&" ) + 1, 20, '0' ) NRSEQUENCIAL FROM "&CE4&" WHERE NRORG = "&CE9&" ) TABELA ON ( NC.NRORG = "&CE9&" AND NC.CDCONTADOR = '"&CE4&"' ) WHEN MATCHED THEN UPDATE SET NC.NRSEQUENCIAL = TABELA.NRSEQUENCIAL WHEN NOT MATCHED THEN INSERT ( CDCONTADOR, NRSEQUENCIAL, NRORG, DTINCLUSAO ) VALUES ( '"&CE4&"', TABELA.NRSEQUENCIAL, "&CE9&", SYSDATE ) ;" -> MERGE INTO NOVOCODIGO NC USING ( SELECT LPAD( MAX( NRPARCNEGOCIO ) + 1, 20, '0' ) NRSEQUENCIAL FROM PARCNEGOCIO WHERE NRORG = 4385 ) TABELA ON ( NC.NRORG = 4385 AND NC.CDCONTADOR = 'PARCNEGOCIO' ) WHEN MATCHED THEN UPDATE SET NC.NRSEQUENCIAL = TABELA.NRSEQUENCIAL WHEN NOT MATCHED THEN INSERT ( CDCONTADOR, NRSEQUENCIAL, NRORG, DTINCLUSAO ) VALUES ( 'PARCNEGOCIO', TABELA.NRSEQUENCIAL, 4385, SYSDATE ) ; | CF2: ="MERGE INTO NOVOCODIGO NC USING ( SELECT LPAD( MAX( "&CF5&" ) + 1, 20, '0' ) NRSEQUENCIAL FROM "&CF4&" WHERE NRORG = "&CF9&" ) TABELA ON ( NC.NRORG = "&CF9&" AND NC.CDCONTADOR = '"&CF4&"' ) WHEN MATCHED THEN UPDATE SET NC.NRSEQUENCIAL = TABELA.NRSEQUENCIAL WHEN NOT MATCHED THEN INSERT ( CDCONTADOR, NRSEQUENCIAL, NRORG, DTINCLUSAO ) VALUES ( '"&CF4&"', TABELA.NRSEQUENCIAL, "&CF9&", SYSDATE ) ;" -> MERGE INTO NOVOCODIGO NC USING ( SELECT LPAD( MAX( NRESTRUTURAM ) + 1, 20, '0' ) NRSEQUENCIAL FROM ESTRUTURAM WHERE NRORG = 4385 ) TABELA ON ( NC.NRORG = 4385 AND NC.CDCONTADOR = 'ESTRUTURAM' ) WHEN MATCHED THEN UPDATE SET NC.NRSEQUENCIAL = TABELA.NRSEQUENCIAL WHEN NOT MATCHED THEN INSERT ( CDCONTADOR, NRSEQUENCIAL, NRORG, DTINCLUSAO ) VALUES ( 'ESTRUTURAM', TABELA.NRSEQUENCIAL, 4385, SYSDATE ) ; | CG2: ="MERGE INTO NOVOCODIGO NC USING ( SELECT LPAD( MAX( "&CG5&" ) + 1, 20, '0' ) NRSEQUENCIAL FROM "&CG4&" WHERE NRORG = "&CG9&" ) TABELA ON ( NC.NRORG = "&CG9&" AND NC.CDCONTADOR = '"&CG4&"' ) WHEN MATCHED THEN UPDATE SET NC.NRSEQUENCIAL = TABELA.NRSEQUENCIAL WHEN NOT MATCHED THEN INSERT ( CDCONTADOR, NRSEQUENCIAL, NRORG, DTINCLUSAO ) VALUES ( '"&CG4&"', TABELA.NRSEQUENCIAL, "&CG9&", SYSDATE ) ;" -> MERGE INTO NOVOCODIGO NC USING ( SELECT LPAD( MAX( NRESTRUTURAH ) + 1, 20, '0' ) NRSEQUENCIAL FROM ESTRUTURAH WHERE NRORG = 4385 ) TABELA ON ( NC.NRORG = 4385 AND NC.CDCONTADOR = 'ESTRUTURAH' ) WHEN MATCHED THEN UPDATE SET NC.NRSEQUENCIAL = TABELA.NRSEQUENCIAL WHEN NOT MATCHED THEN INSERT ( CDCONTADOR, NRSEQUENCIAL, NRORG, DTINCLUSAO ) VALUES ( 'ESTRUTURAH', TABELA.NRSEQUENCIAL, 4385, SYSDATE ) ; | CH2: ="MERGE INTO NOVOCODIGO NC USING ( SELECT LPAD( MAX( "&CH5&" ) + 1, 20, '0' ) NRSEQUENCIAL FROM "&CH4&" WHERE NRORG = "&CH9&" ) TABELA ON ( NC.NRORG = "&CH9&" AND NC.CDCONTADOR = '"&CH4&"' ) WHEN MATCHED THEN UPDATE SET NC.NRSEQUENCIAL = TABELA.NRSEQUENCIAL WHEN NOT MATCHED THEN INSERT ( CDCONTADOR, NRSEQUENCIAL, NRORG, DTINCLUSAO ) VALUES ( '"&CH4&"', TABELA.NRSEQUENCIAL, "&CH9&", SYSDATE ) ;" -> MERGE INTO NOVOCODIGO NC USING ( SELECT LPAD( MAX( NRENDERECOPARC ) + 1, 20, '0' ) NRSEQUENCIAL FROM ENDERECOPARC WHERE NRORG = 4385 ) TABELA ON ( NC.NRORG = 4385 AND NC.CDCONTADOR = 'ENDERECOPARC' ) WHEN MATCHED THEN UPDATE SET NC.NRSEQUENCIAL = TABELA.NRSEQUENCIAL WHEN NOT MATCHED THEN INSERT ( CDCONTADOR, NRSEQUENCIAL, NRORG, DTINCLUSAO ) VALUES ( 'ENDERECOPARC', TABELA.NRSEQUENCIAL, 4385, SYSDATE ) ; | CI2: COMMIT;
A3: 5 | B3: 01/01/2000 | D3: 001.127 | E3: =B3 -> 01/01/2000 | F3: 03801629000200 | H3: LALLEGRO ACTION TECNOLOGY INDUSTRIA E COMERCIO DE | I3: 2062 | J3: 2710403 | P3: OUTROS | Q3: 0055 | R3: MG | S3: VARGINHA | T3: AV | U3: OTTO SALGADO | V3: 295 | W3: DIST. IND. CLAUDIO GALVÃO NOGUEIRA | X3: 37066-440 | Z3: =H3 -> LALLEGRO ACTION TECNOLOGY INDUSTRIA E COMERCIO DE | AA3: =Z3 -> LALLEGRO ACTION TECNOLOGY INDUSTRIA E COMERCIO DE | AE3: =IF(COUNTIF(Base!A:A, D3)=0,"insere","não") -> insere | AG3: =AG2+1 -> 1739 | AH3: =AH2+1 -> 167 | AI3: =AI2+1 -> 167 | AJ3: =IF(AZ3="insere",LARGE($AJ$2:AJ2,1)+1,"") -> 1719 | AK3: =SUBSTITUTE(SUBSTITUTE(SUBSTITUTE(SUBSTITUTE(SUBSTITUTE(F3," ",""),"-",""),".",""),"/",""),"\","") -> 03801629000200 | AL3: =SUBSTITUTE(SUBSTITUTE(SUBSTITUTE(SUBSTITUTE(SUBSTITUTE(G3," ",""),"-",""),".",""),"/",""),"\","") | AM3: =TRIM(SUBSTITUTE(SUBSTITUTE(H3,"'",""),"&","")) -> LALLEGRO ACTION TECNOLOGY INDUSTRIA E COMERCIO DE | AN3: =SUBSTITUTE(SUBSTITUTE(SUBSTITUTE(SUBSTITUTE(SUBSTITUTE(I3," ",""),"-",""),".",""),"/",""),"\","") -> 2062 | AO3: =SUBSTITUTE(SUBSTITUTE(SUBSTITUTE(SUBSTITUTE(SUBSTITUTE(J3," ",""),"-",""),".",""),"/",""),"\","") -> 2710403 | AP3: =SUBSTITUTE(SUBSTITUTE(SUBSTITUTE(SUBSTITUTE(SUBSTITUTE(K3," ",""),"-",""),".",""),"/",""),"\","") | AQ3: =SUBSTITUTE(SUBSTITUTE(SUBSTITUTE(SUBSTITUTE(SUBSTITUTE(L3," ",""),"-",""),".",""),"/",""),"\","") | AR3: =IF(TRIM(N3)="","N",TRIM(N3)) -> N | AS3: =TRIM(O3) | AT3: =IF( TRIM( P3 ) = "", "PRINCIPAL", UPPER( TRIM( P3 ) ) ) -> OUTROS | AU3: =TEXT(Q3,"0000") -> 0055 | AV3: =LEFT(TRIM(SUBSTITUTE(SUBSTITUTE(R3,"'",""),"&","")),2) -> MG | AW3: {=UPPER( TRIM( MIG_REMOVER.ESPECIAL( S3 ) ) )} -> VARGINHA | AX3: =LEFT(TRIM(SUBSTITUTE(SUBSTITUTE(SUBSTITUTE(SUBSTITUTE(SUBSTITUTE(UPPER(T3),"'",""),"&",""),"Á","A"),"Ã","A"),"Ç","C")),4) -> AV | AY3: =TRIM(SUBSTITUTE(SUBSTITUTE(U3,"'",""),"&","")) -> OTTO SALGADO | AZ3: =IF(AND(AT3<>"",AY3<>""),"insere","não") -> insere | BA3: =TRIM(V3) -> 295 | BB3: =TRIM(SUBSTITUTE(SUBSTITUTE(W3,"'",""),"&","")) -> DIST. IND. CLAUDIO GALVÃO NOGUEIRA | BC3: =SUBSTITUTE(SUBSTITUTE(SUBSTITUTE(SUBSTITUTE(SUBSTITUTE(X3," ",""),"-",""),".",""),"/",""),"\","") -> 37066440 | BD3: =TRIM(SUBSTITUTE(SUBSTITUTE(Y3,"'",""),"&","")) | BE3: =TRIM(SUBSTITUTE(SUBSTITUTE(Z3,"'",""),"&","")) -> LALLEGRO ACTION TECNOLOGY INDUSTRIA E COMERCIO DE | BF3: =TRIM(SUBSTITUTE(SUBSTITUTE(AA3,"'",""),"&","")) -> LALLEGRO ACTION TECNOLOGY INDUSTRIA E COMERCIO DE | BG3: =IF(AM3<>"",AM3,IF(BE3<>"",BE3,IF(BF3<>"",BF3,"Estrutura "&AH3&" - "&D3))) -> LALLEGRO ACTION TECNOLOGY INDUSTRIA E COMERCIO DE | BH3: =SUBSTITUTE(SUBSTITUTE(SUBSTITUTE(SUBSTITUTE(SUBSTITUTE(AB3," ",""),"-",""),".",""),"/",""),"\","") | BI3: =TEXT(B3,"DD/MM/AAAA") -> 01/01/2000 | BJ3: =TRIM(IF(C3="","",TEXT(C3,"DD/MM/AAAA"))) | BK3: =IF(E3="","",TEXT(E3,"DD/MM/AAAA")) -> 01/01/2000 | BL3: =TRIM(IF(AC3="","",TEXT(AC3,"DD/MM/AAAA"))) | BM3: =SUBSTITUTE( SUBSTITUTE( SUBSTITUTE( SUBSTITUTE( SUBSTITUTE( SUBSTITUTE( SUBSTITUTE( SUBSTITUTE( SUBSTITUTE( SUBSTITUTE( SUBSTITUTE( SUBSTITUTE( SUBSTITUTE( SUBSTITUTE( SUBSTITUTE( SUBSTITUTE( SUBSTITUTE( SUBSTITUTE( SUBSTITUTE( SUBSTITUTE( SUBSTITUTE( SUBSTITUTE( SUBSTITUTE( SUBSTITUTE( $BM$2, "@NRORG@", $AF$2 ), "@NRPARCNEGOCIO@", $AG3 ), "@NMPRINCIPALPARC@", $BG3 ), "@CNPJ@", $AK3 ), "@NRESTRUTURAM@", $AH3 ), "@NRESTRUTURA@", $D3 ), "@NRTPESTRUTURA@", $A3 ), "@DTINIVIGENCIA@", $BI3 ), "@DTFIMVIGENCIA@", $BJ3 ), "@NMESTRUTURA@", $BF3 ), "@NMFANTASIA@", $BE3 ), "@RAZAOSOCIAL@", $AM3 ), "@NRESTRUTURAH@", $AI3 ), "@COMPETENCIA@", $BK3 ), "@CEI@", $AL3 ), "@NATJURIDICA@", $AN3 ), "@CDCNAE@", $AO3 ), "@CDCAGED@", $AQ3 ), "@IDTPEMPRESA@", $M3 ), "@IDSIMPLES@", $AR3 ), "@IDPARTICIPAT@", $AS3 ), "@CDCPFESTRUTURA@", $BH3 ), "@DTBASESINDICAL@", $BL3 ), "@CDSINDICAL@", $AD3 ) -> INSERT INTO PARCNEGOCIO ( NRORG, NRPARCNEGOCIO, NMPRINCIPALPARC, NMSECUNDARIPARC, NRINSCRICAOPARC, IDATIVO, DTINCLUSAO, NRORGINCLUSAO, CDOPERINCLUSAO, CDTIPOPARCPRINCIPAL, CDTIPOINSCRICAO, IDPESSOAFISICA, IDINSTITUICAO, IDPARCFUNDIDO ) VALUES ( 4385, 1739, 'LALLEGRO ACTION TECNOLOGY INDUSTRIA E COMERCIO DE', 'LALLEGRO ACTION TECNOLOGY INDUSTRIA E COMERCIO DE', '03801629000200', 'S', SYSDATE, 4385, '000000099991', 'ESTRUTURA', 'CNPJ', 'N', 'N', 'N' ); INSERT INTO ESTRUTURAM ( NRORG, NRESTRUTURAM, NRPARCNEGOCIO, CDINTESTRUTURA, NRTIPOESTRUTURA, DTINIVIGENCIA, DTFIMVIGENCIA, NMESTRUTURAM, IDATIVO, DTINCLUSAO, CDOPERINCLUSAO ) VALUES ( 4385, 167, 1739, '001.127', 5, '01/01/2000', '', NVL( 'LALLEGRO ACTION TECNOLOGY INDUSTRIA E COMERCIO DE', NVL( 'LALLEGRO ACTION TECNOLOGY INDUSTRIA E COMERCIO DE', 'LALLEGRO ACTION TECNOLOGY INDUSTRIA E COMERCIO DE' ) ), 'S', SYSDATE, '000000099991'); INSERT INTO ESTRUTURAH ( NRORG, NRESTRUTURAM, NRESTRUTURAH, NRPARCNEGOCIO, DTMESCOMPETENC, CDCNPJESTRUT, CDCEIESTRUT, NMRAZSOCESTRUT, NMFANTASIA, NMESTRUTURAH, CDNATUJURI, CDCNAE, NRCAGED, IDTIPOEMPR, IDOPTSIMPLES, IDPARTICIPAT, CDCPFESTRUTURA, DTBASESINDICAL, CDSINDICAL, IDATIVO, DTINCLUSAO, CDOPERINCLUSAO) VALUES ( 4385, 167, 167, 1739, '01/01/2000', '03801629000200', '', 'LALLEGRO ACTION TECNOLOGY INDUSTRIA E COMERCIO DE', 'LALLEGRO ACTION TECNOLOGY INDUSTRIA E COMERCIO DE', NVL( 'LALLEGRO ACTION TECNOLOGY INDUSTRIA E COMERCIO DE', NVL( 'LALLEGRO ACTION TECNOLOGY INDUSTRIA E COMERCIO DE', 'LALLEGRO ACTION TECNOLOGY INDUSTRIA E COMERCIO DE' ) ), '2062', '2710403', '', '', NVL( 'N', 'N' ), '', '', '', '', 'S', SYSDATE, '000000099991'); | BN3: =SUBSTITUTE( SUBSTITUTE( SUBSTITUTE( SUBSTITUTE( SUBSTITUTE( SUBSTITUTE( SUBSTITUTE( SUBSTITUTE( SUBSTITUTE( SUBSTITUTE( SUBSTITUTE( SUBSTITUTE( SUBSTITUTE( $BN$2, "@NRORG@", $AF$2 ), "@NRENDERECOPARC@", $AJ3 ), "@NRPARCNEGOCIO@", $AG3 ), "@IDENDERECO@", $AT3 ), "@CDPAIS@", $AU3 ), "@SGESTADO@", $AV3 ), "@LOGRADOURO@", $AX3 ), "@BAIRRO@", $BB3 ), "@REFERENCIAENDERECO@", $BD3 ), "@CEP@", $BC3 ), "@ENDERECO@", $AY3 ), "@NUMERO@", $BA3 ), "@MUNICIPIO@", $AW3 ) -> INSERT INTO ENDERECOPARC ( NRORG, NRENDERECOPARC, NRPARCNEGOCIO, CDTIPOENDERECO, IDATIVO, DTINCLUSAO, CDOPERINCLUSAO, CDPAIS, SGESTADO, CDLOGRADOURO, NMBAIRROENDERECO, DSREFERENCIAENDE, NRCEPENDERECO, DSENDERECO, NRIMOVELENDERECO, CDMUNICIPIO ) VALUES ( 4385, 1719, 1739, 'OUTROS', 'S', SYSDATE, '000000099991', LPAD( '0055', 4, '0' ), 'MG', 'AV', 'DIST. IND. CLAUDIO GALVÃO NOGUEIRA', '', '37066440', 'OTTO SALGADO', '295', ( SELECT MAX( CDMUNICIPIO ) FROM MUNICIPIO WHERE UPPER( NMMUNICIPIO ) = 'VARGINHA' AND CDPAIS = LPAD( '0055', 4, '0' ) AND SGESTADO = 'MG' ) ); | BO3: =IF( AE3 <> "insere", "", BM3 & IF( AZ3 = "insere", " " & BN3, "" ) & " COMMIT;" ) -> INSERT INTO PARCNEGOCIO ( NRORG, NRPARCNEGOCIO, NMPRINCIPALPARC, NMSECUNDARIPARC, NRINSCRICAOPARC, IDATIVO, DTINCLUSAO, NRORGINCLUSAO, CDOPERINCLUSAO, CDTIPOPARCPRINCIPAL, CDTIPOINSCRICAO, IDPESSOAFISICA, IDINSTITUICAO, IDPARCFUNDIDO ) VALUES ( 4385, 1739, 'LALLEGRO ACTION TECNOLOGY INDUSTRIA E COMERCIO DE', 'LALLEGRO ACTION TECNOLOGY INDUSTRIA E COMERCIO DE', '03801629000200', 'S', SYSDATE, 4385, '000000099991', 'ESTRUTURA', 'CNPJ', 'N', 'N', 'N' ); INSERT INTO ESTRUTURAM ( NRORG, NRESTRUTURAM, NRPARCNEGOCIO, CDINTESTRUTURA, NRTIPOESTRUTURA, DTINIVIGENCIA, DTFIMVIGENCIA, NMESTRUTURAM, IDATIVO, DTINCLUSAO, CDOPERINCLUSAO ) VALUES ( 4385, 167, 1739, '001.127', 5, '01/01/2000', '', NVL( 'LALLEGRO ACTION TECNOLOGY INDUSTRIA E COMERCIO DE', NVL( 'LALLEGRO ACTION TECNOLOGY INDUSTRIA E COMERCIO DE', 'LALLEGRO ACTION TECNOLOGY INDUSTRIA E COMERCIO DE' ) ), 'S', SYSDATE, '000000099991'); INSERT INTO ESTRUTURAH ( NRORG, NRESTRUTURAM, NRESTRUTURAH, NRPARCNEGOCIO, DTMESCOMPETENC, CDCNPJESTRUT, CDCEIESTRUT, NMRAZSOCESTRUT, NMFANTASIA, NMESTRUTURAH, CDNATUJURI, CDCNAE, NRCAGED, IDTIPOEMPR, IDOPTSIMPLES, IDPARTICIPAT, CDCPFESTRUTURA, DTBASESINDICAL, CDSINDICAL, IDATIVO, DTINCLUSAO, CDOPERINCLUSAO) VALUES ( 4385, 167, 167, 1739, '01/01/2000', '03801629000200', '', 'LALLEGRO ACTION TECNOLOGY INDUSTRIA E COMERCIO DE', 'LALLEGRO ACTION TECNOLOGY INDUSTRIA E COMERCIO DE', NVL( 'LALLEGRO ACTION TECNOLOGY INDUSTRIA E COMERCIO DE', NVL( 'LALLEGRO ACTION TECNOLOGY INDUSTRIA E COMERCIO DE', 'LALLEGRO ACTION TECNOLOGY INDUSTRIA E COMERCIO DE' ) ), '2062', '2710403', '', '', NVL( 'N', 'N' ), '', '', '', '', 'S', SYSDATE, '000000099991'); INSERT INTO ENDERECOPARC ( NRORG, NRENDERECOPARC, NRPARCNEGOCIO, CDTIPOENDERECO, IDATIVO, DTINCLUSAO, CDOPERINCLUSAO, CDPAIS, SGESTADO, CDLOGRADOURO, NMBAIRROENDERECO, DSREFERENCIAENDE, NRCEPENDERECO, DSENDERECO, NRIMOVELENDERECO, CDMUNICIPIO ) VALUES ( 4385, 1719, 1739, 'OUTROS', 'S', SYSDATE, '000000099991', LPAD( '0055', 4, '0' ), 'MG', 'AV', 'DIST. IND. CLAUDIO GALVÃO NOGUEIRA', '', '37066440', 'OTTO SALGADO', '295', ( SELECT MAX( CDMUNICIPIO ) FROM MUNICIPIO WHERE UPPER( NMMUNICIPIO ) = 'VARGINHA' AND CDPAIS = LPAD( '0055', 4, '0' ) AND SGESTADO = 'MG' ) ); COMMIT; | BP3: Template | BT3: Mnemônico | BU3: @NRPARCNEGOCIO@ | BV3: @NRESTRUTURAM@ | BW3: @NRESTRUTURAH@ | BX3: @NRENDERECOPARC@ | BY3: Mnemônico | BZ3: =BU3 -> @NRPARCNEGOCIO@ | CA3: =BV3 -> @NRESTRUTURAM@ | CB3: =BW3 -> @NRESTRUTURAH@ | CC3: =BX3 -> @NRENDERECOPARC@
A4: 5 | B4: 01/01/2000 | D4: 001.058 | E4: =B4 -> 01/01/2000 | F4: 59106377000172 | H4: LALLEGRO METAGAL INDÚSTRIA E COMÉRCIO LTDA - MG | I4: 2062 | J4: 2949299 | P4: OUTROS | Q4: 0055 | R4: MG | S4: SANTA RITA SAPUCAI | T4: ROD | U4: BR 459, KM 121 | V4: 333 | W4: DISTRITO INDUSTRIAL | X4: 37540-000 | Z4: =H4 -> LALLEGRO METAGAL INDÚSTRIA E COMÉRCIO LTDA - MG | AA4: =Z4 -> LALLEGRO METAGAL INDÚSTRIA E COMÉRCIO LTDA - MG | AE4: =IF(COUNTIF(Base!A:A, D4)=0,"insere","não") -> insere | AG4: =AG3+1 -> 1740 | AH4: =AH3+1 -> 168 | AI4: =AI3+1 -> 168 | AJ4: =IF(AZ4="insere",LARGE($AJ$2:AJ3,1)+1,"") -> 1720 | AK4: =SUBSTITUTE(SUBSTITUTE(SUBSTITUTE(SUBSTITUTE(SUBSTITUTE(F4," ",""),"-",""),".",""),"/",""),"\","") -> 59106377000172 | AL4: =SUBSTITUTE(SUBSTITUTE(SUBSTITUTE(SUBSTITUTE(SUBSTITUTE(G4," ",""),"-",""),".",""),"/",""),"\","") | AM4: =TRIM(SUBSTITUTE(SUBSTITUTE(H4,"'",""),"&","")) -> LALLEGRO METAGAL INDÚSTRIA E COMÉRCIO LTDA - MG | AN4: =SUBSTITUTE(SUBSTITUTE(SUBSTITUTE(SUBSTITUTE(SUBSTITUTE(I4," ",""),"-",""),".",""),"/",""),"\","") -> 2062 | AO4: =SUBSTITUTE(SUBSTITUTE(SUBSTITUTE(SUBSTITUTE(SUBSTITUTE(J4," ",""),"-",""),".",""),"/",""),"\","") -> 2949299 | AP4: =SUBSTITUTE(SUBSTITUTE(SUBSTITUTE(SUBSTITUTE(SUBSTITUTE(K4," ",""),"-",""),".",""),"/",""),"\","") | AQ4: =SUBSTITUTE(SUBSTITUTE(SUBSTITUTE(SUBSTITUTE(SUBSTITUTE(L4," ",""),"-",""),".",""),"/",""),"\","") | AR4: =IF(TRIM(N4)="","N",TRIM(N4)) -> N | AS4: =TRIM(O4) | AT4: =IF( TRIM( P4 ) = "", "PRINCIPAL", UPPER( TRIM( P4 ) ) ) -> OUTROS | AU4: =TEXT(Q4,"0000") -> 0055 | AV4: =LEFT(TRIM(SUBSTITUTE(SUBSTITUTE(R4,"'",""),"&","")),2) -> MG | AW4: {=UPPER( TRIM( MIG_REMOVER.ESPECIAL( S4 ) ) )} -> SANTA RITA SAPUCAI | AX4: =LEFT(TRIM(SUBSTITUTE(SUBSTITUTE(SUBSTITUTE(SUBSTITUTE(SUBSTITUTE(UPPER(T4),"'",""),"&",""),"Á","A"),"Ã","A"),"Ç","C")),4) -> ROD | AY4: =TRIM(SUBSTITUTE(SUBSTITUTE(U4,"'",""),"&","")) -> BR 459, KM 121 | AZ4: =IF(AND(AT4<>"",AY4<>""),"insere","não") -> insere | BA4: =TRIM(V4) -> 333 | BB4: =TRIM(SUBSTITUTE(SUBSTITUTE(W4,"'",""),"&","")) -> DISTRITO INDUSTRIAL | BC4: =SUBSTITUTE(SUBSTITUTE(SUBSTITUTE(SUBSTITUTE(SUBSTITUTE(X4," ",""),"-",""),".",""),"/",""),"\","") -> 37540000 | BD4: =TRIM(SUBSTITUTE(SUBSTITUTE(Y4,"'",""),"&","")) | BE4: =TRIM(SUBSTITUTE(SUBSTITUTE(Z4,"'",""),"&","")) -> LALLEGRO METAGAL INDÚSTRIA E COMÉRCIO LTDA - MG | BF4: =TRIM(SUBSTITUTE(SUBSTITUTE(AA4,"'",""),"&","")) -> LALLEGRO METAGAL INDÚSTRIA E COMÉRCIO LTDA - MG | BG4: =IF(AM4<>"",AM4,IF(BE4<>"",BE4,IF(BF4<>"",BF4,"Estrutura "&AH4&" - "&D4))) -> LALLEGRO METAGAL INDÚSTRIA E COMÉRCIO LTDA - MG | BH4: =SUBSTITUTE(SUBSTITUTE(SUBSTITUTE(SUBSTITUTE(SUBSTITUTE(AB4," ",""),"-",""),".",""),"/",""),"\","") | BI4: =TEXT(B4,"DD/MM/AAAA") -> 01/01/2000 | BJ4: =TRIM(IF(C4="","",TEXT(C4,"DD/MM/AAAA"))) | BK4: =IF(E4="","",TEXT(E4,"DD/MM/AAAA")) -> 01/01/2000 | BL4: =TRIM(IF(AC4="","",TEXT(AC4,"DD/MM/AAAA"))) | BM4: =SUBSTITUTE( SUBSTITUTE( SUBSTITUTE( SUBSTITUTE( SUBSTITUTE( SUBSTITUTE( SUBSTITUTE( SUBSTITUTE( SUBSTITUTE( SUBSTITUTE( SUBSTITUTE( SUBSTITUTE( SUBSTITUTE( SUBSTITUTE( SUBSTITUTE( SUBSTITUTE( SUBSTITUTE( SUBSTITUTE( SUBSTITUTE( SUBSTITUTE( SUBSTITUTE( SUBSTITUTE( SUBSTITUTE( SUBSTITUTE( $BM$2, "@NRORG@", $AF$2 ), "@NRPARCNEGOCIO@", $AG4 ), "@NMPRINCIPALPARC@", $BG4 ), "@CNPJ@", $AK4 ), "@NRESTRUTURAM@", $AH4 ), "@NRESTRUTURA@", $D4 ), "@NRTPESTRUTURA@", $A4 ), "@DTINIVIGENCIA@", $BI4 ), "@DTFIMVIGENCIA@", $BJ4 ), "@NMESTRUTURA@", $BF4 ), "@NMFANTASIA@", $BE4 ), "@RAZAOSOCIAL@", $AM4 ), "@NRESTRUTURAH@", $AI4 ), "@COMPETENCIA@", $BK4 ), "@CEI@", $AL4 ), "@NATJURIDICA@", $AN4 ), "@CDCNAE@", $AO4 ), "@CDCAGED@", $AQ4 ), "@IDTPEMPRESA@", $M4 ), "@IDSIMPLES@", $AR4 ), "@IDPARTICIPAT@", $AS4 ), "@CDCPFESTRUTURA@", $BH4 ), "@DTBASESINDICAL@", $BL4 ), "@CDSINDICAL@", $AD4 ) -> INSERT INTO PARCNEGOCIO ( NRORG, NRPARCNEGOCIO, NMPRINCIPALPARC, NMSECUNDARIPARC, NRINSCRICAOPARC, IDATIVO, DTINCLUSAO, NRORGINCLUSAO, CDOPERINCLUSAO, CDTIPOPARCPRINCIPAL, CDTIPOINSCRICAO, IDPESSOAFISICA, IDINSTITUICAO, IDPARCFUNDIDO ) VALUES ( 4385, 1740, 'LALLEGRO METAGAL INDÚSTRIA E COMÉRCIO LTDA - MG', 'LALLEGRO METAGAL INDÚSTRIA E COMÉRCIO LTDA - MG', '59106377000172', 'S', SYSDATE, 4385, '000000099991', 'ESTRUTURA', 'CNPJ', 'N', 'N', 'N' ); INSERT INTO ESTRUTURAM ( NRORG, NRESTRUTURAM, NRPARCNEGOCIO, CDINTESTRUTURA, NRTIPOESTRUTURA, DTINIVIGENCIA, DTFIMVIGENCIA, NMESTRUTURAM, IDATIVO, DTINCLUSAO, CDOPERINCLUSAO ) VALUES ( 4385, 168, 1740, '001.058', 5, '01/01/2000', '', NVL( 'LALLEGRO METAGAL INDÚSTRIA E COMÉRCIO LTDA - MG', NVL( 'LALLEGRO METAGAL INDÚSTRIA E COMÉRCIO LTDA - MG', 'LALLEGRO METAGAL INDÚSTRIA E COMÉRCIO LTDA - MG' ) ), 'S', SYSDATE, '000000099991'); INSERT INTO ESTRUTURAH ( NRORG, NRESTRUTURAM, NRESTRUTURAH, NRPARCNEGOCIO, DTMESCOMPETENC, CDCNPJESTRUT, CDCEIESTRUT, NMRAZSOCESTRUT, NMFANTASIA, NMESTRUTURAH, CDNATUJURI, CDCNAE, NRCAGED, IDTIPOEMPR, IDOPTSIMPLES, IDPARTICIPAT, CDCPFESTRUTURA, DTBASESINDICAL, CDSINDICAL, IDATIVO, DTINCLUSAO, CDOPERINCLUSAO) VALUES ( 4385, 168, 168, 1740, '01/01/2000', '59106377000172', '', 'LALLEGRO METAGAL INDÚSTRIA E COMÉRCIO LTDA - MG', 'LALLEGRO METAGAL INDÚSTRIA E COMÉRCIO LTDA - MG', NVL( 'LALLEGRO METAGAL INDÚSTRIA E COMÉRCIO LTDA - MG', NVL( 'LALLEGRO METAGAL INDÚSTRIA E COMÉRCIO LTDA - MG', 'LALLEGRO METAGAL INDÚSTRIA E COMÉRCIO LTDA - MG' ) ), '2062', '2949299', '', '', NVL( 'N', 'N' ), '', '', '', '', 'S', SYSDATE, '000000099991'); | BN4: =SUBSTITUTE( SUBSTITUTE( SUBSTITUTE( SUBSTITUTE( SUBSTITUTE( SUBSTITUTE( SUBSTITUTE( SUBSTITUTE( SUBSTITUTE( SUBSTITUTE( SUBSTITUTE( SUBSTITUTE( SUBSTITUTE( $BN$2, "@NRORG@", $AF$2 ), "@NRENDERECOPARC@", $AJ4 ), "@NRPARCNEGOCIO@", $AG4 ), "@IDENDERECO@", $AT4 ), "@CDPAIS@", $AU4 ), "@SGESTADO@", $AV4 ), "@LOGRADOURO@", $AX4 ), "@BAIRRO@", $BB4 ), "@REFERENCIAENDERECO@", $BD4 ), "@CEP@", $BC4 ), "@ENDERECO@", $AY4 ), "@NUMERO@", $BA4 ), "@MUNICIPIO@", $AW4 ) -> INSERT INTO ENDERECOPARC ( NRORG, NRENDERECOPARC, NRPARCNEGOCIO, CDTIPOENDERECO, IDATIVO, DTINCLUSAO, CDOPERINCLUSAO, CDPAIS, SGESTADO, CDLOGRADOURO, NMBAIRROENDERECO, DSREFERENCIAENDE, NRCEPENDERECO, DSENDERECO, NRIMOVELENDERECO, CDMUNICIPIO ) VALUES ( 4385, 1720, 1740, 'OUTROS', 'S', SYSDATE, '000000099991', LPAD( '0055', 4, '0' ), 'MG', 'ROD', 'DISTRITO INDUSTRIAL', '', '37540000', 'BR 459, KM 121', '333', ( SELECT MAX( CDMUNICIPIO ) FROM MUNICIPIO WHERE UPPER( NMMUNICIPIO ) = 'SANTA RITA SAPUCAI' AND CDPAIS = LPAD( '0055', 4, '0' ) AND SGESTADO = 'MG' ) ); | BO4: =IF( AE4 <> "insere", "", BM4 & IF( AZ4 = "insere", " " & BN4, "" ) & " COMMIT;" ) -> INSERT INTO PARCNEGOCIO ( NRORG, NRPARCNEGOCIO, NMPRINCIPALPARC, NMSECUNDARIPARC, NRINSCRICAOPARC, IDATIVO, DTINCLUSAO, NRORGINCLUSAO, CDOPERINCLUSAO, CDTIPOPARCPRINCIPAL, CDTIPOINSCRICAO, IDPESSOAFISICA, IDINSTITUICAO, IDPARCFUNDIDO ) VALUES ( 4385, 1740, 'LALLEGRO METAGAL INDÚSTRIA E COMÉRCIO LTDA - MG', 'LALLEGRO METAGAL INDÚSTRIA E COMÉRCIO LTDA - MG', '59106377000172', 'S', SYSDATE, 4385, '000000099991', 'ESTRUTURA', 'CNPJ', 'N', 'N', 'N' ); INSERT INTO ESTRUTURAM ( NRORG, NRESTRUTURAM, NRPARCNEGOCIO, CDINTESTRUTURA, NRTIPOESTRUTURA, DTINIVIGENCIA, DTFIMVIGENCIA, NMESTRUTURAM, IDATIVO, DTINCLUSAO, CDOPERINCLUSAO ) VALUES ( 4385, 168, 1740, '001.058', 5, '01/01/2000', '', NVL( 'LALLEGRO METAGAL INDÚSTRIA E COMÉRCIO LTDA - MG', NVL( 'LALLEGRO METAGAL INDÚSTRIA E COMÉRCIO LTDA - MG', 'LALLEGRO METAGAL INDÚSTRIA E COMÉRCIO LTDA - MG' ) ), 'S', SYSDATE, '000000099991'); INSERT INTO ESTRUTURAH ( NRORG, NRESTRUTURAM, NRESTRUTURAH, NRPARCNEGOCIO, DTMESCOMPETENC, CDCNPJESTRUT, CDCEIESTRUT, NMRAZSOCESTRUT, NMFANTASIA, NMESTRUTURAH, CDNATUJURI, CDCNAE, NRCAGED, IDTIPOEMPR, IDOPTSIMPLES, IDPARTICIPAT, CDCPFESTRUTURA, DTBASESINDICAL, CDSINDICAL, IDATIVO, DTINCLUSAO, CDOPERINCLUSAO) VALUES ( 4385, 168, 168, 1740, '01/01/2000', '59106377000172', '', 'LALLEGRO METAGAL INDÚSTRIA E COMÉRCIO LTDA - MG', 'LALLEGRO METAGAL INDÚSTRIA E COMÉRCIO LTDA - MG', NVL( 'LALLEGRO METAGAL INDÚSTRIA E COMÉRCIO LTDA - MG', NVL( 'LALLEGRO METAGAL INDÚSTRIA E COMÉRCIO LTDA - MG', 'LALLEGRO METAGAL INDÚSTRIA E COMÉRCIO LTDA - MG' ) ), '2062', '2949299', '', '', NVL( 'N', 'N' ), '', '', '', '', 'S', SYSDATE, '000000099991'); INSERT INTO ENDERECOPARC ( NRORG, NRENDERECOPARC, NRPARCNEGOCIO, CDTIPOENDERECO, IDATIVO, DTINCLUSAO, CDOPERINCLUSAO, CDPAIS, SGESTADO, CDLOGRADOURO, NMBAIRROENDERECO, DSREFERENCIAENDE, NRCEPENDERECO, DSENDERECO, NRIMOVELENDERECO, CDMUNICIPIO ) VALUES ( 4385, 1720, 1740, 'OUTROS', 'S', SYSDATE, '000000099991', LPAD( '0055', 4, '0' ), 'MG', 'ROD', 'DISTRITO INDUSTRIAL', '', '37540000', 'BR 459, KM 121', '333', ( SELECT MAX( CDMUNICIPIO ) FROM MUNICIPIO WHERE UPPER( NMMUNICIPIO ) = 'SANTA RITA SAPUCAI' AND CDPAIS = LPAD( '0055', 4, '0' ) AND SGESTADO = 'MG' ) ); COMMIT; | BP4: Linhas | BQ4: =COUNTA( A:A ) -> 10 | BT4: Tabela | BU4: PARCNEGOCIO | BV4: ESTRUTURAM | BW4: ESTRUTURAH | BX4: ENDERECOPARC | BY4: Tabela | BZ4: =BU4 -> PARCNEGOCIO | CA4: =BV4 -> ESTRUTURAM | CB4: =BW4 -> ESTRUTURAH | CC4: =BX4 -> ENDERECOPARC | CD4: Tabela | CE4: =BZ4 -> PARCNEGOCIO | CF4: =CA4 -> ESTRUTURAM | CG4: =CB4 -> ESTRUTURAH | CH4: =CC4 -> ENDERECOPARC
A5: 5 | B5: 01/01/2000 | D5: 001.079 | E5: =B5 -> 01/01/2000 | F5: 01697279000177 | H5: LALLEGRO HYDAC TECNOLOGIA LTDA | I5: 2062 | J5: 2815102 | P5: OUTROS | Q5: 0055 | R5: SP | S5: SÃO BERNARDO DO CAMPO | T5: CJ | U5: FUKUTARO YIDA | V5: 225 | W5: COOPERATIVA | X5: 09852-060 | Z5: =H5 -> LALLEGRO HYDAC TECNOLOGIA LTDA | AA5: =Z5 -> LALLEGRO HYDAC TECNOLOGIA LTDA | AE5: =IF(COUNTIF(Base!A:A, D5)=0,"insere","não") -> insere | AG5: =AG4+1 -> 1741 | AH5: =AH4+1 -> 169 | AI5: =AI4+1 -> 169 | AJ5: =IF(AZ5="insere",LARGE($AJ$2:AJ4,1)+1,"") -> 1721 | AK5: =SUBSTITUTE(SUBSTITUTE(SUBSTITUTE(SUBSTITUTE(SUBSTITUTE(F5," ",""),"-",""),".",""),"/",""),"\","") -> 01697279000177 | AL5: =SUBSTITUTE(SUBSTITUTE(SUBSTITUTE(SUBSTITUTE(SUBSTITUTE(G5," ",""),"-",""),".",""),"/",""),"\","") | AM5: =TRIM(SUBSTITUTE(SUBSTITUTE(H5,"'",""),"&","")) -> LALLEGRO HYDAC TECNOLOGIA LTDA | AN5: =SUBSTITUTE(SUBSTITUTE(SUBSTITUTE(SUBSTITUTE(SUBSTITUTE(I5," ",""),"-",""),".",""),"/",""),"\","") -> 2062 | AO5: =SUBSTITUTE(SUBSTITUTE(SUBSTITUTE(SUBSTITUTE(SUBSTITUTE(J5," ",""),"-",""),".",""),"/",""),"\","") -> 2815102 | AP5: =SUBSTITUTE(SUBSTITUTE(SUBSTITUTE(SUBSTITUTE(SUBSTITUTE(K5," ",""),"-",""),".",""),"/",""),"\","") | AQ5: =SUBSTITUTE(SUBSTITUTE(SUBSTITUTE(SUBSTITUTE(SUBSTITUTE(L5," ",""),"-",""),".",""),"/",""),"\","") | AR5: =IF(TRIM(N5)="","N",TRIM(N5)) -> N | AS5: =TRIM(O5) | AT5: =IF( TRIM( P5 ) = "", "PRINCIPAL", UPPER( TRIM( P5 ) ) ) -> OUTROS | AU5: =TEXT(Q5,"0000") -> 0055 | AV5: =LEFT(TRIM(SUBSTITUTE(SUBSTITUTE(R5,"'",""),"&","")),2) -> SP | AW5: {=UPPER( TRIM( MIG_REMOVER.ESPECIAL( S5 ) ) )} -> SAO BERNARDO DO CAMPO | AX5: =LEFT(TRIM(SUBSTITUTE(SUBSTITUTE(SUBSTITUTE(SUBSTITUTE(SUBSTITUTE(UPPER(T5),"'",""),"&",""),"Á","A"),"Ã","A"),"Ç","C")),4) -> CJ | AY5: =TRIM(SUBSTITUTE(SUBSTITUTE(U5,"'",""),"&","")) -> FUKUTARO YIDA | AZ5: =IF(AND(AT5<>"",AY5<>""),"insere","não") -> insere | BA5: =TRIM(V5) -> 225 | BB5: =TRIM(SUBSTITUTE(SUBSTITUTE(W5,"'",""),"&","")) -> COOPERATIVA | BC5: =SUBSTITUTE(SUBSTITUTE(SUBSTITUTE(SUBSTITUTE(SUBSTITUTE(X5," ",""),"-",""),".",""),"/",""),"\","") -> 09852060 | BD5: =TRIM(SUBSTITUTE(SUBSTITUTE(Y5,"'",""),"&","")) | BE5: =TRIM(SUBSTITUTE(SUBSTITUTE(Z5,"'",""),"&","")) -> LALLEGRO HYDAC TECNOLOGIA LTDA | BF5: =TRIM(SUBSTITUTE(SUBSTITUTE(AA5,"'",""),"&","")) -> LALLEGRO HYDAC TECNOLOGIA LTDA | BG5: =IF(AM5<>"",AM5,IF(BE5<>"",BE5,IF(BF5<>"",BF5,"Estrutura "&AH5&" - "&D5))) -> LALLEGRO HYDAC TECNOLOGIA LTDA | BH5: =SUBSTITUTE(SUBSTITUTE(SUBSTITUTE(SUBSTITUTE(SUBSTITUTE(AB5," ",""),"-",""),".",""),"/",""),"\","") | BI5: =TEXT(B5,"DD/MM/AAAA") -> 01/01/2000 | BJ5: =TRIM(IF(C5="","",TEXT(C5,"DD/MM/AAAA"))) | BK5: =IF(E5="","",TEXT(E5,"DD/MM/AAAA")) -> 01/01/2000 | BL5: =TRIM(IF(AC5="","",TEXT(AC5,"DD/MM/AAAA"))) | BM5: =SUBSTITUTE( SUBSTITUTE( SUBSTITUTE( SUBSTITUTE( SUBSTITUTE( SUBSTITUTE( SUBSTITUTE( SUBSTITUTE( SUBSTITUTE( SUBSTITUTE( SUBSTITUTE( SUBSTITUTE( SUBSTITUTE( SUBSTITUTE( SUBSTITUTE( SUBSTITUTE( SUBSTITUTE( SUBSTITUTE( SUBSTITUTE( SUBSTITUTE( SUBSTITUTE( SUBSTITUTE( SUBSTITUTE( SUBSTITUTE( $BM$2, "@NRORG@", $AF$2 ), "@NRPARCNEGOCIO@", $AG5 ), "@NMPRINCIPALPARC@", $BG5 ), "@CNPJ@", $AK5 ), "@NRESTRUTURAM@", $AH5 ), "@NRESTRUTURA@", $D5 ), "@NRTPESTRUTURA@", $A5 ), "@DTINIVIGENCIA@", $BI5 ), "@DTFIMVIGENCIA@", $BJ5 ), "@NMESTRUTURA@", $BF5 ), "@NMFANTASIA@", $BE5 ), "@RAZAOSOCIAL@", $AM5 ), "@NRESTRUTURAH@", $AI5 ), "@COMPETENCIA@", $BK5 ), "@CEI@", $AL5 ), "@NATJURIDICA@", $AN5 ), "@CDCNAE@", $AO5 ), "@CDCAGED@", $AQ5 ), "@IDTPEMPRESA@", $M5 ), "@IDSIMPLES@", $AR5 ), "@IDPARTICIPAT@", $AS5 ), "@CDCPFESTRUTURA@", $BH5 ), "@DTBASESINDICAL@", $BL5 ), "@CDSINDICAL@", $AD5 ) -> INSERT INTO PARCNEGOCIO ( NRORG, NRPARCNEGOCIO, NMPRINCIPALPARC, NMSECUNDARIPARC, NRINSCRICAOPARC, IDATIVO, DTINCLUSAO, NRORGINCLUSAO, CDOPERINCLUSAO, CDTIPOPARCPRINCIPAL, CDTIPOINSCRICAO, IDPESSOAFISICA, IDINSTITUICAO, IDPARCFUNDIDO ) VALUES ( 4385, 1741, 'LALLEGRO HYDAC TECNOLOGIA LTDA', 'LALLEGRO HYDAC TECNOLOGIA LTDA', '01697279000177', 'S', SYSDATE, 4385, '000000099991', 'ESTRUTURA', 'CNPJ', 'N', 'N', 'N' ); INSERT INTO ESTRUTURAM ( NRORG, NRESTRUTURAM, NRPARCNEGOCIO, CDINTESTRUTURA, NRTIPOESTRUTURA, DTINIVIGENCIA, DTFIMVIGENCIA, NMESTRUTURAM, IDATIVO, DTINCLUSAO, CDOPERINCLUSAO ) VALUES ( 4385, 169, 1741, '001.079', 5, '01/01/2000', '', NVL( 'LALLEGRO HYDAC TECNOLOGIA LTDA', NVL( 'LALLEGRO HYDAC TECNOLOGIA LTDA', 'LALLEGRO HYDAC TECNOLOGIA LTDA' ) ), 'S', SYSDATE, '000000099991'); INSERT INTO ESTRUTURAH ( NRORG, NRESTRUTURAM, NRESTRUTURAH, NRPARCNEGOCIO, DTMESCOMPETENC, CDCNPJESTRUT, CDCEIESTRUT, NMRAZSOCESTRUT, NMFANTASIA, NMESTRUTURAH, CDNATUJURI, CDCNAE, NRCAGED, IDTIPOEMPR, IDOPTSIMPLES, IDPARTICIPAT, CDCPFESTRUTURA, DTBASESINDICAL, CDSINDICAL, IDATIVO, DTINCLUSAO, CDOPERINCLUSAO) VALUES ( 4385, 169, 169, 1741, '01/01/2000', '01697279000177', '', 'LALLEGRO HYDAC TECNOLOGIA LTDA', 'LALLEGRO HYDAC TECNOLOGIA LTDA', NVL( 'LALLEGRO HYDAC TECNOLOGIA LTDA', NVL( 'LALLEGRO HYDAC TECNOLOGIA LTDA', 'LALLEGRO HYDAC TECNOLOGIA LTDA' ) ), '2062', '2815102', '', '', NVL( 'N', 'N' ), '', '', '', '', 'S', SYSDATE, '000000099991'); | BN5: =SUBSTITUTE( SUBSTITUTE( SUBSTITUTE( SUBSTITUTE( SUBSTITUTE( SUBSTITUTE( SUBSTITUTE( SUBSTITUTE( SUBSTITUTE( SUBSTITUTE( SUBSTITUTE( SUBSTITUTE( SUBSTITUTE( $BN$2, "@NRORG@", $AF$2 ), "@NRENDERECOPARC@", $AJ5 ), "@NRPARCNEGOCIO@", $AG5 ), "@IDENDERECO@", $AT5 ), "@CDPAIS@", $AU5 ), "@SGESTADO@", $AV5 ), "@LOGRADOURO@", $AX5 ), "@BAIRRO@", $BB5 ), "@REFERENCIAENDERECO@", $BD5 ), "@CEP@", $BC5 ), "@ENDERECO@", $AY5 ), "@NUMERO@", $BA5 ), "@MUNICIPIO@", $AW5 ) -> INSERT INTO ENDERECOPARC ( NRORG, NRENDERECOPARC, NRPARCNEGOCIO, CDTIPOENDERECO, IDATIVO, DTINCLUSAO, CDOPERINCLUSAO, CDPAIS, SGESTADO, CDLOGRADOURO, NMBAIRROENDERECO, DSREFERENCIAENDE, NRCEPENDERECO, DSENDERECO, NRIMOVELENDERECO, CDMUNICIPIO ) VALUES ( 4385, 1721, 1741, 'OUTROS', 'S', SYSDATE, '000000099991', LPAD( '0055', 4, '0' ), 'SP', 'CJ', 'COOPERATIVA', '', '09852060', 'FUKUTARO YIDA', '225', ( SELECT MAX( CDMUNICIPIO ) FROM MUNICIPIO WHERE UPPER( NMMUNICIPIO ) = 'SAO BERNARDO DO CAMPO' AND CDPAIS = LPAD( '0055', 4, '0' ) AND SGESTADO = 'SP' ) ); | BO5: =IF( AE5 <> "insere", "", BM5 & IF( AZ5 = "insere", " " & BN5, "" ) & " COMMIT;" ) -> INSERT INTO PARCNEGOCIO ( NRORG, NRPARCNEGOCIO, NMPRINCIPALPARC, NMSECUNDARIPARC, NRINSCRICAOPARC, IDATIVO, DTINCLUSAO, NRORGINCLUSAO, CDOPERINCLUSAO, CDTIPOPARCPRINCIPAL, CDTIPOINSCRICAO, IDPESSOAFISICA, IDINSTITUICAO, IDPARCFUNDIDO ) VALUES ( 4385, 1741, 'LALLEGRO HYDAC TECNOLOGIA LTDA', 'LALLEGRO HYDAC TECNOLOGIA LTDA', '01697279000177', 'S', SYSDATE, 4385, '000000099991', 'ESTRUTURA', 'CNPJ', 'N', 'N', 'N' ); INSERT INTO ESTRUTURAM ( NRORG, NRESTRUTURAM, NRPARCNEGOCIO, CDINTESTRUTURA, NRTIPOESTRUTURA, DTINIVIGENCIA, DTFIMVIGENCIA, NMESTRUTURAM, IDATIVO, DTINCLUSAO, CDOPERINCLUSAO ) VALUES ( 4385, 169, 1741, '001.079', 5, '01/01/2000', '', NVL( 'LALLEGRO HYDAC TECNOLOGIA LTDA', NVL( 'LALLEGRO HYDAC TECNOLOGIA LTDA', 'LALLEGRO HYDAC TECNOLOGIA LTDA' ) ), 'S', SYSDATE, '000000099991'); INSERT INTO ESTRUTURAH ( NRORG, NRESTRUTURAM, NRESTRUTURAH, NRPARCNEGOCIO, DTMESCOMPETENC, CDCNPJESTRUT, CDCEIESTRUT, NMRAZSOCESTRUT, NMFANTASIA, NMESTRUTURAH, CDNATUJURI, CDCNAE, NRCAGED, IDTIPOEMPR, IDOPTSIMPLES, IDPARTICIPAT, CDCPFESTRUTURA, DTBASESINDICAL, CDSINDICAL, IDATIVO, DTINCLUSAO, CDOPERINCLUSAO) VALUES ( 4385, 169, 169, 1741, '01/01/2000', '01697279000177', '', 'LALLEGRO HYDAC TECNOLOGIA LTDA', 'LALLEGRO HYDAC TECNOLOGIA LTDA', NVL( 'LALLEGRO HYDAC TECNOLOGIA LTDA', NVL( 'LALLEGRO HYDAC TECNOLOGIA LTDA', 'LALLEGRO HYDAC TECNOLOGIA LTDA' ) ), '2062', '2815102', '', '', NVL( 'N', 'N' ), '', '', '', '', 'S', SYSDATE, '000000099991'); INSERT INTO ENDERECOPARC ( NRORG, NRENDERECOPARC, NRPARCNEGOCIO, CDTIPOENDERECO, IDATIVO, DTINCLUSAO, CDOPERINCLUSAO, CDPAIS, SGESTADO, CDLOGRADOURO, NMBAIRROENDERECO, DSREFERENCIAENDE, NRCEPENDERECO, DSENDERECO, NRIMOVELENDERECO, CDMUNICIPIO ) VALUES ( 4385, 1721, 1741, 'OUTROS', 'S', SYSDATE, '000000099991', LPAD( '0055', 4, '0' ), 'SP', 'CJ', 'COOPERATIVA', '', '09852060', 'FUKUTARO YIDA', '225', ( SELECT MAX( CDMUNICIPIO ) FROM MUNICIPIO WHERE UPPER( NMMUNICIPIO ) = 'SAO BERNARDO DO CAMPO' AND CDPAIS = LPAD( '0055', 4, '0' ) AND SGESTADO = 'SP' ) ); COMMIT; | BP5: Nro Estrutura | BQ5: ="D2:D" & BQ4 -> D2:D10 | BT5: PK | BU5: NRPARCNEGOCIO | BV5: NRESTRUTURAM | BW5: NRESTRUTURAH | BX5: NRENDERECOPARC | BY5: PK | BZ5: =BU5 -> NRPARCNEGOCIO | CA5: =BV5 -> NRESTRUTURAM | CB5: =BW5 -> NRESTRUTURAH | CC5: =BX5 -> NRENDERECOPARC | CD5: PK | CE5: =BZ5 -> NRPARCNEGOCIO | CF5: =CA5 -> NRESTRUTURAM | CG5: =CB5 -> NRESTRUTURAH | CH5: =CC5 -> NRENDERECOPARC
A6: 5 | B6: 01/01/2000 | D6: 001.122VCI | E6: =B6 -> 01/01/2000 | F6: 19076738000160 | H6: LALLEGRO VCI DO BRASIL INDUSTRIA E COMÉRCIO DE CO | I6: 2062 | J6: 2229302 | P6: OUTROS | Q6: 0055 | R6: SP | S6: ITUPEVA | T6: AV | U6: EMILIO CHECHINATO | V6: 4402 | W6: SÃO ROQUE DA CHAVE | X6: 13295-030 | Z6: =H6 -> LALLEGRO VCI DO BRASIL INDUSTRIA E COMÉRCIO DE CO | AA6: =Z6 -> LALLEGRO VCI DO BRASIL INDUSTRIA E COMÉRCIO DE CO | AE6: =IF(COUNTIF(Base!A:A, D6)=0,"insere","não") -> insere | AG6: =AG5+1 -> 1742 | AH6: =AH5+1 -> 170 | AI6: =AI5+1 -> 170 | AJ6: =IF(AZ6="insere",LARGE($AJ$2:AJ5,1)+1,"") -> 1722 | AK6: =SUBSTITUTE(SUBSTITUTE(SUBSTITUTE(SUBSTITUTE(SUBSTITUTE(F6," ",""),"-",""),".",""),"/",""),"\","") -> 19076738000160 | AL6: =SUBSTITUTE(SUBSTITUTE(SUBSTITUTE(SUBSTITUTE(SUBSTITUTE(G6," ",""),"-",""),".",""),"/",""),"\","") | AM6: =TRIM(SUBSTITUTE(SUBSTITUTE(H6,"'",""),"&","")) -> LALLEGRO VCI DO BRASIL INDUSTRIA E COMÉRCIO DE CO | AN6: =SUBSTITUTE(SUBSTITUTE(SUBSTITUTE(SUBSTITUTE(SUBSTITUTE(I6," ",""),"-",""),".",""),"/",""),"\","") -> 2062 | AO6: =SUBSTITUTE(SUBSTITUTE(SUBSTITUTE(SUBSTITUTE(SUBSTITUTE(J6," ",""),"-",""),".",""),"/",""),"\","") -> 2229302 | AP6: =SUBSTITUTE(SUBSTITUTE(SUBSTITUTE(SUBSTITUTE(SUBSTITUTE(K6," ",""),"-",""),".",""),"/",""),"\","") | AQ6: =SUBSTITUTE(SUBSTITUTE(SUBSTITUTE(SUBSTITUTE(SUBSTITUTE(L6," ",""),"-",""),".",""),"/",""),"\","") | AR6: =IF(TRIM(N6)="","N",TRIM(N6)) -> N | AS6: =TRIM(O6) | AT6: =IF( TRIM( P6 ) = "", "PRINCIPAL", UPPER( TRIM( P6 ) ) ) -> OUTROS | AU6: =TEXT(Q6,"0000") -> 0055 | AV6: =LEFT(TRIM(SUBSTITUTE(SUBSTITUTE(R6,"'",""),"&","")),2) -> SP | AW6: {=UPPER( TRIM( MIG_REMOVER.ESPECIAL( S6 ) ) )} -> ITUPEVA | AX6: =LEFT(TRIM(SUBSTITUTE(SUBSTITUTE(SUBSTITUTE(SUBSTITUTE(SUBSTITUTE(UPPER(T6),"'",""),"&",""),"Á","A"),"Ã","A"),"Ç","C")),4) -> AV | AY6: =TRIM(SUBSTITUTE(SUBSTITUTE(U6,"'",""),"&","")) -> EMILIO CHECHINATO | AZ6: =IF(AND(AT6<>"",AY6<>""),"insere","não") -> insere | BA6: =TRIM(V6) -> 4402 | BB6: =TRIM(SUBSTITUTE(SUBSTITUTE(W6,"'",""),"&","")) -> SÃO ROQUE DA CHAVE | BC6: =SUBSTITUTE(SUBSTITUTE(SUBSTITUTE(SUBSTITUTE(SUBSTITUTE(X6," ",""),"-",""),".",""),"/",""),"\","") -> 13295030 | BD6: =TRIM(SUBSTITUTE(SUBSTITUTE(Y6,"'",""),"&","")) | BE6: =TRIM(SUBSTITUTE(SUBSTITUTE(Z6,"'",""),"&","")) -> LALLEGRO VCI DO BRASIL INDUSTRIA E COMÉRCIO DE CO | BF6: =TRIM(SUBSTITUTE(SUBSTITUTE(AA6,"'",""),"&","")) -> LALLEGRO VCI DO BRASIL INDUSTRIA E COMÉRCIO DE CO | BG6: =IF(AM6<>"",AM6,IF(BE6<>"",BE6,IF(BF6<>"",BF6,"Estrutura "&AH6&" - "&D6))) -> LALLEGRO VCI DO BRASIL INDUSTRIA E COMÉRCIO DE CO | BH6: =SUBSTITUTE(SUBSTITUTE(SUBSTITUTE(SUBSTITUTE(SUBSTITUTE(AB6," ",""),"-",""),".",""),"/",""),"\","") | BI6: =TEXT(B6,"DD/MM/AAAA") -> 01/01/2000 | BJ6: =TRIM(IF(C6="","",TEXT(C6,"DD/MM/AAAA"))) | BK6: =IF(E6="","",TEXT(E6,"DD/MM/AAAA")) -> 01/01/2000 | BL6: =TRIM(IF(AC6="","",TEXT(AC6,"DD/MM/AAAA"))) | BM6: =SUBSTITUTE( SUBSTITUTE( SUBSTITUTE( SUBSTITUTE( SUBSTITUTE( SUBSTITUTE( SUBSTITUTE( SUBSTITUTE( SUBSTITUTE( SUBSTITUTE( SUBSTITUTE( SUBSTITUTE( SUBSTITUTE( SUBSTITUTE( SUBSTITUTE( SUBSTITUTE( SUBSTITUTE( SUBSTITUTE( SUBSTITUTE( SUBSTITUTE( SUBSTITUTE( SUBSTITUTE( SUBSTITUTE( SUBSTITUTE( $BM$2, "@NRORG@", $AF$2 ), "@NRPARCNEGOCIO@", $AG6 ), "@NMPRINCIPALPARC@", $BG6 ), "@CNPJ@", $AK6 ), "@NRESTRUTURAM@", $AH6 ), "@NRESTRUTURA@", $D6 ), "@NRTPESTRUTURA@", $A6 ), "@DTINIVIGENCIA@", $BI6 ), "@DTFIMVIGENCIA@", $BJ6 ), "@NMESTRUTURA@", $BF6 ), "@NMFANTASIA@", $BE6 ), "@RAZAOSOCIAL@", $AM6 ), "@NRESTRUTURAH@", $AI6 ), "@COMPETENCIA@", $BK6 ), "@CEI@", $AL6 ), "@NATJURIDICA@", $AN6 ), "@CDCNAE@", $AO6 ), "@CDCAGED@", $AQ6 ), "@IDTPEMPRESA@", $M6 ), "@IDSIMPLES@", $AR6 ), "@IDPARTICIPAT@", $AS6 ), "@CDCPFESTRUTURA@", $BH6 ), "@DTBASESINDICAL@", $BL6 ), "@CDSINDICAL@", $AD6 ) -> INSERT INTO PARCNEGOCIO ( NRORG, NRPARCNEGOCIO, NMPRINCIPALPARC, NMSECUNDARIPARC, NRINSCRICAOPARC, IDATIVO, DTINCLUSAO, NRORGINCLUSAO, CDOPERINCLUSAO, CDTIPOPARCPRINCIPAL, CDTIPOINSCRICAO, IDPESSOAFISICA, IDINSTITUICAO, IDPARCFUNDIDO ) VALUES ( 4385, 1742, 'LALLEGRO VCI DO BRASIL INDUSTRIA E COMÉRCIO DE CO', 'LALLEGRO VCI DO BRASIL INDUSTRIA E COMÉRCIO DE CO', '19076738000160', 'S', SYSDATE, 4385, '000000099991', 'ESTRUTURA', 'CNPJ', 'N', 'N', 'N' ); INSERT INTO ESTRUTURAM ( NRORG, NRESTRUTURAM, NRPARCNEGOCIO, CDINTESTRUTURA, NRTIPOESTRUTURA, DTINIVIGENCIA, DTFIMVIGENCIA, NMESTRUTURAM, IDATIVO, DTINCLUSAO, CDOPERINCLUSAO ) VALUES ( 4385, 170, 1742, '001.122VCI', 5, '01/01/2000', '', NVL( 'LALLEGRO VCI DO BRASIL INDUSTRIA E COMÉRCIO DE CO', NVL( 'LALLEGRO VCI DO BRASIL INDUSTRIA E COMÉRCIO DE CO', 'LALLEGRO VCI DO BRASIL INDUSTRIA E COMÉRCIO DE CO' ) ), 'S', SYSDATE, '000000099991'); INSERT INTO ESTRUTURAH ( NRORG, NRESTRUTURAM, NRESTRUTURAH, NRPARCNEGOCIO, DTMESCOMPETENC, CDCNPJESTRUT, CDCEIESTRUT, NMRAZSOCESTRUT, NMFANTASIA, NMESTRUTURAH, CDNATUJURI, CDCNAE, NRCAGED, IDTIPOEMPR, IDOPTSIMPLES, IDPARTICIPAT, CDCPFESTRUTURA, DTBASESINDICAL, CDSINDICAL, IDATIVO, DTINCLUSAO, CDOPERINCLUSAO) VALUES ( 4385, 170, 170, 1742, '01/01/2000', '19076738000160', '', 'LALLEGRO VCI DO BRASIL INDUSTRIA E COMÉRCIO DE CO', 'LALLEGRO VCI DO BRASIL INDUSTRIA E COMÉRCIO DE CO', NVL( 'LALLEGRO VCI DO BRASIL INDUSTRIA E COMÉRCIO DE CO', NVL( 'LALLEGRO VCI DO BRASIL INDUSTRIA E COMÉRCIO DE CO', 'LALLEGRO VCI DO BRASIL INDUSTRIA E COMÉRCIO DE CO' ) ), '2062', '2229302', '', '', NVL( 'N', 'N' ), '', '', '', '', 'S', SYSDATE, '000000099991'); | BN6: =SUBSTITUTE( SUBSTITUTE( SUBSTITUTE( SUBSTITUTE( SUBSTITUTE( SUBSTITUTE( SUBSTITUTE( SUBSTITUTE( SUBSTITUTE( SUBSTITUTE( SUBSTITUTE( SUBSTITUTE( SUBSTITUTE( $BN$2, "@NRORG@", $AF$2 ), "@NRENDERECOPARC@", $AJ6 ), "@NRPARCNEGOCIO@", $AG6 ), "@IDENDERECO@", $AT6 ), "@CDPAIS@", $AU6 ), "@SGESTADO@", $AV6 ), "@LOGRADOURO@", $AX6 ), "@BAIRRO@", $BB6 ), "@REFERENCIAENDERECO@", $BD6 ), "@CEP@", $BC6 ), "@ENDERECO@", $AY6 ), "@NUMERO@", $BA6 ), "@MUNICIPIO@", $AW6 ) -> INSERT INTO ENDERECOPARC ( NRORG, NRENDERECOPARC, NRPARCNEGOCIO, CDTIPOENDERECO, IDATIVO, DTINCLUSAO, CDOPERINCLUSAO, CDPAIS, SGESTADO, CDLOGRADOURO, NMBAIRROENDERECO, DSREFERENCIAENDE, NRCEPENDERECO, DSENDERECO, NRIMOVELENDERECO, CDMUNICIPIO ) VALUES ( 4385, 1722, 1742, 'OUTROS', 'S', SYSDATE, '000000099991', LPAD( '0055', 4, '0' ), 'SP', 'AV', 'SÃO ROQUE DA CHAVE', '', '13295030', 'EMILIO CHECHINATO', '4402', ( SELECT MAX( CDMUNICIPIO ) FROM MUNICIPIO WHERE UPPER( NMMUNICIPIO ) = 'ITUPEVA' AND CDPAIS = LPAD( '0055', 4, '0' ) AND SGESTADO = 'SP' ) ); | BO6: =IF( AE6 <> "insere", "", BM6 & IF( AZ6 = "insere", " " & BN6, "" ) & " COMMIT;" ) -> INSERT INTO PARCNEGOCIO ( NRORG, NRPARCNEGOCIO, NMPRINCIPALPARC, NMSECUNDARIPARC, NRINSCRICAOPARC, IDATIVO, DTINCLUSAO, NRORGINCLUSAO, CDOPERINCLUSAO, CDTIPOPARCPRINCIPAL, CDTIPOINSCRICAO, IDPESSOAFISICA, IDINSTITUICAO, IDPARCFUNDIDO ) VALUES ( 4385, 1742, 'LALLEGRO VCI DO BRASIL INDUSTRIA E COMÉRCIO DE CO', 'LALLEGRO VCI DO BRASIL INDUSTRIA E COMÉRCIO DE CO', '19076738000160', 'S', SYSDATE, 4385, '000000099991', 'ESTRUTURA', 'CNPJ', 'N', 'N', 'N' ); INSERT INTO ESTRUTURAM ( NRORG, NRESTRUTURAM, NRPARCNEGOCIO, CDINTESTRUTURA, NRTIPOESTRUTURA, DTINIVIGENCIA, DTFIMVIGENCIA, NMESTRUTURAM, IDATIVO, DTINCLUSAO, CDOPERINCLUSAO ) VALUES ( 4385, 170, 1742, '001.122VCI', 5, '01/01/2000', '', NVL( 'LALLEGRO VCI DO BRASIL INDUSTRIA E COMÉRCIO DE CO', NVL( 'LALLEGRO VCI DO BRASIL INDUSTRIA E COMÉRCIO DE CO', 'LALLEGRO VCI DO BRASIL INDUSTRIA E COMÉRCIO DE CO' ) ), 'S', SYSDATE, '000000099991'); INSERT INTO ESTRUTURAH ( NRORG, NRESTRUTURAM, NRESTRUTURAH, NRPARCNEGOCIO, DTMESCOMPETENC, CDCNPJESTRUT, CDCEIESTRUT, NMRAZSOCESTRUT, NMFANTASIA, NMESTRUTURAH, CDNATUJURI, CDCNAE, NRCAGED, IDTIPOEMPR, IDOPTSIMPLES, IDPARTICIPAT, CDCPFESTRUTURA, DTBASESINDICAL, CDSINDICAL, IDATIVO, DTINCLUSAO, CDOPERINCLUSAO) VALUES ( 4385, 170, 170, 1742, '01/01/2000', '19076738000160', '', 'LALLEGRO VCI DO BRASIL INDUSTRIA E COMÉRCIO DE CO', 'LALLEGRO VCI DO BRASIL INDUSTRIA E COMÉRCIO DE CO', NVL( 'LALLEGRO VCI DO BRASIL INDUSTRIA E COMÉRCIO DE CO', NVL( 'LALLEGRO VCI DO BRASIL INDUSTRIA E COMÉRCIO DE CO', 'LALLEGRO VCI DO BRASIL INDUSTRIA E COMÉRCIO DE CO' ) ), '2062', '2229302', '', '', NVL( 'N', 'N' ), '', '', '', '', 'S', SYSDATE, '000000099991'); INSERT INTO ENDERECOPARC ( NRORG, NRENDERECOPARC, NRPARCNEGOCIO, CDTIPOENDERECO, IDATIVO, DTINCLUSAO, CDOPERINCLUSAO, CDPAIS, SGESTADO, CDLOGRADOURO, NMBAIRROENDERECO, DSREFERENCIAENDE, NRCEPENDERECO, DSENDERECO, NRIMOVELENDERECO, CDMUNICIPIO ) VALUES ( 4385, 1722, 1742, 'OUTROS', 'S', SYSDATE, '000000099991', LPAD( '0055', 4, '0' ), 'SP', 'AV', 'SÃO ROQUE DA CHAVE', '', '13295030', 'EMILIO CHECHINATO', '4402', ( SELECT MAX( CDMUNICIPIO ) FROM MUNICIPIO WHERE UPPER( NMMUNICIPIO ) = 'ITUPEVA' AND CDPAIS = LPAD( '0055', 4, '0' ) AND SGESTADO = 'SP' ) ); COMMIT; | BP6: Base | BT6: Inicio PK | BU6: =MIN(OFFSET($A$1,2,MATCH(BU$3,$1:$1,0)-1,1048574,1)) -> 1739 | BV6: =MIN(OFFSET($A$1,2,MATCH(BV$3,$1:$1,0)-1,1048574,1)) -> 167 | BW6: =MIN(OFFSET($A$1,2,MATCH(BW$3,$1:$1,0)-1,1048574,1)) -> 167 | BX6: =MIN(OFFSET($A$1,2,MATCH(BX$3,$1:$1,0)-1,1048574,1)) -> 1719 | BY6: Inicio PK | BZ6: =BU6 -> 1739 | CA6: =BV6 -> 167 | CB6: =BW6 -> 167 | CC6: =BX6 -> 1719
A7: 5 | B7: 01/01/2000 | D7: 001.110 | E7: =B7 -> 01/01/2000 | F7: 02528634000147 | H7: LALLEGRO SABAF DO BRASIL LTDA | I7: 2062 | J7: 2751100 | P7: OUTROS | Q7: 0055 | R7: SP | S7: JUNDIAI | T7: RUA | U7: GUSTAVO HENRIQUE MEERSON | V7: 355 | W7: PARQUE INDUSTRIAL III | X7: 13213-084 | Y7: CONDOMINIO FRAZGRAN | Z7: =H7 -> LALLEGRO SABAF DO BRASIL LTDA | AA7: =Z7 -> LALLEGRO SABAF DO BRASIL LTDA | AE7: =IF(COUNTIF(Base!A:A, D7)=0,"insere","não") -> insere | AG7: =AG6+1 -> 1743 | AH7: =AH6+1 -> 171 | AI7: =AI6+1 -> 171 | AJ7: =IF(AZ7="insere",LARGE($AJ$2:AJ6,1)+1,"") -> 1723 | AK7: =SUBSTITUTE(SUBSTITUTE(SUBSTITUTE(SUBSTITUTE(SUBSTITUTE(F7," ",""),"-",""),".",""),"/",""),"\","") -> 02528634000147 | AL7: =SUBSTITUTE(SUBSTITUTE(SUBSTITUTE(SUBSTITUTE(SUBSTITUTE(G7," ",""),"-",""),".",""),"/",""),"\","") | AM7: =TRIM(SUBSTITUTE(SUBSTITUTE(H7,"'",""),"&","")) -> LALLEGRO SABAF DO BRASIL LTDA | AN7: =SUBSTITUTE(SUBSTITUTE(SUBSTITUTE(SUBSTITUTE(SUBSTITUTE(I7," ",""),"-",""),".",""),"/",""),"\","") -> 2062 | AO7: =SUBSTITUTE(SUBSTITUTE(SUBSTITUTE(SUBSTITUTE(SUBSTITUTE(J7," ",""),"-",""),".",""),"/",""),"\","") -> 2751100 | AP7: =SUBSTITUTE(SUBSTITUTE(SUBSTITUTE(SUBSTITUTE(SUBSTITUTE(K7," ",""),"-",""),".",""),"/",""),"\","") | AQ7: =SUBSTITUTE(SUBSTITUTE(SUBSTITUTE(SUBSTITUTE(SUBSTITUTE(L7," ",""),"-",""),".",""),"/",""),"\","") | AR7: =IF(TRIM(N7)="","N",TRIM(N7)) -> N | AS7: =TRIM(O7) | AT7: =IF( TRIM( P7 ) = "", "PRINCIPAL", UPPER( TRIM( P7 ) ) ) -> OUTROS | AU7: =TEXT(Q7,"0000") -> 0055 | AV7: =LEFT(TRIM(SUBSTITUTE(SUBSTITUTE(R7,"'",""),"&","")),2) -> SP | AW7: {=UPPER( TRIM( MIG_REMOVER.ESPECIAL( S7 ) ) )} -> JUNDIAI | AX7: =LEFT(TRIM(SUBSTITUTE(SUBSTITUTE(SUBSTITUTE(SUBSTITUTE(SUBSTITUTE(UPPER(T7),"'",""),"&",""),"Á","A"),"Ã","A"),"Ç","C")),4) -> RUA | AY7: =TRIM(SUBSTITUTE(SUBSTITUTE(U7,"'",""),"&","")) -> GUSTAVO HENRIQUE MEERSON | AZ7: =IF(AND(AT7<>"",AY7<>""),"insere","não") -> insere | BA7: =TRIM(V7) -> 355 | BB7: =TRIM(SUBSTITUTE(SUBSTITUTE(W7,"'",""),"&","")) -> PARQUE INDUSTRIAL III | BC7: =SUBSTITUTE(SUBSTITUTE(SUBSTITUTE(SUBSTITUTE(SUBSTITUTE(X7," ",""),"-",""),".",""),"/",""),"\","") -> 13213084 | BD7: =TRIM(SUBSTITUTE(SUBSTITUTE(Y7,"'",""),"&","")) -> CONDOMINIO FRAZGRAN | BE7: =TRIM(SUBSTITUTE(SUBSTITUTE(Z7,"'",""),"&","")) -> LALLEGRO SABAF DO BRASIL LTDA | BF7: =TRIM(SUBSTITUTE(SUBSTITUTE(AA7,"'",""),"&","")) -> LALLEGRO SABAF DO BRASIL LTDA | BG7: =IF(AM7<>"",AM7,IF(BE7<>"",BE7,IF(BF7<>"",BF7,"Estrutura "&AH7&" - "&D7))) -> LALLEGRO SABAF DO BRASIL LTDA | BH7: =SUBSTITUTE(SUBSTITUTE(SUBSTITUTE(SUBSTITUTE(SUBSTITUTE(AB7," ",""),"-",""),".",""),"/",""),"\","") | BI7: =TEXT(B7,"DD/MM/AAAA") -> 01/01/2000 | BJ7: =TRIM(IF(C7="","",TEXT(C7,"DD/MM/AAAA"))) | BK7: =IF(E7="","",TEXT(E7,"DD/MM/AAAA")) -> 01/01/2000 | BL7: =TRIM(IF(AC7="","",TEXT(AC7,"DD/MM/AAAA"))) | BM7: =SUBSTITUTE( SUBSTITUTE( SUBSTITUTE( SUBSTITUTE( SUBSTITUTE( SUBSTITUTE( SUBSTITUTE( SUBSTITUTE( SUBSTITUTE( SUBSTITUTE( SUBSTITUTE( SUBSTITUTE( SUBSTITUTE( SUBSTITUTE( SUBSTITUTE( SUBSTITUTE( SUBSTITUTE( SUBSTITUTE( SUBSTITUTE( SUBSTITUTE( SUBSTITUTE( SUBSTITUTE( SUBSTITUTE( SUBSTITUTE( $BM$2, "@NRORG@", $AF$2 ), "@NRPARCNEGOCIO@", $AG7 ), "@NMPRINCIPALPARC@", $BG7 ), "@CNPJ@", $AK7 ), "@NRESTRUTURAM@", $AH7 ), "@NRESTRUTURA@", $D7 ), "@NRTPESTRUTURA@", $A7 ), "@DTINIVIGENCIA@", $BI7 ), "@DTFIMVIGENCIA@", $BJ7 ), "@NMESTRUTURA@", $BF7 ), "@NMFANTASIA@", $BE7 ), "@RAZAOSOCIAL@", $AM7 ), "@NRESTRUTURAH@", $AI7 ), "@COMPETENCIA@", $BK7 ), "@CEI@", $AL7 ), "@NATJURIDICA@", $AN7 ), "@CDCNAE@", $AO7 ), "@CDCAGED@", $AQ7 ), "@IDTPEMPRESA@", $M7 ), "@IDSIMPLES@", $AR7 ), "@IDPARTICIPAT@", $AS7 ), "@CDCPFESTRUTURA@", $BH7 ), "@DTBASESINDICAL@", $BL7 ), "@CDSINDICAL@", $AD7 ) -> INSERT INTO PARCNEGOCIO ( NRORG, NRPARCNEGOCIO, NMPRINCIPALPARC, NMSECUNDARIPARC, NRINSCRICAOPARC, IDATIVO, DTINCLUSAO, NRORGINCLUSAO, CDOPERINCLUSAO, CDTIPOPARCPRINCIPAL, CDTIPOINSCRICAO, IDPESSOAFISICA, IDINSTITUICAO, IDPARCFUNDIDO ) VALUES ( 4385, 1743, 'LALLEGRO SABAF DO BRASIL LTDA', 'LALLEGRO SABAF DO BRASIL LTDA', '02528634000147', 'S', SYSDATE, 4385, '000000099991', 'ESTRUTURA', 'CNPJ', 'N', 'N', 'N' ); INSERT INTO ESTRUTURAM ( NRORG, NRESTRUTURAM, NRPARCNEGOCIO, CDINTESTRUTURA, NRTIPOESTRUTURA, DTINIVIGENCIA, DTFIMVIGENCIA, NMESTRUTURAM, IDATIVO, DTINCLUSAO, CDOPERINCLUSAO ) VALUES ( 4385, 171, 1743, '001.110', 5, '01/01/2000', '', NVL( 'LALLEGRO SABAF DO BRASIL LTDA', NVL( 'LALLEGRO SABAF DO BRASIL LTDA', 'LALLEGRO SABAF DO BRASIL LTDA' ) ), 'S', SYSDATE, '000000099991'); INSERT INTO ESTRUTURAH ( NRORG, NRESTRUTURAM, NRESTRUTURAH, NRPARCNEGOCIO, DTMESCOMPETENC, CDCNPJESTRUT, CDCEIESTRUT, NMRAZSOCESTRUT, NMFANTASIA, NMESTRUTURAH, CDNATUJURI, CDCNAE, NRCAGED, IDTIPOEMPR, IDOPTSIMPLES, IDPARTICIPAT, CDCPFESTRUTURA, DTBASESINDICAL, CDSINDICAL, IDATIVO, DTINCLUSAO, CDOPERINCLUSAO) VALUES ( 4385, 171, 171, 1743, '01/01/2000', '02528634000147', '', 'LALLEGRO SABAF DO BRASIL LTDA', 'LALLEGRO SABAF DO BRASIL LTDA', NVL( 'LALLEGRO SABAF DO BRASIL LTDA', NVL( 'LALLEGRO SABAF DO BRASIL LTDA', 'LALLEGRO SABAF DO BRASIL LTDA' ) ), '2062', '2751100', '', '', NVL( 'N', 'N' ), '', '', '', '', 'S', SYSDATE, '000000099991'); | BN7: =SUBSTITUTE( SUBSTITUTE( SUBSTITUTE( SUBSTITUTE( SUBSTITUTE( SUBSTITUTE( SUBSTITUTE( SUBSTITUTE( SUBSTITUTE( SUBSTITUTE( SUBSTITUTE( SUBSTITUTE( SUBSTITUTE( $BN$2, "@NRORG@", $AF$2 ), "@NRENDERECOPARC@", $AJ7 ), "@NRPARCNEGOCIO@", $AG7 ), "@IDENDERECO@", $AT7 ), "@CDPAIS@", $AU7 ), "@SGESTADO@", $AV7 ), "@LOGRADOURO@", $AX7 ), "@BAIRRO@", $BB7 ), "@REFERENCIAENDERECO@", $BD7 ), "@CEP@", $BC7 ), "@ENDERECO@", $AY7 ), "@NUMERO@", $BA7 ), "@MUNICIPIO@", $AW7 ) -> INSERT INTO ENDERECOPARC ( NRORG, NRENDERECOPARC, NRPARCNEGOCIO, CDTIPOENDERECO, IDATIVO, DTINCLUSAO, CDOPERINCLUSAO, CDPAIS, SGESTADO, CDLOGRADOURO, NMBAIRROENDERECO, DSREFERENCIAENDE, NRCEPENDERECO, DSENDERECO, NRIMOVELENDERECO, CDMUNICIPIO ) VALUES ( 4385, 1723, 1743, 'OUTROS', 'S', SYSDATE, '000000099991', LPAD( '0055', 4, '0' ), 'SP', 'RUA', 'PARQUE INDUSTRIAL III', 'CONDOMINIO FRAZGRAN', '13213084', 'GUSTAVO HENRIQUE MEERSON', '355', ( SELECT MAX( CDMUNICIPIO ) FROM MUNICIPIO WHERE UPPER( NMMUNICIPIO ) = 'JUNDIAI' AND CDPAIS = LPAD( '0055', 4, '0' ) AND SGESTADO = 'SP' ) ); | BO7: =IF( AE7 <> "insere", "", BM7 & IF( AZ7 = "insere", " " & BN7, "" ) & " COMMIT;" ) -> INSERT INTO PARCNEGOCIO ( NRORG, NRPARCNEGOCIO, NMPRINCIPALPARC, NMSECUNDARIPARC, NRINSCRICAOPARC, IDATIVO, DTINCLUSAO, NRORGINCLUSAO, CDOPERINCLUSAO, CDTIPOPARCPRINCIPAL, CDTIPOINSCRICAO, IDPESSOAFISICA, IDINSTITUICAO, IDPARCFUNDIDO ) VALUES ( 4385, 1743, 'LALLEGRO SABAF DO BRASIL LTDA', 'LALLEGRO SABAF DO BRASIL LTDA', '02528634000147', 'S', SYSDATE, 4385, '000000099991', 'ESTRUTURA', 'CNPJ', 'N', 'N', 'N' ); INSERT INTO ESTRUTURAM ( NRORG, NRESTRUTURAM, NRPARCNEGOCIO, CDINTESTRUTURA, NRTIPOESTRUTURA, DTINIVIGENCIA, DTFIMVIGENCIA, NMESTRUTURAM, IDATIVO, DTINCLUSAO, CDOPERINCLUSAO ) VALUES ( 4385, 171, 1743, '001.110', 5, '01/01/2000', '', NVL( 'LALLEGRO SABAF DO BRASIL LTDA', NVL( 'LALLEGRO SABAF DO BRASIL LTDA', 'LALLEGRO SABAF DO BRASIL LTDA' ) ), 'S', SYSDATE, '000000099991'); INSERT INTO ESTRUTURAH ( NRORG, NRESTRUTURAM, NRESTRUTURAH, NRPARCNEGOCIO, DTMESCOMPETENC, CDCNPJESTRUT, CDCEIESTRUT, NMRAZSOCESTRUT, NMFANTASIA, NMESTRUTURAH, CDNATUJURI, CDCNAE, NRCAGED, IDTIPOEMPR, IDOPTSIMPLES, IDPARTICIPAT, CDCPFESTRUTURA, DTBASESINDICAL, CDSINDICAL, IDATIVO, DTINCLUSAO, CDOPERINCLUSAO) VALUES ( 4385, 171, 171, 1743, '01/01/2000', '02528634000147', '', 'LALLEGRO SABAF DO BRASIL LTDA', 'LALLEGRO SABAF DO BRASIL LTDA', NVL( 'LALLEGRO SABAF DO BRASIL LTDA', NVL( 'LALLEGRO SABAF DO BRASIL LTDA', 'LALLEGRO SABAF DO BRASIL LTDA' ) ), '2062', '2751100', '', '', NVL( 'N', 'N' ), '', '', '', '', 'S', SYSDATE, '000000099991'); INSERT INTO ENDERECOPARC ( NRORG, NRENDERECOPARC, NRPARCNEGOCIO, CDTIPOENDERECO, IDATIVO, DTINCLUSAO, CDOPERINCLUSAO, CDPAIS, SGESTADO, CDLOGRADOURO, NMBAIRROENDERECO, DSREFERENCIAENDE, NRCEPENDERECO, DSENDERECO, NRIMOVELENDERECO, CDMUNICIPIO ) VALUES ( 4385, 1723, 1743, 'OUTROS', 'S', SYSDATE, '000000099991', LPAD( '0055', 4, '0' ), 'SP', 'RUA', 'PARQUE INDUSTRIAL III', 'CONDOMINIO FRAZGRAN', '13213084', 'GUSTAVO HENRIQUE MEERSON', '355', ( SELECT MAX( CDMUNICIPIO ) FROM MUNICIPIO WHERE UPPER( NMMUNICIPIO ) = 'JUNDIAI' AND CDPAIS = LPAD( '0055', 4, '0' ) AND SGESTADO = 'SP' ) ); COMMIT; | BP7: Linhas | BQ7: =COUNTA( Base!A:A ) -> 4 | BT7: Fim PK | BU7: =MAX(OFFSET($A$1,2,MATCH(BU$3,$1:$1,0)-1,1048574,1)) -> 1746 | BV7: =MAX(OFFSET($A$1,2,MATCH(BV$3,$1:$1,0)-1,1048574,1)) -> 174 | BW7: =MAX(OFFSET($A$1,2,MATCH(BW$3,$1:$1,0)-1,1048574,1)) -> 174 | BX7: =MAX(OFFSET($A$1,2,MATCH(BX$3,$1:$1,0)-1,1048574,1)) -> 1726 | BY7: Fim PK | BZ7: =BU7 -> 1746 | CA7: =BV7 -> 174 | CB7: =BW7 -> 174 | CC7: =BX7 -> 1726
