Workbook
Name MIG_NORMA.DATA: _xlfn.LAMBDA(_xlpm.data, "'" & TEXT( TRIM( _xlpm.data ), "DD/MM/AAAA" ) & "'" )
Name MIG_NORMA.DECIMAL: _xlfn.LAMBDA(_xlpm.número, SUBSTITUTE( _xlpm.número, ",", ".") )
Name MIG_NORMA.NÚMERICO: _xlfn.LAMBDA(_xlpm.texto, _xlfn.CONCAT( IFERROR( -- MID( _xlpm.texto, _xlfn.SEQUENCE(LEN( _xlpm.texto ) ), 1 ), "" ) ) )
Name MIG_NORMA.TEXTO: _xlfn.LAMBDA(_xlpm.texto, "'" & UPPER( TRIM( MIG_REMOVE.ESPECIAL( _xlpm.texto ) ) ) & "'" )
Name MIG_REMOVE.ESPECIAL: _xlfn.LAMBDA(_xlpm.texto, AUX_TROCAR( _xlpm.texto, "áàâãäÁÀÂÃÄéèêëÉÈÊËíìîïÍÌÎÏóòôöÓÒÔÖúùûüÚÙÛÜçÇ&'`´~^", "aaaaaAAAAAeeeeEEEEiiiiIIIIooooOOOOuuuuUUUUcC " ) )

Sheet Dados
A1: → | B1: → | C1: @CDMATRICULA@ | D1: @NRSITUFUNCM@ | E1: @NRESCALATRABM@ | F1: → | G1: → | H1: @NOMEVINC@ | I1: @CDESTACIVIL@ | J1: → | K1: → | L1: @SERIECTPS@ | M1: @UFCTPS@ | N1: → | O1: @PIS@ | Q1: → | R1: @CDEXRG@ | S1: @UFRG@ | U1: @TITUELEI@ | V1: @SECAOELEI@ | W1: @ZONAELEI@ | X1: @CNH@ | Z1: @CATCNH@ | AA1: → | AB1: → | AC1: @NRRACA@ | AD1: @CDPAIS@ | AE1: @SGESTADO@ | AF1: → | AG1: → | AH1: @IDSEXO@ | AI1: @IDREMUNERACAO@ | AJ1: → | AK1: → | AL1: → | AM1: @NRTPCONTCORR@ | AN1: → | AO1: @IDTPPAGAMENTO@ | AP1: @ESTRUTLEGAL@ | AQ1: @ESTRUTGEREN@ | AR1: → | AS1: @SGESTADO_END@ | AT1: → | AU1: → | AV1: → | AW1: @NRIMOVELENDERECO_END@ | AX1: → | AY1: → | AZ1: → | BA1: @NRTIPOVINCULOM@ | BB1: @NRTPDEMISSAO@ | BG1: @IDMULTVINC@ | BH1: @CDCONTRIBINDIVIDUAL@ | BI1: @NRMOTIVORESC@ | BJ1: @DSOBSRESCISAO@ | BN1: @NRVINCULOEMPREG@ | BO1: @NRTPADMISSAO@ | BQ1: → | BR1: → | BS1: @NRTPMODALIDSAL@ | BT1: @NRGRAUINSTR@ | BU1: @ESTRUTSIND@ | BV1: @NRDIASCONTRATOEXP@ | BW1: @NRDIASCONTRATOEXPPRO@ | CC1: @NRCONDFISPES@ | CD1: @TELPRI@ | CE1: @EMAIL@ | CI1: @DDDTELPRI@ | CJ1: @DDDTELCEL@ | CK1: @TELCEL@ | CM1: ORGANIZAÇÃO | CN1: @DTMESCOMPETENC2@ | CO1: @DTMESCOMPETENC3@ | CP1: @NRPARCNEGOCIO@ | CQ1: @NRPESSOA@ | CR1: @NRPESSOAH@ | CS1: @NRVINCULOM@ | CT1: @NRVINCULOH@ | CU1: @NRVINCULOH2@ | CV1: @NRVINCULOH3@ | CW1: @NRALTESITUFUNC@ | CX1: @NRCONTCORRPARC@ | CY1: @NRCOMUNICAPARC@ | CZ1: @NRCOMUNICAPARC2@ | DA1: @NRCOMUNICAPARC3@ | DB1: @NRENDERECOPARC@ | DC1: @NRMOVIMENTACAO_LEG@ | DD1: @NRMOVIMENTACAO_GER@ | DE1: @NRMOVIMENTACAO_SIN@ | DF1: @IDCONTRIBUISIND@ | DG1: @NMMUNICIPIO@ | DH1: @NRNACIONALID@ | DI1: @CDLOGRADOURO_END@ | DJ1: @DSENDERECO_END@ | DK1: @NMBAIRROENDERECO_END@ | DL1: @DSCOMPLEENDERECO_END@ | DM1: @NRCEPENDERECO_END@ | DN1: @OCUPACAO@ | DO1: @NRDEPENDIR@ | DP1: @NRDEPENDSFAM@ | DQ1: @NRCATMILITARPE@ | DR1: @NRRG@ | DS1: @CDBANCO@ | DT1: @CDAGENCIA@ | DU1: @CDCONTCORR@ | DV1: @CDPAIS_END@ | DW1: @NMMUNICIPIO_END@ | DX1: @CPF@ | DY1: @CTPS@ | DZ1: @DTADMISSAO@ | EA1: @DTRESCISAO@ | EB1: @DTNASCI@ | EC1: @DTCTPS@ | ED1: @DTPIS@ | EE1: @DTVALCNH@ | EF1: @DTEXRG@ | EG1: @DTOPCAOFGTS@ | EH1: @DTAPOSENTAFGTS@ | EI1: @DTPRIMADMISSAO@ | EJ1: @DTEXAMEMEDICO@ | EK1: @DTAVISOTRCT@ | EL1: @DTAVISOPREVIO@ | EM1: @DTBASEFERIAS@ | EN1: @DTINISITUFUNC@ | EO1: @DTFIMCONTRDETERMIN@ | EP1: @NRCERTRESE@ | EQ1: Parceiro de negócio | ER1: Pessoa M | ES1: Pessoa H | ET1: Vinculo M | EU1: Vinculo H | EV1: Vinculo H 2 | EW1: Vinculo H 3 | EX1: Alte Situ Func | EY1: Conta Corr | EZ1: Comunicação Telefone Principal | FA1: Comunicação Telefone Celular | FB1: Comunicação e-mail | FC1: Endereço | FD1: Mov Legal | FE1: Mov Geren | FF1: Mov Sind | FH1: ="H3:H" & COUNTA( A:A ) -> H3:H29 | FI1: ="C3:C" & COUNTA( A:A ) -> C3:C29 | FJ1: Verificação de PK | FK1: ="A3:A" & COUNTA( A:A ) -> A3:A29 | FL1: ="DN3:DN" & COUNTA( A:A ) -> DN3:DN29 | FM1: Verificação de FK - Ocupação | FP1: ="E3:E" & COUNTA( E:E ) -> E3:E29 | FQ1: Verificação de FK - Escala de Trabalho | FT1: ="AP3:AP" & COUNTA( A:A ) -> AP3:AP29 | FU1: Verificação de FK - Legal | FX1: ="AQ3:AQ" & COUNTA( A:A ) -> AQ3:AQ29 | FY1: Verificação de FK - Gerencial | GB1: ="BU3:BU" & COUNTA( A:A ) -> BU3:BU29 | GC1: Verificação de FK - Sindical | GJ1: --Busca de PK’s livres | GU1: --Validações de PK | HF1: --Atualiza ou cria o novo codigo
A2: Data Admissão | B2: Data Rescisão | C2: Nr. Vínculo | D2: Situ. Funcional | E2: Escala Trabalho | F2: Mês Competência | G2: Contribuiçao Sind. | H2: Nome | I2: Estado Civil | J2: CPF | K2: CTPS | L2: Série CTPS | M2: UF CTPS | N2: Emissao CTPS | O2: PIS PASEP | P2: Data de Cadastro do PIS | Q2: carteira de identidade | R2: orgao emissor carteira de identidade | S2: uf carteira identidade | T2: Data de emissão carteira de identidade | U2: Título de eleitor | V2: Seção de Votacão | W2: Zona de votação | X2: CNH | Y2: vencimento CNH | Z2: Tipo CNH | AA2: certificado reservista | AB2: Categoria Militar | AC2: RACA | AD2: pais | AE2: estado | AF2: Naturalidade | AG2: Data de Nascimento | AH2: sexo | AI2: Tipo Remuneração | AJ2: Banco | AK2: Agência | AL2: Conta Corrente | AM2: Tp Conta Corrente | AN2: nacionalidade | AO2: Tp. Pagamento | AP2: Estrutura Trabalho | AQ2: Estrutura Gerencial | AR2: pais_end | AS2: estado end | AT2: municipio_end | AU2: Logradouro | AV2: Endereço | AW2: numero | AX2: bairro | AY2: Complemento | AZ2: Cep | BA2: Tipo Vínculo Mestre | BB2: Tipo de Demissão | BC2: Data FGTS | BD2: Dt. Aposentadoria FGTS | BE2: Data Primeira Admissão | BF2: Ocupação | BG2: Múltiplos Vínculos | BH2: Nr. Contrib. Individual | BI2: Motivo da Rescisão | BJ2: Observação Rescisão | BK2: Data Aviso Prévio | BL2: Tp. Mov. Transferência | BM2: Fim contrato Determinado | BN2: Vínculo Empregatício | BO2: Tipo Admissão | BP2: Dt. Base Férias | BQ2: Dependentes IR | BR2: Dependentes Sal Fam | BS2: Modalidade Salário | BT2: Grau Instrucao | BU2: Estrutura Sindical | BV2: Dias Contrato Exp. | BW2: Dias Contrato Exp. Prorr | BX2: Dt. Exame Médico | BY2: Dt. Aviso TRCT | BZ2: Tipo Sanguineo | CA2: Fator RH | CB2: Inscrição Conselho | CC2: Condição Física | CD2: Telefone Principal | CE2: Email | CF2: Salário | CG2: Nome do Pai | CH2: Nome da Mãe | CI2: DDD Telefone Principal | CJ2: DDD Telefone Celular | CK2: Telefone Celular | CM2: 5862 | CN2: 01/01/2024 | CO2: 01/01/2025 | CP2: 203 | CQ2: 0 | CR2: 0 | CS2: 0 | CT2: 1 | CU2: =CT2+1 -> 2 | CV2: =CU2+1 -> 3 | CW2: 0 | CX2: 0 | CY2: 0 | CZ2: =MAX(CY:CY) -> 2 | DA2: =MAX(CZ:CZ) -> 29 | DB2: 10 | DC2: 0 | DD2: =LARGE( DC:DC, 1 ) -> 27 | DE2: =LARGE( DD:DD, 1 ) -> 54 | DF2: =G2 -> Contribuiçao Sind. | DG2: Naturalidade | DH2: Nacionalidade | DI2: Logradouro | DJ2: Endereço | DK2: bairro | DL2: Complemento | DM2: Cep | DN2: Ocupação | DO2: =BQ2 -> Dependentes IR | DP2: =BR2 -> Dependentes Sal Fam | DQ2: Categoria Militar | DR2: carteira de identidade | DS2: Banco | DT2: Agência | DU2: Conta corrente | DV2: pais_end | DW2: municipio_end | DX2: =J2 -> CPF | DY2: =K2 -> CTPS | DZ2: Data Admissão | EA2: Data Rescisão | EB2: Data de Nascimento | EC2: Emissão CTPS | ED2: Data de Cadastro do PIS | EE2: vencimento CNH | EF2: Data de emissão carteira de identidade | EG2: Data FGTS | EH2: Dt. Aposentadoria FGTS | EI2: Data Primeira Admissão | EJ2: Dt. Exame Médico | EK2: Dt. Aviso TRCT | EL2: Data Aviso Prévio | EM2: Dt. Base Ferias | EO2: Fim contrato Determinado | EP2: =AA2 -> certificado reservista | EQ2: INSERT INTO PARCNEGOCIO ( NRPARCNEGOCIO, NRORG, NMPRINCIPALPARC, NMSECUNDARIPARC, DTNASCIFUNDPARC, NRINSCRICAOPARC, IDATIVO, DTINCLUSAO, NRORGINCLUSAO, CDOPERINCLUSAO, CDTIPOPARCPRINCIPAL, CDTIPOINSCRICAO, IDPESSOAFISICA, IDINSTITUICAO, IDPARCFUNDIDO ) VALUES ( @NRPARCNEGOCIO@, @NRORG@, '@NOMEVINC@', '@NOMEVINC@', '@DTNASCI@', '@CPF@', 'S', SYSDATE, @NRORG@, '000000099991', 'PESSOA', 'CPF', 'S', 'N', 'N' ); | ER2: INSERT INTO GPE_PESSOA ( NRPESSOA, NRORG, NRPARCNEGOCIO, DTINCLUSAO, NRORGINCLUSAO, CDOPERINCLUSAO ) VALUES ( @NRPESSOA@, @NRORG@, @NRPARCNEGOCIO@, SYSDATE, @NRORG@, '000000099991' ); | ES2: INSERT INTO GPE_PESSOAH ( NRPESSOAH, NRPESSOA, NRORG, DTMESCOMPETENC, NMPESSOA, CDESTACIVIL, NRCPFPESSOA, NRCTPSPESSOA, NRSERIECTPSPES, SGUFCTPSPES, DTCTPSPESSOA, NRPISPASEPPES, DTINSCPISPASEP, NRTITUELEIPES, NRSECAELEIPES, NRZONAELEIPES, NRCARTHABPES, DTVALHABCARTPES, DSCATEGHABCART, NRCATMILITARPE, NRCERTRESEPES, DTINCLUSAO, NRORGINCLUSAO, CDOPERINCLUSAO, NRRACAPESSOA, CDPAIS, SGESTADO, CDMUNICIPIO, DTNASCPESSOA, IDSEXOPESSOA, NRRGPESSOA, CDEXRGPESSOA, SGUFRGPESSOA, DTEXRGPESSOA, NRNACIONALID, NRGRAUINSTR, NRCONDFISPES ) VALUES ( @NRPESSOAH@, @NRPESSOA@, @NRORG@, '01/01/2000', '@NOMEVINC@', '@CDESTACIVIL@', '@CPF@', '@CTPS@', '@SERIECTPS@', '@UFCTPS@', '@DTCTPS@', '@PIS@', '@DTPIS@', '@TITUELEI@', '@SECAOELEI@', '@ZONAELEI@', '@CNH@', '@DTVALCNH@', '@CATCNH@', (SELECT NRCATMILITARPE FROM GPE_CATMILITARPE WHERE NRCATMILITARPE = '@NRCATMILITARPE@'), '@NRCERTRESE@', SYSDATE, @NRORG@, '000000099991', '@NRRACA@', '@CDPAIS@', '@SGESTADO@', (SELECT MAX(CDMUNICIPIO) FROM MUNICIPIO WHERE NMMUNICIPIO = '@NMMUNICIPIO@'), '@DTNASCI@', '@IDSEXO@', '@NRRG@', '@CDEXRG@', '@UFRG@', '@DTEXRG@', '@NRNACIONALID@', '@NRGRAUINSTR@' , '@NRCONDFISPES@'); | ET2: INSERT INTO GPE_VINCULOM (NRVINCULOM, NRPESSOA, NRORG, CDMATRICULA, DTADMISSAOVINC, DTRESCISAOVINC, DTINCLUSAO, NRORGINCLUSAO, CDOPERINCLUSAO, NRTIPOVINCULOM, NRVINCULOEMPREG, NRTPADMISSAO, NRTPDEMISSAO, DTOPCAOFGTS, DTAPOSENTAFGTS, DTPRIMADMISSAO, NMVINCULOM, NRMOTIVORESC, DSOBSRESCISAO, DTAVISOPREVIO, NRDIASCONTRATOEXP, NRDIASCONTRATOEXPPRO, DTEXAMEMEDICO, DTAVISOTRCT) VALUES (@NRVINCULOM@, @NRPESSOA@, @NRORG@, '@CDMATRICULA@', '@DTADMISSAO@', '@DTRESCISAO@', SYSDATE, @NRORG@, '000000099991', '@NRTIPOVINCULOM@', '@NRVINCULOEMPREG@', '@NRTPADMISSAO@', '@NRTPDEMISSAO@', '@DTOPCAOFGTS@', '@DTAPOSENTAFGTS@', '@DTPRIMADMISSAO@', '@NOMEVINC@', '@NRMOTIVORESC@', '@DSOBSRESCISAO@', '@DTAVISOPREVIO@', '@NRDIASCONTRATOEXP@', '@NRDIASCONTRATOEXPPRO@', '@DTEXAMEMEDICO@', '@DTAVISOTRCT@'); | EU2: INSERT INTO GPE_VINCULOH (NRVINCULOH, NRVINCULOM, NRSITUFUNCM, NRCARGO, NRFUNCAO, NRORG, DTMESCOMPETENC, IDCONTRIBUISIND, DTINCLUSAO, NRORGINCLUSAO, CDOPERINCLUSAO, NRDEPENDIR, NRDEPENDSFAM, DTBASEFERIAS, IDREMUNERACAO, IDTPPAGAMENTO, NRESTRUTLEGAL, NRESTRUTGEREN, NRESTRUTSIND, NRTPMODALIDSAL, IDMULTVINC, CDCONTRIBINDIVIDUAL, NRTPMOVTRANSFM, DTFIMCONTRDETERMIN, CONFIDENCIAL, NRESCALATRABM) VALUES (@NRVINCULOH@, @NRVINCULOM@, '@NRSITUFUNCM@', (SELECT MAX(NROCUPACAOM) FROM GPE_OCUPACAOH WHERE NRORG = @NRORG@ AND CDINTEGRACAO = '@OCUPACAO@'), (SELECT MAX(NROCUPACAOM) FROM GPE_OCUPACAOH WHERE NRORG = @NRORG@ AND CDINTEGRACAO = '@OCUPACAO@'), @NRORG@, '01/01/2000', '@IDCONTRIBUISIND@', SYSDATE, @NRORG@, '000000099991', '@NRDEPENDIR@', '@NRDEPENDSFAM@', '@DTBASEFERIAS@', '@IDREMUNERACAO@', '@IDTPPAGAMENTO@', (SELECT MAX(NRESTRUTURAM) FROM ESTRUTURAM WHERE NRORG = @NRORG@ AND CDINTESTRUTURA = '@ESTRUTLEGAL@'), NVL((SELECT MAX(NRESTRUTURAM) FROM ESTRUTURAM WHERE NRORG = @NRORG@ AND CDINTESTRUTURA = '@ESTRUTGEREN@'), @CORINGAGEREN@), NVL((SELECT MAX(NRESTRUTURAM) FROM ESTRUTURAM WHERE NRORG = @NRORG@ AND CDINTESTRUTURA = '@ESTRUTSIND@'), @CORINGASIND@), '@NRTPMODALIDSAL@', '@IDMULTVINC@', '@CDCONTRIBINDIVIDUAL@', 2, '@DTFIMCONTRDETERMIN@', 'N', (SELECT MAX(NRESCALATRABM) FROM GPE_ESCALATRABH WHERE NRORG = @NRORG@ AND NRESCALATRABM = '@NRESCALATRABM@') ); | EV2: INSERT INTO GPE_VINCULOH (NRVINCULOH, NRVINCULOM, NRSITUFUNCM, NRCARGO, NRFUNCAO, NRORG, DTMESCOMPETENC, IDCONTRIBUISIND, DTINCLUSAO, NRORGINCLUSAO, CDOPERINCLUSAO, NRDEPENDIR, NRDEPENDSFAM, DTBASEFERIAS, IDREMUNERACAO, IDTPPAGAMENTO, NRESTRUTLEGAL, NRESTRUTGEREN, NRESTRUTSIND, NRTPMODALIDSAL, IDMULTVINC, CDCONTRIBINDIVIDUAL, NRTPMOVTRANSFM, DTFIMCONTRDETERMIN, CONFIDENCIAL, NRESCALATRABM) SELECT @NRVINCULOH2@ NRVINCULOH, NRVINCULOM, NRSITUFUNCM, NRCARGO, NRFUNCAO, NRORG, '@DTMESCOMPETENC2@' DTMESCOMPETENC, IDCONTRIBUISIND, SYSDATE DTINCLUSAO, NRORGINCLUSAO, CDOPERINCLUSAO, NRDEPENDIR, NRDEPENDSFAM, DTBASEFERIAS, IDREMUNERACAO, IDTPPAGAMENTO, NRESTRUTLEGAL, NRESTRUTGEREN, NRESTRUTSIND, NRTPMODALIDSAL, IDMULTVINC, CDCONTRIBINDIVIDUAL, NRTPMOVTRANSFM, DTFIMCONTRDETERMIN, CONFIDENCIAL, NRESCALATRABM FROM GPE_VINCULOH WHERE NRORG = @NRORG@ AND NRVINCULOH = @NRVINCULOH@; | EW2: INSERT INTO GPE_VINCULOH (NRVINCULOH, NRVINCULOM, NRSITUFUNCM, NRCARGO, NRFUNCAO, NRORG, DTMESCOMPETENC, IDCONTRIBUISIND, DTINCLUSAO, NRORGINCLUSAO, CDOPERINCLUSAO, NRDEPENDIR, NRDEPENDSFAM, DTBASEFERIAS, IDREMUNERACAO, IDTPPAGAMENTO, NRESTRUTLEGAL, NRESTRUTGEREN, NRESTRUTSIND, NRTPMODALIDSAL, IDMULTVINC, CDCONTRIBINDIVIDUAL, NRTPMOVTRANSFM, DTFIMCONTRDETERMIN, CONFIDENCIAL, NRESCALATRABM) SELECT @NRVINCULOH3@ NRVINCULOH, NRVINCULOM, NRSITUFUNCM, NRCARGO, NRFUNCAO, NRORG, '@DTMESCOMPETENC3@' DTMESCOMPETENC, IDCONTRIBUISIND, SYSDATE DTINCLUSAO, NRORGINCLUSAO, CDOPERINCLUSAO, NRDEPENDIR, NRDEPENDSFAM, DTBASEFERIAS, IDREMUNERACAO, IDTPPAGAMENTO, NRESTRUTLEGAL, NRESTRUTGEREN, NRESTRUTSIND, NRTPMODALIDSAL, IDMULTVINC, CDCONTRIBINDIVIDUAL, NRTPMOVTRANSFM, DTFIMCONTRDETERMIN, CONFIDENCIAL, NRESCALATRABM FROM GPE_VINCULOH WHERE NRORG = @NRORG@ AND NRVINCULOH = @NRVINCULOH@; | EX2: INSERT INTO GPE_ALTESITUFUNC ( NRALTESITUFUNC, NRORG, NRSITUFUNCM, NRVINCULOM, DTINISITUFUNC, DTINCLUSAO, NRORGINCLUSAO, CDOPERINCLUSAO ) VALUES ( @NRALTESITUFUNC@, @NRORG@, (CASE WHEN '@NRSITUFUNCM@' IS NOT NULL THEN '@NRSITUFUNCM@' WHEN '@DTRESCISAO@' IS NULL THEN '1' ELSE '13' END), @NRVINCULOM@, '@DTINISITUFUNC@', SYSDATE, @NRORG@, '000000099991' ); | EY2: INSERT INTO CONTCORRPARC ( NRCONTCORRPARC, NRORG, NRPARCNEGOCIO, CDBANCO, CDAGENCIA, CDCONTCORR, NRTPCONTCORR, DTINCLUSAO, NRORGINCLUSAO, CDOPERINCLUSAO, IDATIVO ) VALUES ( @NRCONTCORRPARC@, @NRORG@, @NRPARCNEGOCIO@, '@CDBANCO@', '@CDAGENCIA@', '@CDCONTCORR@', '@NRTPCONTCORR@', SYSDATE, @NRORG@, '000000099991', 'S' ); | EZ2: INSERT INTO COMUNICAPARC ( NRCOMUNICAPARC, NRPARCNEGOCIO, CDFORMACOMU, CDPREFIXCOMUPARC, CDCOMUNICAPARC, NRORG, IDATIVO, DTINCLUSAO, NRORGINCLUSAO, CDOPERINCLUSAO ) VALUES ( @NRCOMUNICAPARC@, @NRPARCNEGOCIO@, '01', '@DDDTELPRI@', '@TELPRI@', @NRORG@, 'S', SYSDATE, @NRORG@, '000000099991' ); | FA2: INSERT INTO COMUNICAPARC ( NRCOMUNICAPARC, NRPARCNEGOCIO, CDFORMACOMU, CDPREFIXCOMUPARC, CDCOMUNICAPARC, NRORG, IDATIVO, DTINCLUSAO, NRORGINCLUSAO, CDOPERINCLUSAO ) VALUES ( @NRCOMUNICAPARC2@, @NRPARCNEGOCIO@, '02', '@DDDTELCEL@', '@TELCEL@', @NRORG@, 'S', SYSDATE, @NRORG@, '000000099991' ); | FB2: INSERT INTO COMUNICAPARC ( NRCOMUNICAPARC, NRPARCNEGOCIO, CDFORMACOMU, CDCOMUNICAPARC, NRORG, IDATIVO, DTINCLUSAO, NRORGINCLUSAO, CDOPERINCLUSAO ) VALUES ( @NRCOMUNICAPARC3@, @NRPARCNEGOCIO@, '05', '@EMAIL@', @NRORG@, 'S', SYSDATE, @NRORG@, '000000099991' ); | FC2: INSERT INTO ENDERECOPARC ( NRENDERECOPARC, NRPARCNEGOCIO, CDTIPOENDERECO, NRORG, IDATIVO, DTINCLUSAO, NRORGINCLUSAO, CDOPERINCLUSAO, CDPAIS, CDMUNICIPIO, CDLOGRADOURO, NMBAIRROENDERECO, DSCOMPLEENDERECO, NRCEPENDERECO, DSENDERECO, NRIMOVELENDERECO, SGESTADO ) VALUES ( @NRENDERECOPARC@, @NRPARCNEGOCIO@, 'PRINCIPAL', @NRORG@, 'S', SYSDATE, @NRORG@, '000000099991', '@CDPAIS_END@', ( SELECT MAX(CDMUNICIPIO) FROM MUNICIPIO WHERE NMMUNICIPIO = '@NMMUNICIPIO_END@' AND SGESTADO = '@SGESTADO_END@' ), '@CDLOGRADOURO_END@', '@NMBAIRROENDERECO_END@', '@DSCOMPLEENDERECO_END@', '@NRCEPENDERECO_END@', '@DSENDERECO_END@', '@NRIMOVELENDERECO_END@', '@SGESTADO_END@'); | FD2: INSERT INTO GPE_MOVIMENTACAO ( NRMOVIMENTACAO, NRORG, NRVINCULOM, NRTIPOTRANSFER, NRTPMOVTRANSFM, NRESTRUTURAM, DTINIMOVIMENT, DSOBSERVACAO, DTINCLUSAO, NRORGINCLUSAO, CDOPERINCLUSAO, NRTIPOESTRUTURA ) VALUES ( @NRMOVIMENTACAO_LEG@, @NRORG@, @NRVINCULOM@, 1, 1, (SELECT MAX(NRESTRUTURAM) FROM ESTRUTURAM WHERE NRORG = @NRORG@ AND CDINTESTRUTURA = '@ESTRUTLEGAL@' AND NRTIPOESTRUTURA = (SELECT NRTPESTRUTLEGAL FROM GPE_PARAMORG WHERE NRORG = @NRORG@)), '@DTADMISSAO@', 'Movimentacao gerada via migracao ' || SYSDATE, SYSDATE, @NRORG@, '000000099991', ( SELECT NRTPESTRUTLEGAL FROM GPE_PARAMORG WHERE NRORG = @NRORG@ ) ); | FE2: INSERT INTO GPE_MOVIMENTACAO ( NRMOVIMENTACAO, NRORG, NRVINCULOM, NRTIPOTRANSFER, NRTPMOVTRANSFM, NRESTRUTURAM, DTINIMOVIMENT, DSOBSERVACAO, DTINCLUSAO, NRORGINCLUSAO, CDOPERINCLUSAO, NRTIPOESTRUTURA ) VALUES ( @NRMOVIMENTACAO_GER@, @NRORG@, @NRVINCULOM@, 2, 1, (SELECT MAX(NRESTRUTURAM) FROM ESTRUTURAM WHERE NRORG = @NRORG@ AND CDINTESTRUTURA = '@ESTRUTGEREN@' AND NRTIPOESTRUTURA = (SELECT NRTPESTRUTGEREN FROM GPE_PARAMORG WHERE NRORG = @NRORG@)), '@DTADMISSAO@', 'Movimentacao gerada via migracao ' || SYSDATE, SYSDATE, @NRORG@, '000000099991', ( SELECT NRTPESTRUTGEREN FROM GPE_PARAMORG WHERE NRORG = @NRORG@ ) ); | FF2: INSERT INTO GPE_MOVIMENTACAO ( NRMOVIMENTACAO, NRORG, NRVINCULOM, NRTIPOTRANSFER, NRTPMOVTRANSFM, NRESTRUTURAM, DTINIMOVIMENT, DSOBSERVACAO, DTINCLUSAO, NRORGINCLUSAO, CDOPERINCLUSAO, NRTIPOESTRUTURA ) VALUES ( @NRMOVIMENTACAO_SIN@, @NRORG@, @NRVINCULOM@, 1, 1, (SELECT MAX(NRESTRUTURAM) FROM ESTRUTURAM WHERE NRORG = @NRORG@ AND CDINTESTRUTURA = '@ESTRUTSIND@' AND NRTIPOESTRUTURA = 10), '@DTADMISSAO@', 'Movimentacao gerada via migracao ' || SYSDATE, SYSDATE, @NRORG@, '000000099991', 10 ); | FG2: COMMIT; | FI2: Vinculo existente? | FJ2: =" - Lista de vínculos que já possuem a matrícula cadastrada no HCM. Por este motivo não foram migrado(s). " & ( COUNTA(_xlfn.ANCHORARRAY( FJ3) ) - 1 ) & " ocorrência(s):" -> - Lista de vínculos que já possuem a matrícula cadastrada no HCM. Por este motivo não foram migrado(s). 0 ocorrência(s): | FL2: Ocupação existe? | FM2: Ocupações não encontradas no sistema / planilha 02_Ocupação: | FN2: Vínculo afetado pela ausência de ocupação na planilha 02_Ocupação: | FP2: Escala de trabalho existe? | FQ2: =IF( COUNTA(_xlfn.ANCHORARRAY( FQ3) ) <= 2, "Escalas de trabalho não encontrada na planilha 03_EscalaTrabalho:", "Lista das escalas de trabalho não encontradas na planilha 03_EscalaTrabalho:" ) -> Escalas de trabalho não encontrada na planilha 03_EscalaTrabalho: | FR2: =IF( COUNTA(_xlfn.ANCHORARRAY( FR3) ) <= 2, "Vínculo afetado pela ausência de escala de trabalho na planilha 03_EscalaTrabalho:", "Lista dos vínculos afetados pela ausência de escala de trabalho na planilha 03_EscalaTrabalho:" ) -> Vínculo afetado pela ausência de escala de trabalho na planilha 03_EscalaTrabalho: | FT2: Estrutura Legal existe? | FU2: =" - Estruturas de trabalhos (estrutura legal) não encontradas no sistema / planilha 01_Estruturas. " & ( COUNTA(_xlfn.ANCHORARRAY( FU3) ) - 1 ) & " ocorrência(s):" -> - Estruturas de trabalhos (estrutura legal) não encontradas no sistema / planilha 01_Estruturas. 0 ocorrência(s): | FV2: =" - Vínculos afetados pela ausência de estruturas de trabalhos (estrutura legal) não encontradas no sistema / planilha 01_Estruturas. Por este motivo o histórico do vínculo e movimentação deverão ser atualizados manualmente. " & ( COUNTA(_xlfn.ANCHORARRAY( FV3) ) - 1 ) & " ocorrência(s):" -> - Vínculos afetados pela ausência de estruturas de trabalhos (estrutura legal) não encontradas no sistema / planilha 01_Estruturas. Por este motivo o histórico do vínculo e movimentação deverão ser atualizados manualmente. 0 ocorrência(s): | FX2: Estrutura Gerencial existe? | FY2: =" - Estruturas gerenciais não encontradas no sistema / planilha 01_Estruturas. " & ( COUNTA(_xlfn.ANCHORARRAY( FY3) ) - 1 ) & " ocorrência(s):" -> - Estruturas gerenciais não encontradas no sistema / planilha 01_Estruturas. 0 ocorrência(s): | FZ2: =" - Vínculos afetados pela ausência de estruturas gerenciais não encontradas no sistema / planilha 01_Estruturas. Por este motivo o histórico do vínculo e movimentação deverão ser atualizados manualmente. " & ( COUNTA(_xlfn.ANCHORARRAY( FZ3) ) - 1 ) & " ocorrência(s):" -> - Vínculos afetados pela ausência de estruturas gerenciais não encontradas no sistema / planilha 01_Estruturas. Por este motivo o histórico do vínculo e movimentação deverão ser atualizados manualmente. 0 ocorrência(s): | GB2: Estrutura Gerencial existe? | GC2: =" - Estruturas sindicais não encontradas no sistema / planilha 01_Estruturas. " & ( COUNTA(_xlfn.ANCHORARRAY( GC3) ) - 1 ) & " ocorrência(s):" -> - Estruturas sindicais não encontradas no sistema / planilha 01_Estruturas. 1 ocorrência(s): | GD2: =" - Vínculos afetados pela ausência de estruturas sindicais não encontradas no sistema / planilha 01_Estruturas. Por este motivo o histórico do vínculo e movimentação deverão ser atualizados manualmente. " & ( COUNTA(_xlfn.ANCHORARRAY( GD3) ) - 0 ) & " ocorrência(s):" -> - Vínculos afetados pela ausência de estruturas sindicais não encontradas no sistema / planilha 01_Estruturas. Por este motivo o histórico do vínculo e movimentação deverão ser atualizados manualmente. 19 ocorrência(s): | GF2: Estruturas coringa | GJ2: ="/*"&GJ4&"*/ SELECT A + 1 A, B - 1 B, B - A - 1 LENGHT, (SELECT TO_NUMBER(NRSEQUENCIAL) FROM NOVOCODIGO WHERE NRORG = "&GJ9&" AND CDCONTADOR = '"&GJ4&"') NOVOCODIGO FROM (SELECT 0 A, MIN("&GJ5&") B FROM "&GJ4&" WHERE NRORG = "&GJ9&" UNION ALL SELECT "&GJ5&", LEAD("&GJ5&") OVER (ORDER BY "&GJ5&") FROM "&GJ4&" WHERE NRORG = "&GJ9&" ) WHERE B - A > "&GJ8&" OR B IS NULL ORDER BY A;" -> /*PARCNEGOCIO*/ SELECT A + 1 A, B - 1 B, B - A - 1 LENGHT, (SELECT TO_NUMBER(NRSEQUENCIAL) FROM NOVOCODIGO WHERE NRORG = 5862 AND CDCONTADOR = 'PARCNEGOCIO') NOVOCODIGO FROM (SELECT 0 A, MIN(NRPARCNEGOCIO) B FROM PARCNEGOCIO WHERE NRORG = 5862 UNION ALL SELECT NRPARCNEGOCIO, LEAD(NRPARCNEGOCIO) OVER (ORDER BY NRPARCNEGOCIO) FROM PARCNEGOCIO WHERE NRORG = 5862 ) WHERE B - A > 27 OR B IS NULL ORDER BY A; | GK2: ="/*"&GK4&"*/ SELECT A + 1 A, B - 1 B, B - A - 1 LENGHT, (SELECT TO_NUMBER(NRSEQUENCIAL) FROM NOVOCODIGO WHERE NRORG = "&GK9&" AND CDCONTADOR = '"&GK4&"') NOVOCODIGO FROM (SELECT 0 A, MIN("&GK5&") B FROM "&GK4&" WHERE NRORG = "&GK9&" UNION ALL SELECT "&GK5&", LEAD("&GK5&") OVER (ORDER BY "&GK5&") FROM "&GK4&" WHERE NRORG = "&GK9&" ) WHERE B - A > "&GK8&" OR B IS NULL ORDER BY A;" -> /*GPE_PESSOA*/ SELECT A + 1 A, B - 1 B, B - A - 1 LENGHT, (SELECT TO_NUMBER(NRSEQUENCIAL) FROM NOVOCODIGO WHERE NRORG = 5862 AND CDCONTADOR = 'GPE_PESSOA') NOVOCODIGO FROM (SELECT 0 A, MIN(NRPESSOA) B FROM GPE_PESSOA WHERE NRORG = 5862 UNION ALL SELECT NRPESSOA, LEAD(NRPESSOA) OVER (ORDER BY NRPESSOA) FROM GPE_PESSOA WHERE NRORG = 5862 ) WHERE B - A > 27 OR B IS NULL ORDER BY A; | GL2: ="/*"&GL4&"*/ SELECT A + 1 A, B - 1 B, B - A - 1 LENGHT, (SELECT TO_NUMBER(NRSEQUENCIAL) FROM NOVOCODIGO WHERE NRORG = "&GL9&" AND CDCONTADOR = '"&GL4&"') NOVOCODIGO FROM (SELECT 0 A, MIN("&GL5&") B FROM "&GL4&" WHERE NRORG = "&GL9&" UNION ALL SELECT "&GL5&", LEAD("&GL5&") OVER (ORDER BY "&GL5&") FROM "&GL4&" WHERE NRORG = "&GL9&" ) WHERE B - A > "&GL8&" OR B IS NULL ORDER BY A;" -> /*GPE_PESSOAH*/ SELECT A + 1 A, B - 1 B, B - A - 1 LENGHT, (SELECT TO_NUMBER(NRSEQUENCIAL) FROM NOVOCODIGO WHERE NRORG = 5862 AND CDCONTADOR = 'GPE_PESSOAH') NOVOCODIGO FROM (SELECT 0 A, MIN(NRPESSOAH) B FROM GPE_PESSOAH WHERE NRORG = 5862 UNION ALL SELECT NRPESSOAH, LEAD(NRPESSOAH) OVER (ORDER BY NRPESSOAH) FROM GPE_PESSOAH WHERE NRORG = 5862 ) WHERE B - A > 27 OR B IS NULL ORDER BY A; | GM2: ="/*"&GM4&"*/ SELECT A + 1 A, B - 1 B, B - A - 1 LENGHT, (SELECT TO_NUMBER(NRSEQUENCIAL) FROM NOVOCODIGO WHERE NRORG = "&GM9&" AND CDCONTADOR = '"&GM4&"') NOVOCODIGO FROM (SELECT 0 A, MIN("&GM5&") B FROM "&GM4&" WHERE NRORG = "&GM9&" UNION ALL SELECT "&GM5&", LEAD("&GM5&") OVER (ORDER BY "&GM5&") FROM "&GM4&" WHERE NRORG = "&GM9&" ) WHERE B - A > "&GM8&" OR B IS NULL ORDER BY A;" -> /*GPE_VINCULOM*/ SELECT A + 1 A, B - 1 B, B - A - 1 LENGHT, (SELECT TO_NUMBER(NRSEQUENCIAL) FROM NOVOCODIGO WHERE NRORG = 5862 AND CDCONTADOR = 'GPE_VINCULOM') NOVOCODIGO FROM (SELECT 0 A, MIN(NRVINCULOM) B FROM GPE_VINCULOM WHERE NRORG = 5862 UNION ALL SELECT NRVINCULOM, LEAD(NRVINCULOM) OVER (ORDER BY NRVINCULOM) FROM GPE_VINCULOM WHERE NRORG = 5862 ) WHERE B - A > 27 OR B IS NULL ORDER BY A; | GN2: ="/*"&GN4&"*/ SELECT A + 1 A, B - 1 B, B - A - 1 LENGHT, (SELECT TO_NUMBER(NRSEQUENCIAL) FROM NOVOCODIGO WHERE NRORG = "&GN9&" AND CDCONTADOR = '"&GN4&"') NOVOCODIGO FROM (SELECT 0 A, MIN("&GN5&") B FROM "&GN4&" WHERE NRORG = "&GN9&" UNION ALL SELECT "&GN5&", LEAD("&GN5&") OVER (ORDER BY "&GN5&") FROM "&GN4&" WHERE NRORG = "&GN9&" ) WHERE B - A > "&GN8&" OR B IS NULL ORDER BY A;" -> /*GPE_ALTESITUFUNC*/ SELECT A + 1 A, B - 1 B, B - A - 1 LENGHT, (SELECT TO_NUMBER(NRSEQUENCIAL) FROM NOVOCODIGO WHERE NRORG = 5862 AND CDCONTADOR = 'GPE_ALTESITUFUNC') NOVOCODIGO FROM (SELECT 0 A, MIN(NRALTESITUFUNC) B FROM GPE_ALTESITUFUNC WHERE NRORG = 5862 UNION ALL SELECT NRALTESITUFUNC, LEAD(NRALTESITUFUNC) OVER (ORDER BY NRALTESITUFUNC) FROM GPE_ALTESITUFUNC WHERE NRORG = 5862 ) WHERE B - A > 27 OR B IS NULL ORDER BY A; | GO2: ="/*"&GO4&"*/ SELECT A + 1 A, B - 1 B, B - A - 1 LENGHT, (SELECT TO_NUMBER(NRSEQUENCIAL) FROM NOVOCODIGO WHERE NRORG = "&GO9&" AND CDCONTADOR = '"&GO4&"') NOVOCODIGO FROM (SELECT 0 A, MIN("&GO5&") B FROM "&GO4&" WHERE NRORG = "&GO9&" UNION ALL SELECT "&GO5&", LEAD("&GO5&") OVER (ORDER BY "&GO5&") FROM "&GO4&" WHERE NRORG = "&GO9&" ) WHERE B - A > "&GO8&" OR B IS NULL ORDER BY A;" -> /*CONTCORRPARC*/ SELECT A + 1 A, B - 1 B, B - A - 1 LENGHT, (SELECT TO_NUMBER(NRSEQUENCIAL) FROM NOVOCODIGO WHERE NRORG = 5862 AND CDCONTADOR = 'CONTCORRPARC') NOVOCODIGO FROM (SELECT 0 A, MIN(NRCONTCORRPARC) B FROM CONTCORRPARC WHERE NRORG = 5862 UNION ALL SELECT NRCONTCORRPARC, LEAD(NRCONTCORRPARC) OVER (ORDER BY NRCONTCORRPARC) FROM CONTCORRPARC WHERE NRORG = 5862 ) WHERE B - A > 13 OR B IS NULL ORDER BY A; | GP2: ="/*"&GP4&"*/ SELECT A + 1 A, B - 1 B, B - A - 1 LENGHT, (SELECT TO_NUMBER(NRSEQUENCIAL) FROM NOVOCODIGO WHERE NRORG = "&GP9&" AND CDCONTADOR = '"&GP4&"') NOVOCODIGO FROM (SELECT 0 A, MIN("&GP5&") B FROM "&GP4&" WHERE NRORG = "&GP9&" UNION ALL SELECT "&GP5&", LEAD("&GP5&") OVER (ORDER BY "&GP5&") FROM "&GP4&" WHERE NRORG = "&GP9&" ) WHERE B - A > "&GP8&" OR B IS NULL ORDER BY A;" -> /*COMUNICAPARC*/ SELECT A + 1 A, B - 1 B, B - A - 1 LENGHT, (SELECT TO_NUMBER(NRSEQUENCIAL) FROM NOVOCODIGO WHERE NRORG = 5862 AND CDCONTADOR = 'COMUNICAPARC') NOVOCODIGO FROM (SELECT 0 A, MIN(NRCOMUNICAPARC) B FROM COMUNICAPARC WHERE NRORG = 5862 UNION ALL SELECT NRCOMUNICAPARC, LEAD(NRCOMUNICAPARC) OVER (ORDER BY NRCOMUNICAPARC) FROM COMUNICAPARC WHERE NRORG = 5862 ) WHERE B - A > 2 OR B IS NULL ORDER BY A; | GQ2: ="/*"&GQ4&"*/ SELECT A + 1 A, B - 1 B, B - A - 1 LENGHT, (SELECT TO_NUMBER(NRSEQUENCIAL) FROM NOVOCODIGO WHERE NRORG = "&GQ9&" AND CDCONTADOR = '"&GQ4&"') NOVOCODIGO FROM (SELECT 0 A, MIN("&GQ5&") B FROM "&GQ4&" WHERE NRORG = "&GQ9&" UNION ALL SELECT "&GQ5&", LEAD("&GQ5&") OVER (ORDER BY "&GQ5&") FROM "&GQ4&" WHERE NRORG = "&GQ9&" ) WHERE B - A > "&GQ8&" OR B IS NULL ORDER BY A;" -> /*ENDERECOPARC*/ SELECT A + 1 A, B - 1 B, B - A - 1 LENGHT, (SELECT TO_NUMBER(NRSEQUENCIAL) FROM NOVOCODIGO WHERE NRORG = 5862 AND CDCONTADOR = 'ENDERECOPARC') NOVOCODIGO FROM (SELECT 0 A, MIN(NRENDERECOPARC) B FROM ENDERECOPARC WHERE NRORG = 5862 UNION ALL SELECT NRENDERECOPARC, LEAD(NRENDERECOPARC) OVER (ORDER BY NRENDERECOPARC) FROM ENDERECOPARC WHERE NRORG = 5862 ) WHERE B - A > 27 OR B IS NULL ORDER BY A; | ... GS2: ="/*"&GS4&"*/ SELECT A + 1 A, B - 1 B, B - A - 1 LENGHT, (SELECT TO_NUMBER(NRSEQUENCIAL) FROM NOVOCODIGO WHERE NRORG = "&GS9&" AND CDCONTADOR = '"&GS4&"') NOVOCODIGO FROM (SELECT 0 A, MIN("&GS5&") B FROM "&GS4&" WHERE NRORG = "&GS9&" UNION ALL SELECT "&GS5&", LEAD("&GS5&") OVER (ORDER BY "&GS5&") FROM "&GS4&" WHERE NRORG = "&GS9&" ) WHERE B - A > "&GS8&" OR B IS NULL ORDER BY A;" -> /*GPE_MOVIMENTACAO*/ SELECT A + 1 A, B - 1 B, B - A - 1 LENGHT, (SELECT TO_NUMBER(NRSEQUENCIAL) FROM NOVOCODIGO WHERE NRORG = 5862 AND CDCONTADOR = 'GPE_MOVIMENTACAO') NOVOCODIGO FROM (SELECT 0 A, MIN(NRMOVIMENTACAO) B FROM GPE_MOVIMENTACAO WHERE NRORG = 5862 UNION ALL SELECT NRMOVIMENTACAO, LEAD(NRMOVIMENTACAO) OVER (ORDER BY NRMOVIMENTACAO) FROM GPE_MOVIMENTACAO WHERE NRORG = 5862 ) WHERE B - A > 63 OR B IS NULL ORDER BY A; | GU2: ="SELECT '--Diferenca: ' || (" & GU8 &" - COUNT(1)) || ' | Registros: ' || " & GU8 &" || '; Na base de dados: ' || COUNT(1) STATUS, '"&GU4&"' TABELA FROM "&GU4&" WHERE NRORG = "&GU9&" AND "&GU5&" BETWEEN "&GU6&" AND "&GU7&" UNION ALL " -> SELECT '--Diferenca: ' || (27 - COUNT(1)) || ' | Registros: ' || 27 || '; Na base de dados: ' || COUNT(1) STATUS, 'PARCNEGOCIO' TABELA FROM PARCNEGOCIO WHERE NRORG = 5862 AND NRPARCNEGOCIO BETWEEN 204 AND 230 UNION ALL | GV2: ="SELECT '--Diferenca: ' || (" & GV8 &" - COUNT(1)) || ' | Registros: ' || " & GV8 &" || '; Na base de dados: ' || COUNT(1) STATUS, '"&GV4&"' TABELA FROM "&GV4&" WHERE NRORG = "&GV9&" AND "&GV5&" BETWEEN "&GV6&" AND "&GV7&" UNION ALL " -> SELECT '--Diferenca: ' || (27 - COUNT(1)) || ' | Registros: ' || 27 || '; Na base de dados: ' || COUNT(1) STATUS, 'GPE_PESSOA' TABELA FROM GPE_PESSOA WHERE NRORG = 5862 AND NRPESSOA BETWEEN 1 AND 27 UNION ALL | GW2: ="SELECT '--Diferenca: ' || (" & GW8 &" - COUNT(1)) || ' | Registros: ' || " & GW8 &" || '; Na base de dados: ' || COUNT(1) STATUS, '"&GW4&"' TABELA FROM "&GW4&" WHERE NRORG = "&GW9&" AND "&GW5&" BETWEEN "&GW6&" AND "&GW7&" UNION ALL " -> SELECT '--Diferenca: ' || (27 - COUNT(1)) || ' | Registros: ' || 27 || '; Na base de dados: ' || COUNT(1) STATUS, 'GPE_PESSOAH' TABELA FROM GPE_PESSOAH WHERE NRORG = 5862 AND NRPESSOAH BETWEEN 1 AND 27 UNION ALL | GX2: ="SELECT '--Diferenca: ' || (" & GX8 &" - COUNT(1)) || ' | Registros: ' || " & GX8 &" || '; Na base de dados: ' || COUNT(1) STATUS, '"&GX4&"' TABELA FROM "&GX4&" WHERE NRORG = "&GX9&" AND "&GX5&" BETWEEN "&GX6&" AND "&GX7&" UNION ALL " -> SELECT '--Diferenca: ' || (27 - COUNT(1)) || ' | Registros: ' || 27 || '; Na base de dados: ' || COUNT(1) STATUS, 'GPE_VINCULOM' TABELA FROM GPE_VINCULOM WHERE NRORG = 5862 AND NRVINCULOM BETWEEN 1 AND 27 UNION ALL | GY2: ="SELECT '--Diferenca: ' || (" & GY8 &" - COUNT(1)) || ' | Registros: ' || " & GY8 &" || '; Na base de dados: ' || COUNT(1) STATUS, '"&GY4&"' TABELA FROM "&GY4&" WHERE NRORG = "&GY9&" AND "&GY5&" BETWEEN "&GY6&" AND "&GY7&" UNION ALL " -> SELECT '--Diferenca: ' || (27 - COUNT(1)) || ' | Registros: ' || 27 || '; Na base de dados: ' || COUNT(1) STATUS, 'GPE_ALTESITUFUNC' TABELA FROM GPE_ALTESITUFUNC WHERE NRORG = 5862 AND NRALTESITUFUNC BETWEEN 1 AND 27 UNION ALL | GZ2: ="SELECT '--Diferenca: ' || (" & GZ8 &" - COUNT(1)) || ' | Registros: ' || " & GZ8 &" || '; Na base de dados: ' || COUNT(1) STATUS, '"&GZ4&"' TABELA FROM "&GZ4&" WHERE NRORG = "&GZ9&" AND "&GZ5&" BETWEEN "&GZ6&" AND "&GZ7&" UNION ALL " -> SELECT '--Diferenca: ' || (13 - COUNT(1)) || ' | Registros: ' || 13 || '; Na base de dados: ' || COUNT(1) STATUS, 'CONTCORRPARC' TABELA FROM CONTCORRPARC WHERE NRORG = 5862 AND NRCONTCORRPARC BETWEEN 1 AND 13 UNION ALL | HA2: ="SELECT '--Diferenca: ' || (" & HA8 &" - COUNT(1)) || ' | Registros: ' || " & HA8 &" || '; Na base de dados: ' || COUNT(1) STATUS, '"&HA4&"' TABELA FROM "&HA4&" WHERE NRORG = "&HA9&" AND "&HA5&" BETWEEN "&HA6&" AND "&HA7&" UNION ALL " -> SELECT '--Diferenca: ' || (2 - COUNT(1)) || ' | Registros: ' || 2 || '; Na base de dados: ' || COUNT(1) STATUS, 'COMUNICAPARC' TABELA FROM COMUNICAPARC WHERE NRORG = 5862 AND NRCOMUNICAPARC BETWEEN 1 AND 2 UNION ALL | HB2: ="SELECT '--Diferenca: ' || (" & HB8 &" - COUNT(1)) || ' | Registros: ' || " & HB8 &" || '; Na base de dados: ' || COUNT(1) STATUS, '"&HB4&"' TABELA FROM "&HB4&" WHERE NRORG = "&HB9&" AND "&HB5&" BETWEEN "&HB6&" AND "&HB7&" UNION ALL " -> SELECT '--Diferenca: ' || (27 - COUNT(1)) || ' | Registros: ' || 27 || '; Na base de dados: ' || COUNT(1) STATUS, 'ENDERECOPARC' TABELA FROM ENDERECOPARC WHERE NRORG = 5862 AND NRENDERECOPARC BETWEEN 11 AND 37 UNION ALL | HC2: ="SELECT '--Diferenca: ' || (" & HC8 &" - COUNT(1)) || ' | Registros: ' || " & HC8 &" || '; Na base de dados: ' || COUNT(1) STATUS, '"&HC4&"' TABELA FROM "&HC4&" WHERE NRORG = "&HC9&" AND "&HC5&" BETWEEN "&HC6&" AND "&HC7&" UNION ALL " -> SELECT '--Diferenca: ' || (81 - COUNT(1)) || ' | Registros: ' || 81 || '; Na base de dados: ' || COUNT(1) STATUS, 'GPE_VINCULOH' TABELA FROM GPE_VINCULOH WHERE NRORG = 5862 AND NRVINCULOH BETWEEN 1 AND 81 UNION ALL | HD2: ="SELECT '--Diferenca: ' || (" & HD8 &" - COUNT(1)) || ' | Registros: ' || " & HD8 &" || '; Na base de dados: ' || COUNT(1) STATUS, '"&HD4&"' TABELA FROM "&HD4&" WHERE NRORG = "&HD9&" AND "&HD5&" BETWEEN "&HD6&" AND "&HD7&";" -> SELECT '--Diferenca: ' || (63 - COUNT(1)) || ' | Registros: ' || 63 || '; Na base de dados: ' || COUNT(1) STATUS, 'GPE_MOVIMENTACAO' TABELA FROM GPE_MOVIMENTACAO WHERE NRORG = 5862 AND NRMOVIMENTACAO BETWEEN 1 AND 63; | HF2: ="MERGE INTO NOVOCODIGO NC USING ( SELECT LPAD( MAX( "&HF5&" ) + 1, 20, '0' ) NRSEQUENCIAL FROM "&HF4&" WHERE NRORG = "&HF9&" ) TABELA ON ( NC.NRORG = "&HF9&" AND NC.CDCONTADOR = '"&HF4&"' ) WHEN MATCHED THEN UPDATE SET NC.NRSEQUENCIAL = TABELA.NRSEQUENCIAL WHEN NOT MATCHED THEN INSERT ( CDCONTADOR, NRSEQUENCIAL, NRORG, DTINCLUSAO ) VALUES ( '"&HF4&"', TABELA.NRSEQUENCIAL, "&HF9&", SYSDATE );" -> MERGE INTO NOVOCODIGO NC USING ( SELECT LPAD( MAX( NRPARCNEGOCIO ) + 1, 20, '0' ) NRSEQUENCIAL FROM PARCNEGOCIO WHERE NRORG = 5862 ) TABELA ON ( NC.NRORG = 5862 AND NC.CDCONTADOR = 'PARCNEGOCIO' ) WHEN MATCHED THEN UPDATE SET NC.NRSEQUENCIAL = TABELA.NRSEQUENCIAL WHEN NOT MATCHED THEN INSERT ( CDCONTADOR, NRSEQUENCIAL, NRORG, DTINCLUSAO ) VALUES ( 'PARCNEGOCIO', TABELA.NRSEQUENCIAL, 5862, SYSDATE ); | HG2: ="MERGE INTO NOVOCODIGO NC USING ( SELECT LPAD( MAX( "&HG5&" ) + 1, 20, '0' ) NRSEQUENCIAL FROM "&HG4&" WHERE NRORG = "&HG9&" ) TABELA ON ( NC.NRORG = "&HG9&" AND NC.CDCONTADOR = '"&HG4&"' ) WHEN MATCHED THEN UPDATE SET NC.NRSEQUENCIAL = TABELA.NRSEQUENCIAL WHEN NOT MATCHED THEN INSERT ( CDCONTADOR, NRSEQUENCIAL, NRORG, DTINCLUSAO ) VALUES ( '"&HG4&"', TABELA.NRSEQUENCIAL, "&HG9&", SYSDATE );" -> MERGE INTO NOVOCODIGO NC USING ( SELECT LPAD( MAX( NRPESSOA ) + 1, 20, '0' ) NRSEQUENCIAL FROM GPE_PESSOA WHERE NRORG = 5862 ) TABELA ON ( NC.NRORG = 5862 AND NC.CDCONTADOR = 'GPE_PESSOA' ) WHEN MATCHED THEN UPDATE SET NC.NRSEQUENCIAL = TABELA.NRSEQUENCIAL WHEN NOT MATCHED THEN INSERT ( CDCONTADOR, NRSEQUENCIAL, NRORG, DTINCLUSAO ) VALUES ( 'GPE_PESSOA', TABELA.NRSEQUENCIAL, 5862, SYSDATE ); | HH2: ="MERGE INTO NOVOCODIGO NC USING ( SELECT LPAD( MAX( "&HH5&" ) + 1, 20, '0' ) NRSEQUENCIAL FROM "&HH4&" WHERE NRORG = "&HH9&" ) TABELA ON ( NC.NRORG = "&HH9&" AND NC.CDCONTADOR = '"&HH4&"' ) WHEN MATCHED THEN UPDATE SET NC.NRSEQUENCIAL = TABELA.NRSEQUENCIAL WHEN NOT MATCHED THEN INSERT ( CDCONTADOR, NRSEQUENCIAL, NRORG, DTINCLUSAO ) VALUES ( '"&HH4&"', TABELA.NRSEQUENCIAL, "&HH9&", SYSDATE );" -> MERGE INTO NOVOCODIGO NC USING ( SELECT LPAD( MAX( NRPESSOAH ) + 1, 20, '0' ) NRSEQUENCIAL FROM GPE_PESSOAH WHERE NRORG = 5862 ) TABELA ON ( NC.NRORG = 5862 AND NC.CDCONTADOR = 'GPE_PESSOAH' ) WHEN MATCHED THEN UPDATE SET NC.NRSEQUENCIAL = TABELA.NRSEQUENCIAL WHEN NOT MATCHED THEN INSERT ( CDCONTADOR, NRSEQUENCIAL, NRORG, DTINCLUSAO ) VALUES ( 'GPE_PESSOAH', TABELA.NRSEQUENCIAL, 5862, SYSDATE ); | HI2: ="MERGE INTO NOVOCODIGO NC USING ( SELECT LPAD( MAX( "&HI5&" ) + 1, 20, '0' ) NRSEQUENCIAL FROM "&HI4&" WHERE NRORG = "&HI9&" ) TABELA ON ( NC.NRORG = "&HI9&" AND NC.CDCONTADOR = '"&HI4&"' ) WHEN MATCHED THEN UPDATE SET NC.NRSEQUENCIAL = TABELA.NRSEQUENCIAL WHEN NOT MATCHED THEN INSERT ( CDCONTADOR, NRSEQUENCIAL, NRORG, DTINCLUSAO ) VALUES ( '"&HI4&"', TABELA.NRSEQUENCIAL, "&HI9&", SYSDATE );" -> MERGE INTO NOVOCODIGO NC USING ( SELECT LPAD( MAX( NRVINCULOM ) + 1, 20, '0' ) NRSEQUENCIAL FROM GPE_VINCULOM WHERE NRORG = 5862 ) TABELA ON ( NC.NRORG = 5862 AND NC.CDCONTADOR = 'GPE_VINCULOM' ) WHEN MATCHED THEN UPDATE SET NC.NRSEQUENCIAL = TABELA.NRSEQUENCIAL WHEN NOT MATCHED THEN INSERT ( CDCONTADOR, NRSEQUENCIAL, NRORG, DTINCLUSAO ) VALUES ( 'GPE_VINCULOM', TABELA.NRSEQUENCIAL, 5862, SYSDATE ); | HJ2: ="MERGE INTO NOVOCODIGO NC USING ( SELECT LPAD( MAX( "&HJ5&" ) + 1, 20, '0' ) NRSEQUENCIAL FROM "&HJ4&" WHERE NRORG = "&HJ9&" ) TABELA ON ( NC.NRORG = "&HJ9&" AND NC.CDCONTADOR = '"&HJ4&"' ) WHEN MATCHED THEN UPDATE SET NC.NRSEQUENCIAL = TABELA.NRSEQUENCIAL WHEN NOT MATCHED THEN INSERT ( CDCONTADOR, NRSEQUENCIAL, NRORG, DTINCLUSAO ) VALUES ( '"&HJ4&"', TABELA.NRSEQUENCIAL, "&HJ9&", SYSDATE );" -> MERGE INTO NOVOCODIGO NC USING ( SELECT LPAD( MAX( NRALTESITUFUNC ) + 1, 20, '0' ) NRSEQUENCIAL FROM GPE_ALTESITUFUNC WHERE NRORG = 5862 ) TABELA ON ( NC.NRORG = 5862 AND NC.CDCONTADOR = 'GPE_ALTESITUFUNC' ) WHEN MATCHED THEN UPDATE SET NC.NRSEQUENCIAL = TABELA.NRSEQUENCIAL WHEN NOT MATCHED THEN INSERT ( CDCONTADOR, NRSEQUENCIAL, NRORG, DTINCLUSAO ) VALUES ( 'GPE_ALTESITUFUNC', TABELA.NRSEQUENCIAL, 5862, SYSDATE ); | HK2: ="MERGE INTO NOVOCODIGO NC USING ( SELECT LPAD( MAX( "&HK5&" ) + 1, 20, '0' ) NRSEQUENCIAL FROM "&HK4&" WHERE NRORG = "&HK9&" ) TABELA ON ( NC.NRORG = "&HK9&" AND NC.CDCONTADOR = '"&HK4&"' ) WHEN MATCHED THEN UPDATE SET NC.NRSEQUENCIAL = TABELA.NRSEQUENCIAL WHEN NOT MATCHED THEN INSERT ( CDCONTADOR, NRSEQUENCIAL, NRORG, DTINCLUSAO ) VALUES ( '"&HK4&"', TABELA.NRSEQUENCIAL, "&HK9&", SYSDATE );" -> MERGE INTO NOVOCODIGO NC USING ( SELECT LPAD( MAX( NRCONTCORRPARC ) + 1, 20, '0' ) NRSEQUENCIAL FROM CONTCORRPARC WHERE NRORG = 5862 ) TABELA ON ( NC.NRORG = 5862 AND NC.CDCONTADOR = 'CONTCORRPARC' ) WHEN MATCHED THEN UPDATE SET NC.NRSEQUENCIAL = TABELA.NRSEQUENCIAL WHEN NOT MATCHED THEN INSERT ( CDCONTADOR, NRSEQUENCIAL, NRORG, DTINCLUSAO ) VALUES ( 'CONTCORRPARC', TABELA.NRSEQUENCIAL, 5862, SYSDATE ); | HL2: ="MERGE INTO NOVOCODIGO NC USING ( SELECT LPAD( MAX( "&HL5&" ) + 1, 20, '0' ) NRSEQUENCIAL FROM "&HL4&" WHERE NRORG = "&HL9&" ) TABELA ON ( NC.NRORG = "&HL9&" AND NC.CDCONTADOR = '"&HL4&"' ) WHEN MATCHED THEN UPDATE SET NC.NRSEQUENCIAL = TABELA.NRSEQUENCIAL WHEN NOT MATCHED THEN INSERT ( CDCONTADOR, NRSEQUENCIAL, NRORG, DTINCLUSAO ) VALUES ( '"&HL4&"', TABELA.NRSEQUENCIAL, "&HL9&", SYSDATE );" -> MERGE INTO NOVOCODIGO NC USING ( SELECT LPAD( MAX( NRCOMUNICAPARC ) + 1, 20, '0' ) NRSEQUENCIAL FROM COMUNICAPARC WHERE NRORG = 5862 ) TABELA ON ( NC.NRORG = 5862 AND NC.CDCONTADOR = 'COMUNICAPARC' ) WHEN MATCHED THEN UPDATE SET NC.NRSEQUENCIAL = TABELA.NRSEQUENCIAL WHEN NOT MATCHED THEN INSERT ( CDCONTADOR, NRSEQUENCIAL, NRORG, DTINCLUSAO ) VALUES ( 'COMUNICAPARC', TABELA.NRSEQUENCIAL, 5862, SYSDATE ); | HM2: ="MERGE INTO NOVOCODIGO NC USING ( SELECT LPAD( MAX( "&HM5&" ) + 1, 20, '0' ) NRSEQUENCIAL FROM "&HM4&" WHERE NRORG = "&HM9&" ) TABELA ON ( NC.NRORG = "&HM9&" AND NC.CDCONTADOR = '"&HM4&"' ) WHEN MATCHED THEN UPDATE SET NC.NRSEQUENCIAL = TABELA.NRSEQUENCIAL WHEN NOT MATCHED THEN INSERT ( CDCONTADOR, NRSEQUENCIAL, NRORG, DTINCLUSAO ) VALUES ( '"&HM4&"', TABELA.NRSEQUENCIAL, "&HM9&", SYSDATE );" -> MERGE INTO NOVOCODIGO NC USING ( SELECT LPAD( MAX( NRENDERECOPARC ) + 1, 20, '0' ) NRSEQUENCIAL FROM ENDERECOPARC WHERE NRORG = 5862 ) TABELA ON ( NC.NRORG = 5862 AND NC.CDCONTADOR = 'ENDERECOPARC' ) WHEN MATCHED THEN UPDATE SET NC.NRSEQUENCIAL = TABELA.NRSEQUENCIAL WHEN NOT MATCHED THEN INSERT ( CDCONTADOR, NRSEQUENCIAL, NRORG, DTINCLUSAO ) VALUES ( 'ENDERECOPARC', TABELA.NRSEQUENCIAL, 5862, SYSDATE ); | ... HO2: ="MERGE INTO NOVOCODIGO NC USING ( SELECT LPAD( MAX( "&HO5&" ) + 1, 20, '0' ) NRSEQUENCIAL FROM "&HO4&" WHERE NRORG = "&HO9&" ) TABELA ON ( NC.NRORG = "&HO9&" AND NC.CDCONTADOR = '"&HO4&"' ) WHEN MATCHED THEN UPDATE SET NC.NRSEQUENCIAL = TABELA.NRSEQUENCIAL WHEN NOT MATCHED THEN INSERT ( CDCONTADOR, NRSEQUENCIAL, NRORG, DTINCLUSAO ) VALUES ( '"&HO4&"', TABELA.NRSEQUENCIAL, "&HO9&", SYSDATE );" -> MERGE INTO NOVOCODIGO NC USING ( SELECT LPAD( MAX( NRMOVIMENTACAO ) + 1, 20, '0' ) NRSEQUENCIAL FROM GPE_MOVIMENTACAO WHERE NRORG = 5862 ) TABELA ON ( NC.NRORG = 5862 AND NC.CDCONTADOR = 'GPE_MOVIMENTACAO' ) WHEN MATCHED THEN UPDATE SET NC.NRSEQUENCIAL = TABELA.NRSEQUENCIAL WHEN NOT MATCHED THEN INSERT ( CDCONTADOR, NRSEQUENCIAL, NRORG, DTINCLUSAO ) VALUES ( 'GPE_MOVIMENTACAO', TABELA.NRSEQUENCIAL, 5862, SYSDATE ); | HP2: COMMIT;
A3: 23/02/2026 | C3: 290000-0-01643 | D3: =IF(B3="",1,13) -> 1 | E3: 000001 | F3: 01/01/2000 | G3: NUNCA | H3: DENISE DA CUNHA NASCIMENTO | I3: S | J3: 93313764215 | K3: 1455296 | L3: 0030 | M3: PA | N3: 05/02/2009 | O3: 13666196429 | Q3: 5378686 | R3: SSP | S3: PA | T3: 13/07/2011 | U3: 052779011376 | V3: 28 | W3: 73 | AC3: 5 | AD3: 1058 | AE3: PA | AF3: Belem | AG3: 18/11/1986 | AH3: F | AI3: SAL1 | AJ3: 237 | AK3: 2156 | AL3: 673315 | AM3: 2 | AN3: 1 | AO3: MENSAL | AP3: est_MATSAUDE | AQ3: dep_290000 | AR3: 0055 | AS3: PA | AT3: Belem | AU3: R | AV3: 01 / CONJUNTO COAB GLEBA 01 | AW3: 80 | AX3: MARAMBAIA | AZ3: 66623250 | BA3: 1 | BC3: 23/02/2026 | BF3: 0048-2 | BG3: UNICO | BJ3: COREN-PA 362.838 - COREN-PA 035.838 ( ESPECIALISTA) POS Graduada EM Enfermagem Obstetrica e ginecologica- 2017INTEGRACAO - 12/02/14Adevertencia Verbal: Descumprimento as normas internas da enfermagem - 14/05/2014Certidao Negativa-2016 | BM3: 08/04/2026 | BN3: 1 | BO3: 1 | BP3: 23/02/2026 | BQ3: 0 | BR3: 0 | BS3: 1 | BT3: 9 | BU3: sin_02 | BV3: 45 | BW3: 0 | BX3: 23/02/2027 | BZ3: -1 | CC3: 1 | CD3: 32437120 | CE3: nascimento.denisec@gmail.com | CF3: 2590.12 | CG3: ANTONIO WALTER LOPES NASCIMENTO | CH3: IRAJARA DE FATIMA DA CUNHA NASCIMENTO | CI3: 91 | CJ3: 91 | CK3: 983215560 | CM3: Não excluir antes | CN3: Este campo deve ser texto! | CO3: Este campo deve ser texto! | CP3: =CP2+1 -> 204 | CQ3: =CQ2+1 -> 1 | CR3: =CR2+1 -> 1 | CS3: =CS2+1 -> 1 | CT3: =CT2 -> 1 | CU3: =CU2 -> 2 | CV3: =CV2 -> 3 | CW3: =CW2+1 -> 1 | CX3: =IF( COUNTA( AJ3:AL3 ) <> 3, CX2, CX2 + 1 ) -> 1 | CY3: =IF( TRIM( CD3 ) = "", CY2, CY2 + 1 ) -> 1 | CZ3: =IF( TRIM( CK3 ) = "", CZ2, CZ2 + 1 ) -> 3 | DA3: =IF( TRIM( CE3 ) = "", DA2, DA2 + 1 ) -> 30 | DB3: =DB2+1 -> 11 | DC3: =IF( OR( AP3 = "", FT3 <> "existe" ), "", LARGE( DC$2:DC2, 1 ) + 1 ) -> 1 | DD3: =IF( OR( AQ3 = "", FX3 <> "existe" ), "", LARGE( DD$2:DD2, 1 ) + 1 ) -> 28 | DE3: =IF( OR( BU3 = "", GB3 <> "existe" ), "", LARGE( DE$2:DE2, 1 ) + 1 ) -> 55 | DF3: =TRIM(UPPER(G3)) -> NUNCA | DG3: {=UPPER( MIG_REMOVE.ESPECIAL(AF3) )} -> BELEM | DH3: =IF(TRIM(AN3) = "", "", TRIM(AN3)*1) -> 1 | DI3: =UPPER( MID( SUBSTITUTE( SUBSTITUTE( SUBSTITUTE(AU3, "Ç", "C"), "Ã", "A"), "Á", "A"), 1, 4) ) -> R | DJ3: =TRIM(SUBSTITUTE(SUBSTITUTE(AV3,"'",""),"&","")) -> 01 / CONJUNTO COAB GLEBA 01 | DK3: =TRIM(SUBSTITUTE(SUBSTITUTE(AX3,"'",""),"&","")) -> MARAMBAIA | DL3: =TRIM(SUBSTITUTE(SUBSTITUTE(AY3,"'",""),"&","")) | DM3: =TRIM(SUBSTITUTE(SUBSTITUTE(AZ3,"'",""),"&","")) -> 66623250 | DN3: =BF3 -> 0048-2 | DO3: =TRIM(BQ3) -> 0 | DP3: =TRIM(BR3) -> 0 | DQ3: =IFERROR( SUBSTITUTE( SUBSTITUTE( SUBSTITUTE( SUBSTITUTE( AB3, ".", "" ), ",", "" ), "-", "" ), " ", "" ) * 1, "" ) | DR3: =TRIM(SUBSTITUTE(SUBSTITUTE(Q3,"'",""),"+","")) -> 5378686 | DS3: =TEXT(AJ3,"000") -> 237 | DT3: =UPPER( MID( SUBSTITUTE( TRIM( AK3 ), "-", "" ), 1, 5 ) ) -> 2156 | DU3: =UPPER( SUBSTITUTE( TRIM( AL3 ), "-", "" ) ) -> 673315 | DV3: =TEXT(AR3,"0000") -> 0055 | DW3: =UPPER( TRIM(SUBSTITUTE(SUBSTITUTE(AT3,"'",""),"&","")) ) -> BELEM | DX3: {=TEXT( MIG_NORMA.NÚMERICO( J3 ), "00000000000" )} -> 93313764215 | DY3: {=TEXT( MIG_NORMA.NÚMERICO( K3 ), "0000000" )} -> 1455296 | DZ3: =IF(TRIM(A3)="","",TEXT(TRIM(A3),"DD/MM/AAAA")) -> 23/02/2026 | EA3: =IF(TRIM(B3)="","",TEXT(TRIM(B3),"DD/MM/AAAA")) | EB3: =IF(TRIM(AG3)="","",TEXT(TRIM(AG3),"DD/MM/AAAA")) -> 18/11/1986 | EC3: =IF(TRIM(N3)="","",TEXT(TRIM(N3),"DD/MM/AAAA")) -> 05/02/2009 | ED3: =IF(TRIM(P3)="","",TEXT(TRIM(P3),"DD/MM/AAAA")) | EE3: =IF(TRIM(Y3)="","",TEXT(TRIM(Y3),"DD/MM/AAAA")) | EF3: =IF(TRIM(T3)="","",TEXT(TRIM(T3),"DD/MM/AAAA")) -> 13/07/2011 | EG3: =IF(TRIM(BC3)="","",TEXT(TRIM(BC3),"DD/MM/AAAA")) -> 23/02/2026 | EH3: =IF(TRIM(BD3)="","",TEXT(TRIM(BD3),"DD/MM/AAAA")) | EI3: =IF(TRIM(BE3)="","",TEXT(TRIM(BE3),"DD/MM/AAAA")) | EJ3: =IF(TRIM(BX3)="","",TEXT(TRIM(BX3),"DD/MM/AAAA")) -> 23/02/2027 | EK3: =IF(TRIM(BY3)="","",TEXT(TRIM(BY3),"DD/MM/AAAA")) | EL3: =IF(TRIM(BK3)="","",TEXT(TRIM(BK3),"DD/MM/AAAA")) | EM3: =IF(TRIM(BP3)="","",TEXT(TRIM(BP3),"DD/MM/AAAA")) -> 23/02/2026 | EN3: =IF(EA3="",DZ3,EA3) -> 23/02/2026 | EO3: =IF(TRIM(BM3)="","",TEXT(TRIM(BM3),"DD/MM/AAAA")) -> 08/04/2026 | EP3: =MID(TRIM(AA3),1,20) | EQ3: =SUBSTITUTE(SUBSTITUTE(SUBSTITUTE(SUBSTITUTE(SUBSTITUTE(SUBSTITUTE(SUBSTITUTE($EQ$2,"@NRORG@",$CM$2),$CP$1,CP3),$H$1,H3),$EB$1,EB3),$J$1,J3),$CP$1,CP3),$DX$1,DX3) -> INSERT INTO PARCNEGOCIO ( NRPARCNEGOCIO, NRORG, NMPRINCIPALPARC, NMSECUNDARIPARC, DTNASCIFUNDPARC, NRINSCRICAOPARC, IDATIVO, DTINCLUSAO, NRORGINCLUSAO, CDOPERINCLUSAO, CDTIPOPARCPRINCIPAL, CDTIPOINSCRICAO, IDPESSOAFISICA, IDINSTITUICAO, IDPARCFUNDIDO ) VALUES ( 204, 5862, 'DENISE DA CUNHA NASCIMENTO', 'DENISE DA CUNHA NASCIMENTO', '18/11/1986', '93313764215', 'S', SYSDATE, 5862, '000000099991', 'PESSOA', 'CPF', 'S', 'N', 'N' ); | ER3: =SUBSTITUTE(SUBSTITUTE(SUBSTITUTE($ER$2,"@NRORG@",$CM$2),$CQ$1,CQ3),$CP$1,CP3) -> INSERT INTO GPE_PESSOA ( NRPESSOA, NRORG, NRPARCNEGOCIO, DTINCLUSAO, NRORGINCLUSAO, CDOPERINCLUSAO ) VALUES ( 1, 5862, 204, SYSDATE, 5862, '000000099991' ); | ES3: =SUBSTITUTE( SUBSTITUTE( SUBSTITUTE( SUBSTITUTE( SUBSTITUTE( SUBSTITUTE( SUBSTITUTE( SUBSTITUTE( SUBSTITUTE( SUBSTITUTE( SUBSTITUTE( SUBSTITUTE( SUBSTITUTE( SUBSTITUTE( SUBSTITUTE( SUBSTITUTE( SUBSTITUTE( SUBSTITUTE( SUBSTITUTE( SUBSTITUTE( SUBSTITUTE( SUBSTITUTE( SUBSTITUTE( SUBSTITUTE( SUBSTITUTE( SUBSTITUTE( SUBSTITUTE( SUBSTITUTE( SUBSTITUTE( SUBSTITUTE( SUBSTITUTE( SUBSTITUTE( SUBSTITUTE( $ES$2, "@NRORG@", $CM$2 ), "@NRPESSOAH@", $CR3 ), "@NRPESSOA@", $CQ3 ), "@NOMEVINC@", $H3 ), "@CDESTACIVIL@", $I3 ), "@CPF@", $DX3 ), "@CTPS@", $DY3 ), "@SERIECTPS@", $L3 ), "@UFCTPS@", $M3 ), "@DTCTPS@", $EC3 ), "@PIS@", $O3 ), "@DTPIS@", $ED3 ), "@TITUELEI@", $U3 ), "@SECAOELEI@", $V3 ), "@ZONAELEI@", $W3 ), "@CNH@", $X3 ), "@DTVALCNH@", $EE3 ), "@CATCNH@", $Z3 ), "@NRCATMILITARPE@", $DQ3 ), "@NRCERTRESE@", $EP3 ), "@NRRACA@", $AC3 ), "@CDPAIS@", $AD3 ), "@SGESTADO@", $AE3 ), "@NMMUNICIPIO@", $DG3 ), "@DTNASCI@", $EB3 ), "@IDSEXO@", $AH3 ), "@NRRG@", $DR3 ), "@CDEXRG@", SUBSTITUTE($R3,"'","") ), "@UFRG@", $S3 ), "@DTEXRG@", $EF3 ), "@NRNACIONALID@", $DH3 ), "@NRGRAUINSTR@", $BT3 ),"@NRCONDFISPES@", $CC3 ) -> INSERT INTO GPE_PESSOAH ( NRPESSOAH, NRPESSOA, NRORG, DTMESCOMPETENC, NMPESSOA, CDESTACIVIL, NRCPFPESSOA, NRCTPSPESSOA, NRSERIECTPSPES, SGUFCTPSPES, DTCTPSPESSOA, NRPISPASEPPES, DTINSCPISPASEP, NRTITUELEIPES, NRSECAELEIPES, NRZONAELEIPES, NRCARTHABPES, DTVALHABCARTPES, DSCATEGHABCART, NRCATMILITARPE, NRCERTRESEPES, DTINCLUSAO, NRORGINCLUSAO, CDOPERINCLUSAO, NRRACAPESSOA, CDPAIS, SGESTADO, CDMUNICIPIO, DTNASCPESSOA, IDSEXOPESSOA, NRRGPESSOA, CDEXRGPESSOA, SGUFRGPESSOA, DTEXRGPESSOA, NRNACIONALID, NRGRAUINSTR, NRCONDFISPES ) VALUES ( 1, 1, 5862, '01/01/2000', 'DENISE DA CUNHA NASCIMENTO', 'S', '93313764215', '1455296', '0030', 'PA', '05/02/2009', '13666196429', '', '052779011376', '28', '73', '', '', '', (SELECT NRCATMILITARPE FROM GPE_CATMILITARPE WHERE NRCATMILITARPE = ''), '', SYSDATE, 5862, '000000099991', '5', '1058', 'PA', (SELECT MAX(CDMUNICIPIO) FROM MUNICIPIO WHERE NMMUNICIPIO = 'BELEM'), '18/11/1986', 'F', '5378686', 'SSP', 'PA', '13/07/2011', '1', '9' , '1'); | ET3: =SUBSTITUTE(SUBSTITUTE(SUBSTITUTE(SUBSTITUTE(SUBSTITUTE(SUBSTITUTE(SUBSTITUTE(SUBSTITUTE(SUBSTITUTE(SUBSTITUTE(SUBSTITUTE(SUBSTITUTE(SUBSTITUTE(SUBSTITUTE(SUBSTITUTE(SUBSTITUTE(SUBSTITUTE(SUBSTITUTE(SUBSTITUTE(SUBSTITUTE(SUBSTITUTE($ET$2,"@NRORG@",$CM$2),$CS$1,CS3),$CQ$1,CQ3),$C$1,C3),$DZ$1,DZ3),$EA$1,EA3),$BA$1,BA3),$BN$1,BN3),$BO$1,BO3),$BB$1,BB3),$EG$1,EG3),$EH$1,EH3),$EI$1,EI3),$H$1,H3),$BI$1,BI3),$BJ$1,BJ3),$EL$1,EL3),$BV$1,BV3),$BW$1,BW3),$EJ$1,EJ3),$EK$1,EK3) -> INSERT INTO GPE_VINCULOM (NRVINCULOM, NRPESSOA, NRORG, CDMATRICULA, DTADMISSAOVINC, DTRESCISAOVINC, DTINCLUSAO, NRORGINCLUSAO, CDOPERINCLUSAO, NRTIPOVINCULOM, NRVINCULOEMPREG, NRTPADMISSAO, NRTPDEMISSAO, DTOPCAOFGTS, DTAPOSENTAFGTS, DTPRIMADMISSAO, NMVINCULOM, NRMOTIVORESC, DSOBSRESCISAO, DTAVISOPREVIO, NRDIASCONTRATOEXP, NRDIASCONTRATOEXPPRO, DTEXAMEMEDICO, DTAVISOTRCT) VALUES (1, 1, 5862, '290000-0-01643', '23/02/2026', '', SYSDATE, 5862, '000000099991', '1', '1', '1', '', '23/02/2026', '', '', 'DENISE DA CUNHA NASCIMENTO', '', 'COREN-PA 362.838 - COREN-PA 035.838 ( ESPECIALISTA) POS Graduada EM Enfermagem Obstetrica e ginecologica- 2017INTEGRACAO - 12/02/14Adevertencia Verbal: Descumprimento as normas internas da enfermagem - 14/05/2014Certidao Negativa-2016', '', '45', '0', '23/02/2027', ''); | EU3: =SUBSTITUTE( SUBSTITUTE( SUBSTITUTE( SUBSTITUTE( SUBSTITUTE( SUBSTITUTE( SUBSTITUTE( SUBSTITUTE( SUBSTITUTE( SUBSTITUTE( SUBSTITUTE( SUBSTITUTE( SUBSTITUTE( SUBSTITUTE( SUBSTITUTE( SUBSTITUTE( SUBSTITUTE( SUBSTITUTE( SUBSTITUTE( SUBSTITUTE( SUBSTITUTE( $EU$2, "@NRORG@", $CM$2 ), "@NRVINCULOH@", $CT3 ), "@NRVINCULOM@", $CS3 ), "@NRSITUFUNCM@", $D3 ), "@OCUPACAO@", $DN3 ), "@IDCONTRIBUISIND@", $DF3 ), "@NRDEPENDIR@", $DO3 ), "@NRDEPENDSFAM@", $DP3 ), "@DTBASEFERIAS@", $EM3 ), "@IDREMUNERACAO@", $AI3 ), "@IDTPPAGAMENTO@", $AO3 ), "@ESTRUTLEGAL@", $AP3 ), "@ESTRUTGEREN@", $AQ3 ), "@ESTRUTSIND@", $BU3 ), "@NRTPMODALIDSAL@", $BS3 ), "@IDMULTVINC@", $BG3 ), "@CDCONTRIBINDIVIDUAL@", $BH3 ), "@DTFIMCONTRDETERMIN@", $EO3 ), "@NRESCALATRABM@", $E3 ), "@CORINGASIND@", $GF$8 ), "@CORINGAGEREN@", $GF$6 ) -> INSERT INTO GPE_VINCULOH (NRVINCULOH, NRVINCULOM, NRSITUFUNCM, NRCARGO, NRFUNCAO, NRORG, DTMESCOMPETENC, IDCONTRIBUISIND, DTINCLUSAO, NRORGINCLUSAO, CDOPERINCLUSAO, NRDEPENDIR, NRDEPENDSFAM, DTBASEFERIAS, IDREMUNERACAO, IDTPPAGAMENTO, NRESTRUTLEGAL, NRESTRUTGEREN, NRESTRUTSIND, NRTPMODALIDSAL, IDMULTVINC, CDCONTRIBINDIVIDUAL, NRTPMOVTRANSFM, DTFIMCONTRDETERMIN, CONFIDENCIAL, NRESCALATRABM) VALUES (1, 1, '1', (SELECT MAX(NROCUPACAOM) FROM GPE_OCUPACAOH WHERE NRORG = 5862 AND CDINTEGRACAO = '0048-2'), (SELECT MAX(NROCUPACAOM) FROM GPE_OCUPACAOH WHERE NRORG = 5862 AND CDINTEGRACAO = '0048-2'), 5862, '01/01/2000', 'NUNCA', SYSDATE, 5862, '000000099991', '0', '0', '23/02/2026', 'SAL1', 'MENSAL', (SELECT MAX(NRESTRUTURAM) FROM ESTRUTURAM WHERE NRORG = 5862 AND CDINTESTRUTURA = 'est_MATSAUDE'), NVL((SELECT MAX(NRESTRUTURAM) FROM ESTRUTURAM WHERE NRORG = 5862 AND CDINTESTRUTURA = 'dep_290000'), 999992), NVL((SELECT MAX(NRESTRUTURAM) FROM ESTRUTURAM WHERE NRORG = 5862 AND CDINTESTRUTURA = 'sin_02'), 999993), '1', 'UNICO', '', 2, '08/04/2026', 'N', (SELECT MAX(NRESCALATRABM) FROM GPE_ESCALATRABH WHERE NRORG = 5862 AND NRESCALATRABM = '000001') ); | EV3: =SUBSTITUTE(SUBSTITUTE(SUBSTITUTE(SUBSTITUTE(SUBSTITUTE($EV$2,"@NRORG@",$CM$2),$CT$1,CT3),$CU$1,CU3),$CV$1,CV3),$CN$1,$CN$2) -> INSERT INTO GPE_VINCULOH (NRVINCULOH, NRVINCULOM, NRSITUFUNCM, NRCARGO, NRFUNCAO, NRORG, DTMESCOMPETENC, IDCONTRIBUISIND, DTINCLUSAO, NRORGINCLUSAO, CDOPERINCLUSAO, NRDEPENDIR, NRDEPENDSFAM, DTBASEFERIAS, IDREMUNERACAO, IDTPPAGAMENTO, NRESTRUTLEGAL, NRESTRUTGEREN, NRESTRUTSIND, NRTPMODALIDSAL, IDMULTVINC, CDCONTRIBINDIVIDUAL, NRTPMOVTRANSFM, DTFIMCONTRDETERMIN, CONFIDENCIAL, NRESCALATRABM) SELECT 2 NRVINCULOH, NRVINCULOM, NRSITUFUNCM, NRCARGO, NRFUNCAO, NRORG, '01/01/2024' DTMESCOMPETENC, IDCONTRIBUISIND, SYSDATE DTINCLUSAO, NRORGINCLUSAO, CDOPERINCLUSAO, NRDEPENDIR, NRDEPENDSFAM, DTBASEFERIAS, IDREMUNERACAO, IDTPPAGAMENTO, NRESTRUTLEGAL, NRESTRUTGEREN, NRESTRUTSIND, NRTPMODALIDSAL, IDMULTVINC, CDCONTRIBINDIVIDUAL, NRTPMOVTRANSFM, DTFIMCONTRDETERMIN, CONFIDENCIAL, NRESCALATRABM FROM GPE_VINCULOH WHERE NRORG = 5862 AND NRVINCULOH = 1; | EW3: =SUBSTITUTE(SUBSTITUTE(SUBSTITUTE(SUBSTITUTE(SUBSTITUTE($EW$2,"@NRORG@",$CM$2),$CT$1,CT3),$CV$1,CV3),$CV$1,CV3),$CO$1,$CO$2) -> INSERT INTO GPE_VINCULOH (NRVINCULOH, NRVINCULOM, NRSITUFUNCM, NRCARGO, NRFUNCAO, NRORG, DTMESCOMPETENC, IDCONTRIBUISIND, DTINCLUSAO, NRORGINCLUSAO, CDOPERINCLUSAO, NRDEPENDIR, NRDEPENDSFAM, DTBASEFERIAS, IDREMUNERACAO, IDTPPAGAMENTO, NRESTRUTLEGAL, NRESTRUTGEREN, NRESTRUTSIND, NRTPMODALIDSAL, IDMULTVINC, CDCONTRIBINDIVIDUAL, NRTPMOVTRANSFM, DTFIMCONTRDETERMIN, CONFIDENCIAL, NRESCALATRABM) SELECT 3 NRVINCULOH, NRVINCULOM, NRSITUFUNCM, NRCARGO, NRFUNCAO, NRORG, '01/01/2025' DTMESCOMPETENC, IDCONTRIBUISIND, SYSDATE DTINCLUSAO, NRORGINCLUSAO, CDOPERINCLUSAO, NRDEPENDIR, NRDEPENDSFAM, DTBASEFERIAS, IDREMUNERACAO, IDTPPAGAMENTO, NRESTRUTLEGAL, NRESTRUTGEREN, NRESTRUTSIND, NRTPMODALIDSAL, IDMULTVINC, CDCONTRIBINDIVIDUAL, NRTPMOVTRANSFM, DTFIMCONTRDETERMIN, CONFIDENCIAL, NRESCALATRABM FROM GPE_VINCULOH WHERE NRORG = 5862 AND NRVINCULOH = 1; | EX3: =SUBSTITUTE(SUBSTITUTE(SUBSTITUTE(SUBSTITUTE(SUBSTITUTE(SUBSTITUTE($EX$2,"@NRORG@",$CM$2),$CW$1,CW3),$D$1,D3),$CS$1,CS3),$EN$1,EN3),$EA$1,EA3) -> INSERT INTO GPE_ALTESITUFUNC ( NRALTESITUFUNC, NRORG, NRSITUFUNCM, NRVINCULOM, DTINISITUFUNC, DTINCLUSAO, NRORGINCLUSAO, CDOPERINCLUSAO ) VALUES ( 1, 5862, (CASE WHEN '1' IS NOT NULL THEN '1' WHEN '' IS NULL THEN '1' ELSE '13' END), 1, '23/02/2026', SYSDATE, 5862, '000000099991' ); | EY3: =IF(COUNTA(AJ3:AL3)<>3,"",SUBSTITUTE(SUBSTITUTE(SUBSTITUTE(SUBSTITUTE(SUBSTITUTE(SUBSTITUTE(SUBSTITUTE($EY$2,"@NRORG@",$CM$2),$CX$1,CX3),$CP$1,CP3),$DS$1,DS3),$DT$1,DT3),$DU$1,DU3),$AM$1,AM3)) -> INSERT INTO CONTCORRPARC ( NRCONTCORRPARC, NRORG, NRPARCNEGOCIO, CDBANCO, CDAGENCIA, CDCONTCORR, NRTPCONTCORR, DTINCLUSAO, NRORGINCLUSAO, CDOPERINCLUSAO, IDATIVO ) VALUES ( 1, 5862, 204, '237', '2156', '673315', '2', SYSDATE, 5862, '000000099991', 'S' ); | EZ3: =IF(CD3="","",SUBSTITUTE(SUBSTITUTE(SUBSTITUTE(SUBSTITUTE(SUBSTITUTE($EZ$2,"@NRORG@",$CM$2),$CY$1,CY3),$CP$1,CP3),$CD$1,CD3),$CI$1,TRIM(CI3))) -> INSERT INTO COMUNICAPARC ( NRCOMUNICAPARC, NRPARCNEGOCIO, CDFORMACOMU, CDPREFIXCOMUPARC, CDCOMUNICAPARC, NRORG, IDATIVO, DTINCLUSAO, NRORGINCLUSAO, CDOPERINCLUSAO ) VALUES ( 1, 204, '01', '91', '32437120', 5862, 'S', SYSDATE, 5862, '000000099991' ); | FA3: =IF($CK3="","",SUBSTITUTE(SUBSTITUTE(SUBSTITUTE(SUBSTITUTE(SUBSTITUTE($FA$2,"@NRORG@",$CM$2),$CZ$1,$CZ3),$CP$1,$CP3),$CK$1,SUBSTITUTE(TRIM($CK3),"'","")),$CJ$1,TRIM(SUBSTITUTE($CJ3,"'","")))) -> INSERT INTO COMUNICAPARC ( NRCOMUNICAPARC, NRPARCNEGOCIO, CDFORMACOMU, CDPREFIXCOMUPARC, CDCOMUNICAPARC, NRORG, IDATIVO, DTINCLUSAO, NRORGINCLUSAO, CDOPERINCLUSAO ) VALUES ( 3, 204, '02', '91', '983215560', 5862, 'S', SYSDATE, 5862, '000000099991' ); | FB3: =IF(TRIM($CE3)="","",SUBSTITUTE(SUBSTITUTE(SUBSTITUTE(SUBSTITUTE($FB$2,"@NRORG@",$CM$2),$DA$1,$DA3),$CP$1,$CP3),$CE$1,SUBSTITUTE(TRIM($CE3),"'",""))) -> INSERT INTO COMUNICAPARC ( NRCOMUNICAPARC, NRPARCNEGOCIO, CDFORMACOMU, CDCOMUNICAPARC, NRORG, IDATIVO, DTINCLUSAO, NRORGINCLUSAO, CDOPERINCLUSAO ) VALUES ( 30, 204, '05', 'nascimento.denisec@gmail.com', 5862, 'S', SYSDATE, 5862, '000000099991' ); | FC3: =IF(AV3="","",SUBSTITUTE(SUBSTITUTE(SUBSTITUTE(SUBSTITUTE(SUBSTITUTE(SUBSTITUTE(SUBSTITUTE(SUBSTITUTE(SUBSTITUTE(SUBSTITUTE(SUBSTITUTE(SUBSTITUTE($FC$2,"@NRORG@",$CM$2),$DB$1,DB3),$CP$1,CP3),$DV$1,DV3),$DW$1,DW3),$DI$1,DI3),$DK$1,DK3),$DL$1,DL3),$DM$1,DM3),$DJ$1,DJ3),$AW$1,SUBSTITUTE(TRIM(AW3),"'","")),$AS$1,AS3)) -> INSERT INTO ENDERECOPARC ( NRENDERECOPARC, NRPARCNEGOCIO, CDTIPOENDERECO, NRORG, IDATIVO, DTINCLUSAO, NRORGINCLUSAO, CDOPERINCLUSAO, CDPAIS, CDMUNICIPIO, CDLOGRADOURO, NMBAIRROENDERECO, DSCOMPLEENDERECO, NRCEPENDERECO, DSENDERECO, NRIMOVELENDERECO, SGESTADO ) VALUES ( 11, 204, 'PRINCIPAL', 5862, 'S', SYSDATE, 5862, '000000099991', '0055', ( SELECT MAX(CDMUNICIPIO) FROM MUNICIPIO WHERE NMMUNICIPIO = 'BELEM' AND SGESTADO = 'PA' ), 'R', 'MARAMBAIA', '', '66623250', '01 / CONJUNTO COAB GLEBA 01', '80', 'PA'); | FD3: =IF( DC3 = "", "", SUBSTITUTE( SUBSTITUTE( SUBSTITUTE( SUBSTITUTE( SUBSTITUTE( $FD$2, "@NRORG@", $CM$2 ), "@NRMOVIMENTACAO_LEG@", $DC3 ), "@NRVINCULOM@", $CS3 ), "@ESTRUTLEGAL@", $AP3 ), "@DTADMISSAO@", $DZ3 ) ) -> INSERT INTO GPE_MOVIMENTACAO ( NRMOVIMENTACAO, NRORG, NRVINCULOM, NRTIPOTRANSFER, NRTPMOVTRANSFM, NRESTRUTURAM, DTINIMOVIMENT, DSOBSERVACAO, DTINCLUSAO, NRORGINCLUSAO, CDOPERINCLUSAO, NRTIPOESTRUTURA ) VALUES ( 1, 5862, 1, 1, 1, (SELECT MAX(NRESTRUTURAM) FROM ESTRUTURAM WHERE NRORG = 5862 AND CDINTESTRUTURA = 'est_MATSAUDE' AND NRTIPOESTRUTURA = (SELECT NRTPESTRUTLEGAL FROM GPE_PARAMORG WHERE NRORG = 5862)), '23/02/2026', 'Movimentacao gerada via migracao ' || SYSDATE, SYSDATE, 5862, '000000099991', ( SELECT NRTPESTRUTLEGAL FROM GPE_PARAMORG WHERE NRORG = 5862 ) ); | FE3: =IF( DD3 = "", "", SUBSTITUTE( SUBSTITUTE( SUBSTITUTE( SUBSTITUTE( SUBSTITUTE( $FE$2, "@NRORG@", $CM$2 ), "@NRMOVIMENTACAO_GER@", $DD3 ), "@NRVINCULOM@", $CS3 ), "@ESTRUTGEREN@", $AQ3 ), "@DTADMISSAO@", $DZ3 ) ) -> INSERT INTO GPE_MOVIMENTACAO ( NRMOVIMENTACAO, NRORG, NRVINCULOM, NRTIPOTRANSFER, NRTPMOVTRANSFM, NRESTRUTURAM, DTINIMOVIMENT, DSOBSERVACAO, DTINCLUSAO, NRORGINCLUSAO, CDOPERINCLUSAO, NRTIPOESTRUTURA ) VALUES ( 28, 5862, 1, 2, 1, (SELECT MAX(NRESTRUTURAM) FROM ESTRUTURAM WHERE NRORG = 5862 AND CDINTESTRUTURA = 'dep_290000' AND NRTIPOESTRUTURA = (SELECT NRTPESTRUTGEREN FROM GPE_PARAMORG WHERE NRORG = 5862)), '23/02/2026', 'Movimentacao gerada via migracao ' || SYSDATE, SYSDATE, 5862, '000000099991', ( SELECT NRTPESTRUTGEREN FROM GPE_PARAMORG WHERE NRORG = 5862 ) ); | FF3: =IF( DE3 = "", "", SUBSTITUTE( SUBSTITUTE( SUBSTITUTE( SUBSTITUTE( SUBSTITUTE( $FF$2, "@NRORG@", $CM$2 ), "@NRMOVIMENTACAO_SIN@", $DE3 ), "@NRVINCULOM@", $CS3 ), "@ESTRUTSIND@", $BU3 ), "@DTADMISSAO@", $DZ3 ) ) -> INSERT INTO GPE_MOVIMENTACAO ( NRMOVIMENTACAO, NRORG, NRVINCULOM, NRTIPOTRANSFER, NRTPMOVTRANSFM, NRESTRUTURAM, DTINIMOVIMENT, DSOBSERVACAO, DTINCLUSAO, NRORGINCLUSAO, CDOPERINCLUSAO, NRTIPOESTRUTURA ) VALUES ( 55, 5862, 1, 1, 1, (SELECT MAX(NRESTRUTURAM) FROM ESTRUTURAM WHERE NRORG = 5862 AND CDINTESTRUTURA = 'sin_02' AND NRTIPOESTRUTURA = 10), '23/02/2026', 'Movimentacao gerada via migracao ' || SYSDATE, SYSDATE, 5862, '000000099991', 10 ); | FG3: =$FG$2 -> COMMIT; | FI3: {=IF( COUNTIF( Base!A:A, INDIRECT( FI1 ) ) >= 1, "existe", "não" )} -> não | FJ3: {=" - " & _xlfn._xlws.SORT( _xlfn.UNIQUE( IF(_xlfn.ANCHORARRAY( FI3) = "existe", INDIRECT( FI1 ), "" ) ) )} -> - | FL3: {=IF( COUNTIF( Base!H:H, INDIRECT( FL1 ) ) >= 1, "existe", "não" )} -> existe | FM3: {=_xlfn._xlws.SORT( _xlfn.UNIQUE( IF(_xlfn.ANCHORARRAY( FL3) = "existe", "", INDIRECT( FL1 ) ) ) )} | FN3: {=_xlfn._xlws.SORT( _xlfn.UNIQUE( IF(_xlfn.ANCHORARRAY( FL3) = "existe", "", "Vínculo (matrícula): " & INDIRECT( $FI$1 ) & ", ocupação " & INDIRECT( FL1 ) & ", Nome: " & INDIRECT( FH1 )& ", Admissão: " & INDIRECT( FK1 )) ) )} | FP3: {=IF( COUNTIF( Base!F:F, INDIRECT( FP1 ) ) >= 1, "existe", "não" )} -> existe | FQ3: {=_xlfn._xlws.SORT( _xlfn.UNIQUE( IF(_xlfn.ANCHORARRAY( FP3) = "existe", "", INDIRECT( FP1 ) ) ) )} | FR3: {=_xlfn._xlws.SORT( _xlfn.UNIQUE( IF(_xlfn.ANCHORARRAY( FP3) = "existe", "", "Vínculo (matrícula): " & INDIRECT( $FI$1 ) & ", escala trab. " & INDIRECT( FP1 ) & ", Nome: " & INDIRECT( FH1 )& ", Admissão: " & INDIRECT( FK1 )) ) )} | FT3: {=IF( COUNTIF( Base!M:M, "'" & INDIRECT( FT1 ) & "'" ) >= 1, "existe", INDIRECT( FT1 ) )} -> existe | FU3: {=" - " & _xlfn._xlws.SORT( _xlfn.UNIQUE( IF(_xlfn.ANCHORARRAY( FT3) = "existe", "",_xlfn.ANCHORARRAY( FT3)) ) )} -> - | FV3: {=" - " & _xlfn._xlws.SORT( _xlfn.UNIQUE( IF(_xlfn.ANCHORARRAY( FT3) = "existe", "", "Vínculo (matrícula): " & INDIRECT( $FI$1 ) & ", estrutura legal " & INDIRECT( FT1 ) ) ) )} -> - | FX3: {=IF( COUNTIF( Base!M:M, "'" & INDIRECT( FX1 ) & "'" ) >= 1, "existe", INDIRECT( FX1 ) )} -> existe | FY3: {=" - " & _xlfn._xlws.SORT( _xlfn.UNIQUE( IF(_xlfn.ANCHORARRAY( FX3) = "existe", "",_xlfn.ANCHORARRAY( FX3) ) ) )} -> - | FZ3: {=" - " & _xlfn._xlws.SORT( _xlfn.UNIQUE( IF(_xlfn.ANCHORARRAY( FX3) = "existe", "", "Vínculo (matrícula): " & INDIRECT( $FI$1 ) & ", estrutura gerencial " & INDIRECT( FX1 ) & ", Nome: " & INDIRECT( FH1 )& ", Admissão: " & INDIRECT( FK1 )) ) )} -> - | GB3: {=IF( COUNTIF( Base!M:M, "'" & INDIRECT( GB1 ) & "'" ) >= 1, "existe", INDIRECT( GB1 ) )} -> existe | GC3: {=" - " & _xlfn._xlws.SORT( _xlfn.UNIQUE( IF(_xlfn.ANCHORARRAY( GB3) = "existe", "",_xlfn.ANCHORARRAY( GB3) ) ) )} -> - 0 | GD3: {=" - " & _xlfn._xlws.SORT( _xlfn.UNIQUE( IF(_xlfn.ANCHORARRAY( GB3) = "existe", "", "Vínculo (matrícula): " & INDIRECT( $FI$1 ) & ", estrutura legal " & INDIRECT( GB1 ) ) ) )} -> - | GF3: Legal | GI3: Mnemônico | GJ3: @NRPARCNEGOCIO@ | GK3: @NRPESSOA@ | GL3: @NRPESSOAH@ | GM3: @NRVINCULOM@ | GN3: @NRALTESITUFUNC@ | GO3: @NRCONTCORRPARC@ | GP3: @NRCOMUNICAPARC@ | GQ3: @NRENDERECOPARC@ | GR3: @NRVINCULOH@ | GS3: @NRMOVIMENTACAO_LEG@
